Workbook
Name adjebitda: #REF!
Name Annualization_Factor: #REF!
Name Aple: #REF!
Name cc: #REF!
Name ccc: #REF!
Name ccccc: #REF!
Name cccccc: #REF!
Name ccccccccccccc: #REF!
Name ccccccccccccccc: #REF!
Name ccccccccccccccccccccc: #REF!
Name ccccccccccccccccccccccccccc: #REF!
Name d: #REF!
Name dadf: #REF!
Name DATA_01: #REF!
Name DATA_02: #REF!
Name DATA_03: #REF!
Name DATA_04: #REF!
Name DATA_05: #REF!
Name DATA_06: #REF!
Name DCF: #REF!
Name dddd: #REF!
Name f: #REF!
Name fafdssadf: #REF!
Name h: #REF!
Name Help: #REF!
Name hh: #REF!
Name hhhhh: #REF!
Name hhhhhhhhhhhhhhhhh: #REF!
Name i: #REF!
Name IntroPrintArea: #REF!
Name IntroPrintArea2: #REF!
Name IQ_CH: 110000
Name IQ_CQ: 5000
Name IQ_CY: 10000
Name IQ_DAILY: 500000
Name IQ_FH: 100000
Name IQ_FQ: 500
Name IQ_FY: 1000
Name IQ_LTM: 2000
Name IQ_MONTH: 15000
Name IQ_NTM: 6000
Name IQ_WEEK: 50000
Name IQ_YTD: 3000
Name j: #REF!
Name lkjh: #REF!
Name Look1Area: #REF!
Name Look1Area2: #REF!
Name Look2Area: #REF!
Name Look2Area2: #REF!
Name Look3Area: #REF!
Name Look3Area3: #REF!
Name Look4Area: #REF!
Name Look4Area2: #REF!
Name Look5Area: #REF!
Name Look5Area2: #REF!
Name m: #REF!
Name ODEAaldksf: #REF!
Name PurchasePrice: #REF!
Name q: #REF!
Name qq: #REF!

Sheet Cover Pg.
C11: Apex Trading Group Financial Analysis and Modeling Template
C12: This is a company financial analysis and valuation model.
C14: Table of Contents
B15: 1 | C15: Revenue Build
B16: 2 | C16: Case Assumptions
B17: 3 | C17: Operating Model
B18: 4 | C18: Working Capital Schedule
B19: 5 | C19: Public Comparable Companies Analysis
B20: 6 | C20: WACC Calculation
B21: 7 | C21: Discounted Cash Flow Analysis
C27: Required Inputs
C28: Input Stock Ticker Into Yellow Box Below...
C29: TTMI-USA
C30: Must include "-USA" (E.g. AAPL-USA, MSFT-USA)
C32: Notes
C33: You must download FactSet 365 from FactSet.com in order to automate parts of this model. You gain access to the "FactSet 365" tab via the "Add-ins" button in the top right of the Home tab after you have downloaded the software from their website.
C37: Statement of Confidentiality
C38: This financial model is developed for use by Apex Trading Group. Please do not share, distribute, or reproduce this material without prior consent, as it contains information intended only for authorized individuals.

Sheet IS
A1: TTM Technologies, Inc. (TTMI)
A2: 95.47
A5: TTM Technologies, Inc.
A6: TTMI 87305R109 2635659 NASDAQ Common stock
A7: Source: FactSet Fundamentals
B8: DEC '16 | C8: DEC '17 | D8: DEC '18 | E8: DEC '19 | F8: DEC '20 | G8: DEC '21 | H8: DEC '22 | I8: DEC '23 | J8: DEC '24 | K8: DEC '25
E9: Restate
A10: Sales | B10: 2533.4 | C10: 2658.6 | D10: 2847.3 | E10: 2133.2 | F10: 2105.3 | G10: 2248.7 | H10: 2495 | I10: 2232.6 | J10: 2442.8 | K10: 2906.3
A11: Cost of Goods Sold (COGS) incl. D&A | B11: 2133.8 | C11: 2252.5 | D11: 2449.8 | E11: 1801.8 | F11: 1785.1 | G11: 1912.5 | H11: 2074.2 | I11: 1868 | J11: 2000.9 | K11: 2332.2
A12: COGS excluding D&A | B12: 1953.5 | C12: 2078.2 | D12: 2224.2 | E12: 1657.8 | F12: 1641.2 | G12: 1785.1 | H12: 1940.3 | I12: 1707.2 | J12: 1850.8 | K12: 2185
A13: Depreciation & Amortization Expense | B13: 180.3 | C13: 174.3 | D13: 225.6 | E13: 144 | F13: 143.9 | G13: 127.3 | H13: 133.9 | I13: 160.7 | J13: 150.1 | K13: 147.2
A14: Depreciation | B14: 156.1 | C14: 150.6 | D14: 162.6 | E14: 93.4 | F14: 99.6 | G14: 85.9 | H14: 91.3 | I14: 99.2 | J14: 105.2 | K14: 110.3
A15: Amortization of Intangibles | B15: 24.3 | C15: 23.6 | D15: 63 | E15: 50.6 | F15: 44.4 | G15: 41.4 | H15: 42.6 | I15: 61.6 | J15: 44.9 | K15: 36.9
A16: Gross Income | B16: 399.5 | C16: 406.1 | D16: 397.5 | E16: 331.4 | F16: 320.2 | G16: 336.3 | H16: 420.9 | I16: 364.6 | J16: 441.8 | K16: 574.1
A17: SG&A Expense | B17: 211.9 | C17: 189.7 | D17: 219.5 | E17: 216.4 | F17: 199.4 | G17: 199.3 | H17: 246.6 | I17: 253.2 | J17: 282 | K17: 306.6
A18: Research & Development | E18: 17.9 | F18: 19.8 | G18: 18.1 | H18: 24.8 | I18: 27.3 | J18: 31.8 | K18: 29
A19: Other SG&A | B19: 211.9 | C19: 189.7 | D19: 219.5 | E19: 198.5 | F19: 179.7 | G19: 181.2 | H19: 221.8 | I19: 226 | J19: 250.1 | K19: 277.6
A20: EBIT (Operating Income) | B20: 187.6 | C20: 216.4 | D20: 178 | E20: 115 | F20: 120.8 | G20: 136.9 | H20: 174.2 | I20: 111.4 | J20: 159.8 | K20: 267.5
A21: Nonoperating Income - Net | B21: 17.1 | C21: -18.3 | D21: 7.9 | E21: 4.5 | F21: -10.2 | G21: -6.5 | H21: 65.7 | I21: 4 | J21: 11.2 | K21: -10.9
A22: Other Income (Expense) | B22: 17.1 | C22: -18.3 | D22: 7.9 | E22: 4.5 | F22: -10.2 | G22: -6.5 | H22: 65.7 | I22: 4 | J22: 11.2 | K22: -10.9
A23: Interest Expense | B23: 76 | C23: 53.9 | D23: 77.4 | E23: 79.8 | F23: 64.2 | G23: 34.2 | H23: 41.4 | I23: 44.9 | J23: 43.3 | K23: 43.4
A24: Gross Interest Expense | B24: 77.9 | C24: 55.4 | D24: 78.8 | E24: 81.6 | F24: 66 | G24: 35.1 | H24: 42.1 | I24: 47.2 | J24: 47.3 | K24: 47.3
A25: Interest Capitalized | B25: 1.9 | C25: 1.5 | D25: 1.4 | E25: 1.8 | F25: 1.8 | G25: 0.9 | H25: 0.7 | I25: 2.3 | J25: 4 | K25: 3.8
A26: Unusual Expense - Net | B26: 61.8 | C26: 4.2 | D26: 18.8 | E26: 5.4 | F26: 92.7 | G26: 26.2 | H26: 15.6 | I26: 70.2 | J26: 43.8 | K26: 2.8
A27: Impairments | B27: 3.3 | C27: 0 | D27: 0 | E27: 0 | F27: 69.2 | G27: 0 | H27: 0 | I27: 44.1 | J27: 32.6 | K27: 0
A28: Goodwill | B28: 0 | C28: 0 | D28: 0 | E28: 0 | F28: 69.2 | G28: 0 | H28: 0 | I28: 44.1 | J28: 32.6 | K28: 0
A29: Property,Plant & Equipment | B29: 3.3 | C29: 0 | D29: 0
A30: Restructuring Expense | B30: 10.6 | C30: 3.5 | D30: 18.8 | E30: 5.4 | F30: 16.8 | G30: 10.9 | H30: 15.6 | I30: 25 | J30: 11.2 | K30: 2.8
A31: Excpl Chrgs - Others | B31: 47.8 | C31: 0.8 | D31: 0 | F31: 6.7 | G31: 15.2 | H31: 0 | I31: 1.2 | J31: 0 | K31: 0
A32: Restructuring of Debt | B32: 47.8 | C32: 0.8 | D32: 0 | G32: 15.2 | H32: 0 | I32: 1.2 | J32: 0 | K32: 0
A33: Accelerated Depreciation | F33: 6.7
A34: Pretax Income | B34: 67 | C34: 140 | D34: 89.8 | E34: 34.3 | F34: -46.3 | G34: 70.1 | H34: 182.9 | I34: 0.3 | J34: 83.9 | K34: 210.3
A35: Income Taxes | B35: 31.4 | C35: 15.2 | D35: -83.8 | E35: 2.4 | F35: -29.9 | G35: 15.6 | H35: 88.3 | I35: 19 | J35: 27.7 | K35: 32.9
A36: Income Taxes - Current Domestic | B36: 0.9 | C36: 0.4 | D36: 0.9 | E36: 2.6 | F36: 4.7 | G36: 0.6 | H36: 4.4 | I36: 1.1 | J36: 5.9 | K36: 6.1
A37: Income Taxes - Current Foreign | B37: 29.7 | C37: 24 | D37: 12 | E37: 12.7 | F37: -27.9 | G37: 9.2 | H37: 23.5 | I37: 29.1 | J37: 22.9 | K37: 23
A38: Income Taxes - Deferred Domestic | B38: -0.7 | C38: 0 | D38: -112.1 | E38: 0.1 | F38: -6.9 | G38: -1.4 | H38: 33 | I38: -1.6 | J38: -0.4 | K38: 1.9
A39: Income Taxes - Deferred Foreign | B39: 1.6 | C39: -9.2 | D39: 15.3 | E39: -13 | F39: 0.3 | G39: 7.2 | H39: 27.4 | I39: -9.6 | J39: -0.8 | K39: 1.9
A40: Consolidated Net Income | B40: 35.6 | C40: 124.7 | D40: 173.6 | E40: 31.9 | F40: -16.4 | G40: 54.4 | H40: 94.6 | I40: -18.7 | J40: 56.3 | K40: 177.4
A41: Minority Interest | B41: 0.7 | C41: 0.5 | D41: 0 | E41: 0 | F41: 0 | G41: 0 | H41: 0 | I41: 0 | J41: 0 | K41: 0
A42: Net Income | B42: 34.9 | C42: 124.2 | D42: 173.6 | E42: 31.9 | F42: -16.4 | G42: 54.4 | H42: 94.6 | I42: -18.7 | J42: 56.3 | K42: 177.4
...

Sheet BS
A1: TTM Technologies, Inc.
A2: TTMI 87305R109 2635659 NASDAQ Common stock
A3: Source: FactSet Fundamentals
B4: DEC '16 | C4: DEC '17 | D4: DEC '18 | E4: DEC '19 | F4: DEC '20 | G4: DEC '21 | H4: DEC '22 | I4: DEC '23 | J4: DEC '24 | K4: DEC '25
E5: Restate
A6: Assets
A7: Cash & Short-Term Investments | B7: 256.277 | C7: 409.326 | D7: 256.36 | E7: 379.818 | F7: 451.565 | G7: 537.678 | H7: 402.749 | I7: 450.208 | J7: 503.932 | K7: 501.234
A8: Cash Only | B8: 256.277 | C8: 409.326 | D8: 256.36 | E8: 379.818 | F8: 451.565 | G8: 537.678 | H8: 402.749 | I8: 450.208 | J8: 503.932 | K8: 501.234
A9: Short-Term Receivables | B9: 432.788 | C9: 483.903 | D9: 810.906 | E9: 758.198 | F9: 654.361 | G9: 711.209 | H9: 878.253 | I9: 712.344 | J9: 829.993 | K9: 1031.747
A10: Accounts Receivables, Net | B10: 432.788 | C10: 483.903 | D10: 810.906 | E10: 758.198 | F10: 654.361 | G10: 711.209 | H10: 809.013 | I10: 705.607 | J10: 829.993 | K10: 1031.747
A11: Accounts Receivables, Gross | B11: 435.639 | C11: 486.371 | D11: 813.656 | E11: 760.127 | F11: 657.247 | G11: 712.767 | H11: 811.088 | I11: 708.648 | J11: 833.241 | K11: 1033.32
A12: Bad Debt/Doubtful Accounts | B12: -2.851 | C12: -2.468 | D12: -2.75 | E12: -1.929 | F12: -2.886 | G12: -1.558 | H12: -2.075 | I12: -3.041 | J12: -3.248 | K12: -1.573
A13: Other Receivables | B13: 0 | C13: 0 | D13: 0 | E13: 0 | F13: 0 | G13: 0 | H13: 69.24 | I13: 6.737 | J13: 0 | K13: 0
A14: Inventories | B14: 269.212 | C14: 294.588 | D14: 109.377 | E14: 113.753 | F14: 115.651 | G14: 127.612 | H14: 170.639 | I14: 213.075 | J14: 224.985 | K14: 250.057
A15: Finished Goods | B15: 90.621 | C15: 98.722 | D15: 1.478 | E15: 5.195 | F15: 3.92 | G15: 3.339 | H15: 4.964 | I15: 1.915 | J15: 1.339 | K15: 4.29
A16: Work in Progress | B16: 105.094 | C16: 120.031 | D16: 10.299 | E16: 10.898 | F16: 7.841 | G16: 9.62 | H16: 20.114 | I16: 45.494 | J16: 45.58 | K16: 48.236
A17: Raw Materials | B17: 73.497 | C17: 75.835 | D17: 97.6 | E17: 97.66 | F17: 103.89 | G17: 114.653 | H17: 145.561 | I17: 165.666 | J17: 178.066 | K17: 197.531
A18: Other Current Assets | B18: 54.564 | C18: 33.49 | D18: 30.271 | E18: 90.915 | F18: 27.181 | G18: 30.914 | H18: 41.415 | I18: 54.06 | J18: 47.834 | K18: 72.368
... A26: Construction in Progress | B26: 54.521 | C26: 51.865 | D26: 42.713 | E26: 58.195 | F26: 33.191 | G26: 25.554 | H26: 27.774 | I26: 90.94 | J26: 75.502 | K26: 101.945
A27: Other Property, Plant & Equipment | E27: 10.329 | F27: 10.304 | G27: 10.36 | H27: 11.327 | I27: 10.157 | J27: 11.115 | K27: 11.642
A28: Operating Lease Right-of-Use Assets | E28: 22.173 | F28: 24.34 | G28: 20.802 | H28: 18.862 | I28: 86.286 | J28: 78.252 | K28: 80.914
A29: Accumulated Depreciation | B29: 647.459 | C29: 815.551 | D29: 957.277 | E29: 612.228 | F29: 686.104 | G29: 753.443 | H29: 824.996 | I29: 863.236 | J29: 918.879 | K29: 997.191
A30: Total Long-Term Investments | B30: 0 | C30: 0 | D30: 0 | E30: 0 | F30: 0 | G30: 0 | H30: 0 | I30: 1.476 | J30: 1.3 | K30: 4.249
A31: Other Long-Term Investments | B31: 0 | C31: 0 | D31: 0 | E31: 0 | F31: 0 | G31: 0 | H31: 0 | I31: 1.476 | J31: 1.3 | K31: 0
A32: Long-Term Note Receivable | K32: 4.249
A33: Intangible Assets | B33: 499.222 | C33: 475.521 | D33: 1142.968 | E33: 1032.204 | F33: 918.631 | G33: 877.242 | H33: 1048.474 | I33: 939.446 | J33: 861.954 | K33: 825.057
A34: Goodwill | B34: 372.609 | C34: 372.571 | D34: 767.045 | E34: 706.524 | F34: 637.324 | G34: 637.324 | H34: 760.437 | I34: 702.735 | J34: 670.135 | K34: 670.135
A35: Other Intangible Assets | B35: 126.613 | C35: 102.95 | D35: 375.923 | E35: 325.68 | F35: 281.307 | G35: 239.918 | H35: 288.037 | I35: 236.711 | J35: 191.819 | K35: 154.922
A36: Other Assets | B36: 21.375 | C36: 28.209 | D36: 55.597 | E36: 485.671 | F36: 53.78 | G36: 54.335 | H36: 39.008 | I36: 59.101 | J36: 54.287 | K36: 63.995
A37: Deferred Charges | C37: 2.421 | D37: 1.42 | E37: 2.511 | F37: 1.919 | G37: 1.355 | H37: 0.792 | I37: 1.603 | J37: 1.239 | K37: 0.874
A38: Tangible Other Assets | B38: 21.375 | C38: 25.788 | D38: 54.177 | E38: 483.16 | F38: 51.861 | G38: 52.98 | H38: 38.216 | I38: 57.498 | J38: 53.048 | K38: 63.121
A39: Total Assets | B39: 2500.076 | C39: 2781.882 | D39: 3457.503 | E39: 3560.933 | F39: 2895.944 | G39: 3025.547 | H39: 3323.604 | I39: 3323.663 | J39: 3472.494 | K39: 3840.331
A40: Liabilities & Shareholders' Equity
A41: Current
A42: ST Debt & Curr. Portion LT Debt | B42: 110.652 | C42: 4.578 | D42: 30 | E42: 257.086 | F42: 8.144 | G42: 7.06 | H42: 58.104 | I42: 12.713 | J42: 12.165 | K42: 13.841
A43: Accounts Payable | B43: 371.61 | C43: 438.99 | D43: 431.288 | E43: 329.866 | F43: 327.102 | G43: 361.484 | H43: 361.788 | I43: 334.609 | J43: 406.221 | K43: 543.538
A44: Income Tax Payable | D44: 11.345 | E44: 13.035 | F44: 2.428 | G44: 7.162 | H44: 28.057 | I44: 5.466 | J44: 15.919 | K44: 8.08
A45: Other Current Liabilities | B45: 206.803 | C45: 276.788 | D45: 200.581 | E45: 346.679 | F45: 180.372 | G45: 182.442 | H45: 313.376 | I45: 351.196 | J45: 374.749 | K45: 396.738
A46: Accrued Payroll | B46: 97.171 | C46: 103.638 | D46: 94.95 | E46: 85.114 | F46: 97.268 | G46: 89.446 | H46: 115.524 | I46: 98.561 | J46: 108.149 | K46: 132.967
A47: Miscellaneous Current Liabilities | B47: 109.632 | C47: 173.15 | D47: 105.631 | E47: 261.565 | F47: 83.104 | G47: 92.996 | H47: 197.852 | I47: 252.635 | J47: 266.6 | K47: 263.771
...

Sheet CFS
A1: Chipotle Mexican Grill, Inc. (CMG)
A2: $56.08
A5: TTM Technologies, Inc.
A6: TTMI 87305R109 2635659 NASDAQ Common stock
A7: Source: FactSet Fundamentals
B8: DEC '16 | C8: DEC '17 | D8: DEC '18 | E8: DEC '19 | F8: DEC '20 | G8: DEC '21 | H8: DEC '22 | I8: DEC '23 | J8: DEC '24 | K8: DEC '25
E9: Restate
A10: Operating Activities
A11: Net Income / Starting Line | B11: 35.575 | C11: 123.701 | D11: 173.584 | E11: 41.301 | F11: 177.535 | G11: 54.414 | H11: 94.583 | I11: -18.718 | J11: 56.299 | K11: 177.448
A12: Depreciation, Depletion & Amortization | B12: 180.481 | C12: 174.443 | D12: 225.577 | E12: 219.87 | F12: 166.129 | G12: 127.331 | H12: 133.907 | I12: 160.731 | J12: 150.125 | K12: 147.171
A13: Depreciation and Depletion | B13: 156.229 | C13: 150.809 | D13: 162.551 | E13: 166.574 | F13: 120.947 | G13: 85.942 | H13: 91.276 | I13: 99.155 | J13: 105.233 | K13: 110.274
A14: Amortization of Intangible Assets | B14: 24.252 | C14: 23.634 | D14: 63.026 | E14: 53.296 | F14: 45.182 | G14: 41.389 | H14: 42.631 | I14: 61.576 | J14: 44.892 | K14: 36.897
A15: Deferred Taxes & Investment Tax Credit | B15: 0.9 | C15: -9.19 | D15: -98.291 | E15: -12.454 | F15: 6.653 | G15: 9.745 | H15: 61.304 | I15: -11.347 | J15: -1.722 | K15: 3.349
A16: Deferred Taxes | B16: 0.9 | C16: -9.19 | D16: -98.291 | E16: -12.454 | F16: 6.653 | G16: 9.745 | H16: 61.304 | I16: -11.347 | J16: -1.722 | K16: 3.349
A17: Other Funds | B17: 76.624 | C17: 41.036 | D17: 31.736 | E17: 27.136 | F17: -132.561 | G17: 25.388 | H17: -35.306 | I17: 68.56 | J17: 62.523 | K17: 49.201
A18: Funds from Operations | B18: 293.58 | C18: 329.99 | D18: 332.606 | E18: 275.853 | F18: 217.756 | G18: 216.878 | H18: 254.488 | I18: 199.226 | J18: 267.225 | K18: 377.169
A19: Changes in Working Capital | B19: 4.756 | C19: 2.765 | D19: -59.468 | E19: 34.281 | F19: 69.42 | G19: -40.246 | H19: 18.385 | I19: -11.942 | J19: -30.331 | K19: -85.287
A20: Receivables | B20: 23.212 | C20: -51.115 | D20: -2.136 | E20: 19.007 | F20: 97.454 | G20: -56.848 | H20: -20.204 | I20: 92.525 | J20: -124.386 | K20: -201.754
A21: Inventories | B21: -0.289 | C21: -25.376 | D21: 18.254 | E21: -12.642 | F21: 1.38 | G21: -11.961 | H21: -4.411 | I21: -45.392 | J21: -11.91 | K21: -25.072
A22: Accounts Payable | B22: -7.796 | C22: 54.602 | D22: -45.739 | E22: 42.045 | F22: 1.21 | G22: 40.951 | H22: -14.804 | I22: -34.582 | J22: 49.719 | K22: 138.971
... A25: Net Operating Cash Flow | B25: 298.336 | C25: 332.755 | D25: 273.138 | E25: 310.134 | F25: 287.176 | G25: 176.632 | H25: 272.873 | I25: 187.284 | J25: 236.894 | K25: 291.882
A26: Investing Activities
A27: Capital Expenditures | B27: -85.139 | C27: -151.345 | D27: -150.127 | E27: -142.576 | F27: -103.289 | G27: -81.951 | H27: -102.884 | I27: -160.242 | J27: -185.739 | K27: -292.565
A28: Capital Expenditures (Fixed Assets) | B28: -85.139 | C28: -151.345 | D28: -150.127 | E28: -142.576 | F28: -103.289 | G28: -81.951 | H28: -102.884 | I28: -160.242 | J28: -185.739 | K28: -292.565
A29: Net Assets from Acquisitions | B29: 0 | C29: -8.568 | D29: -596.396 | E29: 0 | F29: 0 | G29: 0 | H29: -298.339 | I29: 0 | J29: 0 | K29: 0
A30: Sale of Fixed Assets & Businesses | B30: 3.641 | C30: 27.255 | D30: 0.331 | E30: 6.604 | F30: 508.204 | G30: 1.427 | H30: 6.01 | I30: 68.313 | J30: 39.605 | K30: 18.625
A31: Purchase/Sale of Investments | B31: 0 | C31: 0 | D31: 0 | E31: 0 | F31: 0 | G31: -3.188 | H31: 0 | I31: 0 | J31: 0 | K31: 0
A32: Purchase of Investments | C32: 0 | D32: 0 | E32: 0 | F32: 0 | G32: 3.188 | H32: 0 | I32: 0 | J32: 0 | K32: 0
A33: Other Funds | B33: 0 | C33: 0 | D33: 0 | E33: 0 | F33: -0.623 | G33: -0.431 | H33: -0.245 | I33: -0.101 | J33: -0.076 | K33: 0
A34: Other Uses | B34: 0 | C34: 0 | D34: 0 | E34: 0 | F34: -0.623 | G34: -0.431 | H34: -0.245 | I34: -0.101 | J34: -0.076 | K34: 0
A35: Net Investing Cash Flow | B35: -81.498 | C35: -132.658 | D35: -746.192 | E35: -135.972 | F35: 404.292 | G35: -84.143 | H35: -395.458 | I35: -92.03 | J35: -146.21 | K35: -273.94
A36: Financing Activities
A37: Change in Capital Stock | B37: 1.743 | C37: 0.074 | D37: 0.191 | E37: 0 | F37: 0.191 | G37: -64.726 | H37: -35.424 | I37: -24.432 | J37: -34.479 | K37: -17.639
A38: Repurchase of Common & Preferred Stk. | B38: 0 | C38: 0 | D38: 0 | E38: 0 | F38: 0 | G38: -64.726 | H38: -35.424 | I38: -24.432 | J38: -34.479 | K38: -17.875
A39: Sale of Common & Preferred Stock | B39: 1.743 | C39: 0.074 | D39: 0.191 | E39: 0 | F39: 0.191 | G39: 0 | H39: 0 | I39: 0 | J39: 0 | K39: 0.236
A40: Proceeds from Stock Options | B40: 1.743 | C40: 0.074 | D40: 0.191 | E40: 0 | F40: 0.191 | G40: 0 | H40: 0 | I40: 0 | J40: 0 | K40: 0.236
A41: Issuance/Reduction of Debt, Net | B41: -215.322 | C41: -48.732 | D41: 322.365 | E41: -30.01 | F41: -649.975 | G41: 68.202 | H41: 0 | I41: -12.241 | J41: -2.342 | K41: -3.795
A42: Change in Current Debt | B42: 3.53 | C42: 0 | D42: 0 | E42: 0 | F42: 0 | G42: 0 | H42: 0 | I42: 0 | J42: 0 | K42: 0
A43: Change in Long-Term Debt | B43: -218.852 | C43: -48.732 | D43: 322.365 | E43: -30.01 | F43: -649.975 | G43: 68.202 | H43: 0 | I43: -12.241 | J43: -2.342 | K43: -3.795
A44: Issuance of Long-Term Debt | B44: 803.773 | C44: 715.158 | D44: 615.347 | E44: 0 | F44: 0 | G44: 494.04 | H44: 50 | I44: 279.331 | J44: 7.254 | K44: 0
...

Sheet Revenue Build
B2: Revenue Build
A5: x | B5: Revenue | E5: =F5-1 -> 2016 | F5: =G5-1 -> 2017 | G5: =H5-1 -> 2018 | H5: =I5-1 -> 2019 | I5: =J5-1 -> 2020 | J5: =K5-1 -> 2021 | K5: =L5-1 -> 2022 | L5: =M5-1 -> 2023 | ... N5: =O5-1 -> 2025 | O5: =DCF!O16 -> 2026 | P5: =O5+1 -> 2027 | Q5: =P5+1 -> 2028 | R5: =Q5+1 -> 2029 | S5: =R5+1 -> 2030
A6: 3 | E6: =E12 -> 2533.3501 | F6: =F12 -> 2658.5901 | G6: =G12 -> 2847.26 | H6: =H12 -> 2689.3081 | I6: =I12 -> 2105.322 | J6: =J12 -> 2248.74 | K6: =K12 -> 2495.0459 | L6: =L12 -> 2232.5669 | ... N6: =N12 -> 2906.345 | O6: =N6*(1+O7) -> 3487.614 | P6: =O6*(1+P7) -> 4080.5084 | Q6: =P6*(1+Q7) -> 4651.7796 | R6: =Q6*(1+R7) -> 5116.9575 | S6: =R6*(1+S7) -> 5475.1445
B7: % growth | E7: -- | F7: =(F6-E6)/E6 -> 0.049436511 | G7: =(G6-F6)/F6 -> 0.070966157 | H7: =(H6-G6)/G6 -> -0.055475055 | I7: =(I6-H6)/H6 -> -0.21715105 | J7: =(J6-I6)/I6 -> 0.06812163 | K7: =(K6-J6)/J6 -> 0.10953063 | L7: =(L6-K6)/K6 -> -0.10520007 | M7: =(M6-L6)/L6 -> 0.094145459 | N7: =(N6-M6)/M6 -> 0.18978263 | O7: =CHOOSE($A$6,O8,O9,O10) -> 0.2 | P7: =CHOOSE($A$6,P8,P9,P10) -> 0.17 | Q7: =CHOOSE($A$6,Q8,Q9,Q10) -> 0.14 | R7: =CHOOSE($A$6,R8,R9,R10) -> 0.1 | S7: =CHOOSE($A$6,S8,S9,S10) -> 0.07
B8: Conservative | O8: 0.15 | P8: 0.1 | Q8: 0.06 | R8: 0.04 | S8: 0.03
B9: Base (Street) | O9: 0.18 | P9: 0.14 | Q9: 0.1 | R9: 0.07 | S9: 0.05
B10: Optimistic | O10: 0.2 | P10: 0.17 | Q10: 0.14 | R10: 0.1 | S10: 0.07
B12: Total Revenue | E12: ='Case Assumptions'!E6 -> 2533.3501 | F12: ='Case Assumptions'!F6 -> 2658.5901 | G12: ='Case Assumptions'!G6 -> 2847.26 | H12: ='Case Assumptions'!H6 -> 2689.3081 | I12: ='Case Assumptions'!I6 -> 2105.322 | J12: ='Case Assumptions'!J6 -> 2248.74 | K12: ='Case Assumptions'!K6 -> 2495.0459 | L12: ='Case Assumptions'!L6 -> 2232.5669 | ... N12: ='Case Assumptions'!N6 -> 2906.345 | O12: =O6 -> 3487.614 | P12: =P6 -> 4080.5084 | Q12: =Q6 -> 4651.7796 | R12: =R6 -> 5116.9575 | S12: =S6 -> 5475.1445

Sheet Case Assumptions
B2: Case Assumptions
A5: x | B5: Case Assumptions | E5: =F5-1 -> 2016 | F5: =G5-1 -> 2017 | G5: =H5-1 -> 2018 | H5: =I5-1 -> 2019 | I5: =J5-1 -> 2020 | J5: =K5-1 -> 2021 | K5: =L5-1 -> 2022 | L5: =M5-1 -> 2023 | ... N5: =O5-1 -> 2025 | O5: =DCF!O16 -> 2026 | P5: =O5+1 -> 2027 | Q5: =P5+1 -> 2028 | R5: =Q5+1 -> 2029 | S5: =R5+1 -> 2030
B6: Revenue | E6: {=_xll.FDSLIVE(DCF!$D$4,"RTP_SALES(ANN,-9)")} -> 2533.3501 | F6: {=_xll.FDSLIVE(DCF!$D$4,"RTP_SALES(ANN,-8)")} -> 2658.5901 | G6: {=_xll.FDSLIVE(DCF!$D$4,"RTP_SALES(ANN,-7)")} -> 2847.26 | H6: {=_xll.FDSLIVE(DCF!$D$4,"RTP_SALES(ANN,-6)")} -> 2689.3081 | I6: {=_xll.FDSLIVE(DCF!$D$4,"RTP_SALES(ANN,-5)")} -> 2105.322 | J6: {=_xll.FDSLIVE(DCF!$D$4,"RTP_SALES(ANN,-4)")} -> 2248.74 | K6: {=_xll.FDSLIVE(DCF!$D$4,"RTP_SALES(ANN,-3)")} -> 2495.0459 | L6: {=_xll.FDSLIVE(DCF!$D$4,"RTP_SALES(ANN,-2)")} -> 2232.5669 | M6: {=_xll.FDSLIVE(DCF!$D$4,"RTP_SALES(ANN,-1)")} -> 2442.7529 | N6: {=_xll.FDSLIVE(DCF!$D$4,"RTP_SALES(ANN,0)")} -> 2906.345 | O6: ='Revenue Build'!O12 -> 3487.614 | P6: ='Revenue Build'!P12 -> 4080.5084 | Q6: ='Revenue Build'!Q12 -> 4651.7796 | R6: ='Revenue Build'!R12 -> 5116.9575 | S6: ='Revenue Build'!S12 -> 5475.1445
B7: Active Case
A9: 3 | B9: COGS (excl. D&A) | E9: =IS!B12 -> 1953.5 | F9: =IS!C12 -> 2078.2 | G9: =IS!D12 -> 2224.2 | H9: =IS!E12 -> 1657.8 | I9: =IS!F12 -> 1641.2 | J9: =IS!G12 -> 1785.1 | K9: =IS!H12 -> 1940.3 | L9: =IS!I12 -> 1707.2 | ... N9: =IS!K12 -> 2185 | O9: =O10*O$6 -> 2574.0375 | P9: =P10*P$6 -> 2897.1609 | Q9: =Q10*Q$6 -> 3279.5046 | R9: =R10*R$6 -> 3581.8703 | S9: =S10*S$6 -> 3777.8497 | T9: Pull COGS Manually From FactSet
B10: % of sales | E10: =E9/E$6 -> 0.77111332 | F10: =F9/F6 -> 0.78169253 | G10: =G9/G6 -> 0.78117207 | H10: =H9/H6 -> 0.61644108 | I10: =I9/I6 -> 0.7795482 | J10: =J9/J6 -> 0.79382232 | K10: =K9/K6 -> 0.77766104 | L10: =L9/L6 -> 0.76468033 | M10: =M9/M6 -> 0.75766975 | N10: =N9/N6 -> 0.75180338 | O10: =CHOOSE($A9,O11,O12,O13) -> 0.73805116 | P10: =CHOOSE($A9,P11,P12,P13) -> 0.71 | Q10: =CHOOSE($A9,Q11,Q12,Q13) -> 0.705 | R10: =CHOOSE($A9,R11,R12,R13) -> 0.7 | S10: =CHOOSE($A9,S11,S12,S13) -> 0.69
B11: Conservative | O11: =O12+2% -> 0.77805116 | P11: =P12+2% -> 0.75 | Q11: =Q12+2% -> 0.745 | R11: =R12+2% -> 0.74 | S11: =S12+2% -> 0.73
B12: Base (Street) | O12: =AVERAGE(L10:N10) -> 0.75805116 | P12: 0.73 | Q12: 0.725 | R12: 0.72 | S12: 0.71
B13: Optimistic | O13: =O12-2% -> 0.73805116 | P13: =P12-2% -> 0.71 | Q13: =Q12-2% -> 0.705 | R13: =R12-2% -> 0.7 | S13: =S12-2% -> 0.69
A15: 2 | B15: D&A | E15: =IS!B13 -> 180.3 | F15: =IS!C13 -> 174.3 | G15: =IS!D13 -> 225.6 | H15: =IS!E13 -> 144 | I15: =IS!F13 -> 143.9 | J15: =IS!G13 -> 127.3 | K15: =IS!H13 -> 133.9 | L15: =IS!I13 -> 160.7 | ... N15: =IS!K13 -> 147.2 | O15: =O16*O$6 -> 209.25684 | P15: =P16*P$6 -> 244.8305 | Q15: =Q16*Q$6 -> 274.45499 | R15: =R16*R$6 -> 296.78354 | S15: =S16*S$6 -> 312.08324 | T15: Pull D&A Manually From FactSet
B16: % of sales | E16: =E15/E$6 -> 0.071170582 | F16: =F15/F$6 -> 0.065561066 | G16: =G15/G$6 -> 0.07923407 | H16: =H15/H$6 -> 0.053545371 | I16: =I15/I$6 -> 0.068350589 | J16: =J15/J$6 -> 0.056609479 | K16: =K15/K$6 -> 0.053666347 | L16: =L15/L$6 -> 0.071979926 | ... N16: =N15/N$6 -> 0.050647807 | O16: =CHOOSE($A15,O17,O18,O19) -> 0.06 | P16: =CHOOSE($A15,P17,P18,P19) -> 0.06 | Q16: =CHOOSE($A15,Q17,Q18,Q19) -> 0.059 | R16: =CHOOSE($A15,R17,R18,R19) -> 0.058 | S16: =CHOOSE($A15,S17,S18,S19) -> 0.057
B17: Conservative | O17: 0.061 | P17: 0.061 | Q17: 0.06 | R17: 0.059 | S17: 0.058
B18: Base (Street) | O18: 0.06 | P18: 0.06 | Q18: 0.059 | R18: 0.058 | S18: 0.057
B19: Optimistic | O19: 0.059 | P19: 0.059 | Q19: 0.058 | R19: 0.057 | S19: 0.056
A21: 2 | B21: SG&A | E21: =IS!B17 -> 211.9 | F21: =IS!C17 -> 189.7 | G21: =IS!D17 -> 219.5 | H21: =IS!E17 -> 216.4 | I21: =IS!F17 -> 199.4 | J21: =IS!G17 -> 199.3 | K21: =IS!H17 -> 246.6 | L21: =IS!I17 -> 253.2 | ... N21: =IS!K17 -> 306.6 | O21: =O22*O$6 -> 331.32333 | P21: =P22*P$6 -> 375.40677 | Q21: =Q22*Q$6 -> 409.3566 | R21: =R22*R$6 -> 434.94139 | S21: =S22*S$6 -> 454.437 | T21: Pull SG&A Manually From FactSet
B22: % of sales | E22: =E21/E$6 -> 0.083644183 | F22: =F21/F$6 -> 0.07135361 | G22: =G21/G$6 -> 0.07709166 | H22: =H21/H$6 -> 0.080466794 | I22: =I21/I$6 -> 0.094712352 | J22: =J21/J$6 -> 0.08862741 | K22: =K21/K$6 -> 0.098835857 | L22: =L21/L$6 -> 0.11341206 | ... N22: =N21/N$6 -> 0.10549333 | O22: =CHOOSE($A21,O23,O24,O25) -> 0.095 | P22: =CHOOSE($A21,P23,P24,P25) -> 0.092 | Q22: =CHOOSE($A21,Q23,Q24,Q25) -> 0.088 | R22: =CHOOSE($A21,R23,R24,R25) -> 0.085 | S22: =CHOOSE($A21,S23,S24,S25) -> 0.083
B23: Conservative | O23: 0.1 | P23: 0.097 | Q23: 0.094 | R23: 0.091 | S23: 0.088
B24: Base (Street) | O24: 0.095 | P24: 0.092 | Q24: 0.088 | R24: 0.085 | S24: 0.083
B25: Optimistic | O25: 0.093 | P25: 0.089 | Q25: 0.085 | R25: 0.082 | S25: 0.08
A27: 2 | B27: Operating Expenses | E27: 0 | F27: 0 | G27: 0 | H27: 0 | I27: 0 | J27: 0 | K27: 0 | L27: 0 | M27: 0 | N27: 0 | O27: 0 | P27: 0 | Q27: 0 | R27: 0 | S27: 0
B28: % of sales | E28: =E27/E$6 -> 0 | F28: =F27/F$6 -> 0 | G28: =G27/G$6 -> 0 | H28: =H27/H$6 -> 0 | I28: =I27/I$6 -> 0 | J28: =J27/J$6 -> 0 | K28: =K27/K$6 -> 0 | L28: =L27/L$6 -> 0 | ... N28: =N27/N$6 -> 0 | O28: =CHOOSE($A27,O29,O30,O31) -> 0 | P28: =CHOOSE($A27,P29,P30,P31) -> 0 | Q28: =CHOOSE($A27,Q29,Q30,Q31) -> 0 | R28: =CHOOSE($A27,R29,R30,R31) -> 0 | S28: =CHOOSE($A27,S29,S30,S31) -> 0
B29: Conservative | O29: 0 | P29: 0 | Q29: 0 | R29: 0 | S29: 0
B30: Base (Street) | O30: 0 | P30: 0 | Q30: 0 | R30: 0 | S30: 0
B31: Optimistic | O31: 0 | P31: 0 | Q31: 0 | R31: 0 | S31: 0
A33: 2 | B33: Nonoperating Income | E33: =IS!B21 -> 17.1 | F33: =IS!C21 -> -18.3 | G33: =IS!D21 -> 7.9 | H33: =IS!E21 -> 4.5 | I33: =IS!F21 -> -10.2 | J33: =IS!G21 -> -6.5 | K33: =IS!H21 -> 65.7 | L33: =IS!I21 -> 4 | ... N33: =IS!K21 -> -10.9 | O33: =O34*$O$9 -> 25.740375 | P33: =P34*$O$9 -> 25.740375 | Q33: =Q34*$O$9 -> 25.740375 | R33: =R34*$O$9 -> 25.740375 | S33: =S34*$O$9 -> 25.740375
B34: % of COGS | E34: =E33/E$9 -> 0.0087535193 | F34: =F33/F$9 -> -0.0088056972 | G34: =G33/G$9 -> 0.0035518389 | H34: =H33/H$9 -> 0.0027144408 | I34: =I33/I$9 -> -0.0062149647 | J34: =J33/J$9 -> -0.0036412526 | K34: =K33/K$9 -> 0.033860743 | L34: =L33/L$9 -> 0.0023430178 | ... N34: =N33/N$9 -> -0.0049885584 | O34: =CHOOSE($A33,O35,O36,O37) -> 0.01 | P34: =CHOOSE($A33,P35,P36,P37) -> 0.01 | Q34: =CHOOSE($A33,Q35,Q36,Q37) -> 0.01 | R34: =CHOOSE($A33,R35,R36,R37) -> 0.01 | S34: =CHOOSE($A33,S35,S36,S37) -> 0.01
B35: Conservative | O35: 0.005 | P35: 0.005 | Q35: 0.005 | R35: 0.005 | S35: 0.005
B36: Base (Street) | O36: 0.01 | P36: 0.01 | Q36: 0.01 | R36: 0.01 | S36: 0.01
B37: Optimistic | O37: 0.015 | P37: 0.015 | Q37: 0.015 | R37: 0.015 | S37: 0.015
A44: 2 | B44: CapEx | E44: =-CFS!B27 -> 85.139 | F44: =-CFS!C27 -> 151.345 | G44: =-CFS!D27 -> 150.127 | H44: =-CFS!E27 -> 142.576 | I44: =-CFS!F27 -> 103.289 | J44: =-CFS!G27 -> 81.951 | K44: =-CFS!H27 -> 102.884 | L44: =-CFS!I27 -> 160.242 | ... N44: =-CFS!K27 -> 292.565 | O44: =O45*O$6 -> 261.57105 | P44: =P45*P$6 -> 285.63559 | Q44: =Q45*Q$6 -> 302.36567 | R44: =R45*R$6 -> 307.01745 | S44: =S45*S$6 -> 301.13295 | T44: Pull CapEx Manually from FactSet, THIS IS FOUND ON CASH FLOW STATEMENT
B45: % of sales | E45: =E44/E$6 -> 0.033607278 | F45: =F44/F$6 -> 0.05692679 | G45: =G44/G$6 -> 0.052726832 | H45: =H44/H$6 -> 0.053015867 | I45: =I44/I$6 -> 0.049060903 | J45: =J44/J$6 -> 0.036443075 | K45: =K44/K$6 -> 0.041235314 | L45: =L44/L$6 -> 0.071774781 | ... N45: =N44/N$6 -> 0.10066424 | O45: =CHOOSE($A44,O46,O47,O48) -> 0.075 | P45: =CHOOSE($A44,P46,P47,P48) -> 0.07 | Q45: =CHOOSE($A44,Q46,Q47,Q48) -> 0.065 | R45: =CHOOSE($A44,R46,R47,R48) -> 0.06 | S45: =CHOOSE($A44,S46,S47,S48) -> 0.055
B46: Conservative | O46: 0.07 | P46: 0.065 | Q46: 0.06 | R46: 0.055 | S46: 0.05
B47: Base (Street) | O47: 0.075 | P47: 0.07 | Q47: 0.065 | R47: 0.06 | S47: 0.055
B48: Optimistic | O48: 0.08 | P48: 0.075 | Q48: 0.07 | R48: 0.065 | S48: 0.06

Sheet Operating Model
B2: Operating Model
A5: x | B5: Operating Model | C5: =D5-1 -> 2016 | D5: =E5-1 -> 2017 | E5: =F5-1 -> 2018 | F5: =G5-1 -> 2019 | G5: =H5-1 -> 2020 | H5: =I5-1 -> 2021 | I5: =J5-1 -> 2022 | J5: =K5-1 -> 2023 | ... L5: =M5-1 -> 2025 | M5: =DCF!O16 -> 2026 | N5: =M5+1 -> 2027 | O5: =N5+1 -> 2028 | P5: =O5+1 -> 2029 | Q5: =P5+1 -> 2030
B6: Revenue | C6: ='Case Assumptions'!E6 -> 2533.3501 | D6: ='Case Assumptions'!F6 -> 2658.5901 | E6: ='Case Assumptions'!G6 -> 2847.26 | F6: ='Case Assumptions'!H6 -> 2689.3081 | G6: ='Case Assumptions'!I6 -> 2105.322 | H6: ='Case Assumptions'!J6 -> 2248.74 | I6: ='Case Assumptions'!K6 -> 2495.0459 | J6: ='Case Assumptions'!L6 -> 2232.5669 | ... Q6: ='Case Assumptions'!S6 -> 5475.1445
B7: % Growth YoY | D7: =(D6-C6)/D6 -> 0.047107672 | E7: =(E6-D6)/E6 -> 0.066263678 | F7: =(F6-E6)/F6 -> -0.058733287 | G7: =(G6-F6)/G6 -> -0.27738563 | H7: =(H6-G6)/H6 -> 0.063777035 | I7: =(I6-H6)/I6 -> 0.098717987 | J7: =(J6-I6)/J6 -> -0.11756826 | K7: =(K6-J6)/K6 -> 0.086044738 | ... Q7: =(Q6-P6)/Q6 -> 0.065420561
B9: COGS (excl. D&A) | C9: ='Case Assumptions'!E9 -> 1953.5 | D9: ='Case Assumptions'!F9 -> 2078.2 | E9: ='Case Assumptions'!G9 -> 2224.2 | F9: ='Case Assumptions'!H9 -> 1657.8 | G9: ='Case Assumptions'!I9 -> 1641.2 | H9: ='Case Assumptions'!J9 -> 1785.1 | I9: ='Case Assumptions'!K9 -> 1940.3 | J9: ='Case Assumptions'!L9 -> 1707.2 | ... Q9: ='Case Assumptions'!S9 -> 3777.8497
B10: % Sales | D10: =(D9-C9)/D9 -> 0.060003849 | E10: =(E9-D9)/E9 -> 0.065641579 | F10: =(F9-E9)/F9 -> -0.34165762 | G10: =(G9-F9)/G9 -> -0.01011455 | H10: =(H9-G9)/H9 -> 0.08061173 | I10: =(I9-H9)/I9 -> 0.079987631 | J10: =(J9-I9)/J9 -> -0.13653936 | K10: =(K9-J9)/K9 -> 0.07758807 | ... Q10: =(Q9-P9)/Q9 -> 0.051875931
B12: Gross Profit | C12: =C6-C9 -> 579.8501 | D12: =D6-D9 -> 580.39009 | E12: =E6-E9 -> 623.06001 | F12: =F6-F9 -> 1031.5081 | G12: =G6-G9 -> 464.12202 | H12: =H6-H9 -> 463.63999 | I12: =I6-I9 -> 554.7459 | J12: =J6-J9 -> 525.36689 | ... Q12: =Q6-Q9 -> 1697.2948
B13: Margin | C13: =C12/C6 -> 0.22888668 | D13: =D12/D6 -> 0.21830747 | E13: =E12/E6 -> 0.21882793 | F13: =F12/F6 -> 0.38355892 | G13: =G12/G6 -> 0.2204518 | H13: =H12/H6 -> 0.20617768 | I13: =I12/I6 -> 0.22233896 | J13: =J12/J6 -> 0.23531967 | ... Q13: =Q12/Q6 -> 0.31
B15: Depreciation and Amortization | C15: ='Case Assumptions'!E15 -> 180.3 | D15: ='Case Assumptions'!F15 -> 174.3 | E15: ='Case Assumptions'!G15 -> 225.6 | F15: ='Case Assumptions'!H15 -> 144 | G15: ='Case Assumptions'!I15 -> 143.9 | H15: ='Case Assumptions'!J15 -> 127.3 | I15: ='Case Assumptions'!K15 -> 133.9 | J15: ='Case Assumptions'!L15 -> 160.7 | ... Q15: ='Case Assumptions'!S15 -> 312.08324
B16: % Sales | D16: =(D15-C15)/D15 -> -0.034423408 | E16: =(E15-D15)/E15 -> 0.22739362 | F16: =(F15-E15)/F15 -> -0.56666667 | G16: =(G15-F15)/G15 -> -0.00069492703 | H16: =(H15-G15)/H15 -> -0.13040063 | I16: =(I15-H15)/I15 -> 0.049290515 | J16: =(J15-I15)/J15 -> 0.16677038 | K16: =(K15-J15)/K15 -> -0.070619587 | ... Q16: =(Q15-P15)/Q15 -> 0.04902443
B18: Selling, General, and Administrative | C18: ='Case Assumptions'!E21 -> 211.9 | D18: ='Case Assumptions'!F21 -> 189.7 | E18: ='Case Assumptions'!G21 -> 219.5 | F18: ='Case Assumptions'!H21 -> 216.4 | G18: ='Case Assumptions'!I21 -> 199.4 | H18: ='Case Assumptions'!J21 -> 199.3 | I18: ='Case Assumptions'!K21 -> 246.6 | J18: ='Case Assumptions'!L21 -> 253.2 | ... Q18: ='Case Assumptions'!S21 -> 454.437
B19: % Sales | D19: =(D18-C18)/D18 -> -0.11702688 | E19: =(E18-D18)/E18 -> 0.1357631 | F19: =(F18-E18)/F18 -> -0.014325323 | G19: =(G18-F18)/G18 -> -0.085255767 | H19: =(H18-G18)/H18 -> -0.00050175615 | I19: =(I18-H18)/I18 -> 0.1918086 | J19: =(J18-I18)/J18 -> 0.026066351 | K19: =(K18-J18)/K18 -> 0.10212766 | ... Q19: =(Q18-P18)/Q18 -> 0.042900574
B21: Operating Expenses | C21: 0 | D21: 0 | E21: 0 | F21: 0 | G21: 0 | H21: 0 | I21: 0 | J21: 0 | K21: 0 | L21: 0 | M21: 0 | N21: 0 | O21: 0 | P21: 0 | Q21: 0
B22: % Sales
B24: Operating Profit (EBIT) | C24: =C12-C15-C18-C21 -> 187.6501 | D24: =D12-D15-D18-D21 -> 216.39009 | E24: =E12-E15-E18-E21 -> 177.96001 | F24: =F12-F15-F18-F21 -> 671.10811 | G24: =G12-G15-G18-G21 -> 120.82202 | H24: =H12-H15-H18-H21 -> 137.03999 | I24: =I12-I15-I18-I21 -> 174.2459 | J24: =J12-J15-J18-J21 -> 111.46689 | ... Q24: =Q12-Q15-Q18-Q21 -> 930.77457
B25: CHECK (HIDE ROW) | C25: =IS!K19 -> 277.6 | D25: =IS!J19 -> 250.1 | E25: =IS!I19 -> 226 | F25: =IS!H19 -> 221.8 | G25: =IS!G19 -> 181.2 | H25: =IS!F19 -> 179.7 | I25: =IS!E19 -> 198.5 | J25: =IS!D19 -> 219.5 | K25: =IS!C19 -> 189.7 | L25: =IS!B19 -> 211.9
B27: Nonoperating Income - Net | C27: ='Case Assumptions'!E33 -> 17.1 | D27: ='Case Assumptions'!F33 -> -18.3 | E27: ='Case Assumptions'!G33 -> 7.9 | F27: ='Case Assumptions'!H33 -> 4.5 | G27: ='Case Assumptions'!I33 -> -10.2 | H27: ='Case Assumptions'!J33 -> -6.5 | I27: ='Case Assumptions'!K33 -> 65.7 | J27: ='Case Assumptions'!L33 -> 4 | ... Q27: ='Case Assumptions'!S33 -> 25.740375
B28: % COGS | D28: =(D27-C27)/$M$9 -> -0.013752713 | E28: =(E27-D27)/$M$9 -> 0.010178562 | F28: =(F27-E27)/$M$9 -> -0.0013208821 | G28: =(G27-F27)/$M$9 -> -0.0057108724 | H28: =(H27-G27)/$M$9 -> 0.0014374305 | I28: =(I27-H27)/$M$9 -> 0.028049319 | J28: =(J27-I27)/$M$9 -> -0.023970124 | K28: =(K27-J27)/$M$9 -> 0.002797162 | ... Q28: =(Q27-P27)/$M$9 -> 0
B30: Other Expenses | C30: =(C24+C27)-C33 -> 137.7501 | D30: =(D24+D27)-D33 -> 58.090088 | E30: =(E24+E27)-E33 -> 96.06001 | F30: =(F24+F27)-F33 -> 641.30811 | G30: =(G24+G27)-G33 -> 156.92202 | H30: =(H24+H27)-H33 -> 60.43999 | I30: =(I24+I27)-I33 -> 57.045898 | J30: =(J24+J27)-J33 -> 115.16689 | ... L30: =(L24+L27)-L33 -> 46.345 | M30: =M31*M9 -> 3.8610563 | N30: =N31*N9 -> 4.3457414 | O30: =O31*O9 -> 4.9192569 | P30: =P31*P9 -> 5.3728054 | Q30: =Q31*Q9 -> 5.6667746
B31: % COGS | D31: =(D30-C30)/$M$9 -> -0.030947493 | E31: =(E30-D30)/$M$9 -> 0.014751114 | F31: =(F30-E30)/$M$9 -> 0.21182601 | G31: =(G30-F30)/$M$9 -> -0.18818144 | H31: =(H30-G30)/$M$9 -> -0.03748276 | I31: =(I30-H30)/$M$9 -> -0.0013185868 | J31: =(J30-I30)/$M$9 -> 0.0225797 | K31: =(K30-J30)/$M$9 -> -0.010883277 | L31: =(L30-K30)/$M$9 -> -0.015853665 | M31: 0.0015 | N31: 0.0015 | O31: 0.0015 | P31: 0.0015 | Q31: 0.0015
B33: Pretax Income (Loss) | C33: =IS!B34 -> 67 | D33: =IS!C34 -> 140 | E33: =IS!D34 -> 89.8 | F33: =IS!E34 -> 34.3 | G33: =IS!F34 -> -46.3 | H33: =IS!G34 -> 70.1 | I33: =IS!H34 -> 182.9 | J33: =IS!I34 -> 0.3 | ... L33: =IS!K34 -> 210.3 | M33: =M24+M27-M30 -> 394.87561 | N33: =N24+N27-N30 -> 584.50479 | O33: =O24+O27-O30 -> 709.28449 | P33: =P24+P27-P30 -> 823.7299 | Q33: =Q24+Q27-Q30 -> 950.84817
B35: Income Taxes | C35: =IS!B35 -> 31.4 | D35: =IS!C35 -> 15.2 | E35: =IS!D35 -> -83.8 | F35: =IS!E35 -> 2.4 | G35: =IS!F35 -> -29.9 | H35: =IS!G35 -> 15.6 | I35: =IS!H35 -> 88.3 | J35: =IS!I35 -> 19 | ... L35: =IS!K35 -> 32.9 | M35: =M36*M33 -> 90.82139 | N35: =N36*N33 -> 139.61835 | O35: =O36*O33 -> 147.84071 | P35: =P36*P33 -> 185.97143 | Q35: =Q36*Q33 -> 213.3291
B36: Tax Rate (%) | C36: =C35/C33 -> 0.46865672 | D36: =D35/D33 -> 0.10857143 | E36: =E35/E33 -> -0.93318486 | F36: =F35/F33 -> 0.069970845 | G36: =G35/G33 -> 0.64578834 | H36: =H35/H33 -> 0.22253923 | I36: =I35/I33 -> 0.48277747 | J36: =J35/J33 -> 63.333333 | ... L36: =L35/L33 -> 0.15644318 | M36: 0.23 | N36: =AVERAGE(K36:M36) -> 0.23886604 | O36: =AVERAGE(L36:N36) -> 0.20843641 | P36: =AVERAGE(M36:O36) -> 0.22576748 | Q36: =AVERAGE(N36:P36) -> 0.22435664
B38: Net Income | C38: =C33-C35 -> 35.6 | D38: =D33-D35 -> 124.8 | E38: =E33-E35 -> 173.6 | F38: =F33-F35 -> 31.9 | G38: =G33-G35 -> -16.4 | H38: =H33-H35 -> 54.5 | I38: =I33-I35 -> 94.6 | J38: =J33-J35 -> -18.7 | ... Q38: =Q33-Q35 -> 737.51907
B39: CHECK | C39: =IS!B40 -> 35.6 | D39: =IS!C40 -> 124.7 | E39: =IS!D40 -> 173.6 | F39: =IS!E40 -> 31.9 | G39: =IS!F40 -> -16.4 | H39: =IS!G40 -> 54.4 | I39: =IS!H40 -> 94.6 | J39: =IS!I40 -> -18.7 | ... L39: =IS!K40 -> 177.4

Sheet Working Cap Schedule
B2: Working Capital Schedule
A5: x | B5: Working Capital | E5: =F5-1 -> 2016 | F5: =G5-1 -> 2017 | G5: =H5-1 -> 2018 | H5: =I5-1 -> 2019 | I5: =J5-1 -> 2020 | J5: =K5-1 -> 2021 | K5: =L5-1 -> 2022 | L5: =M5-1 -> 2023 | ... N5: =O5-1 -> 2025 | O5: =DCF!O16 -> 2026 | P5: =O5+1 -> 2027 | Q5: =P5+1 -> 2028 | R5: =Q5+1 -> 2029 | S5: =R5+1 -> 2030
B6: Current Assets
B7: Accounts Recievables | K7: =BS!B10 -> 432.788 | L7: =BS!C10 -> 483.903 | M7: =BS!D10 -> 810.906 | N7: =BS!E10 -> 758.198 | O7: =O8*'Operating Model'!M$6 -> 909.8376 | P7: =P8*'Operating Model'!N$6 -> 1064.51 | Q7: =Q8*'Operating Model'!O$6 -> 1213.5414 | R7: =R8*'Operating Model'!P$6 -> 1334.8955 | S7: =S8*'Operating Model'!Q$6 -> 1428.3382
B8: % Revenue | K8: =K7/'Operating Model'!I$6 -> 0.17345893 | L8: =L7/'Operating Model'!J$6 -> 0.21674737 | M8: =M7/'Operating Model'!K$6 -> 0.33196399 | N8: =N7/'Operating Model'!L$6 -> 0.26087681 | O8: =N8 -> 0.26087681 | P8: =O8 -> 0.26087681 | Q8: =P8 -> 0.26087681 | R8: =Q8 -> 0.26087681 | S8: =R8 -> 0.26087681
B10: Inventories | K10: =BS!B14 -> 269.212 | L10: =BS!C14 -> 294.588 | M10: =BS!D14 -> 109.377 | N10: =BS!E14 -> 113.753 | O10: =O11*'Operating Model'!M$6 -> 136.5036 | P10: =P11*'Operating Model'!N6 -> 159.70921 | Q10: =Q11*'Operating Model'!O6 -> 182.0685 | R10: =R11*'Operating Model'!P6 -> 200.27535 | S10: =S11*'Operating Model'!Q6 -> 214.29463
B11: % Revenue | K11: =K10/'Operating Model'!I$6 -> 0.10789862 | L11: =L10/'Operating Model'!J$6 -> 0.13195036 | M11: =M10/'Operating Model'!K$6 -> 0.044776121 | N11: =N10/'Operating Model'!L$6 -> 0.039139538 | O11: =N11 -> 0.039139538 | P11: =O11 -> 0.039139538 | Q11: =P11 -> 0.039139538 | R11: =Q11 -> 0.039139538 | S11: =R11 -> 0.039139538
B13: Total CA | J13: ='Case Assumptions'!J6 -> 2248.74 | K13: =K7+K10 -> 702 | L13: =L7+L10 -> 778.491 | M13: =M7+M10 -> 920.283 | N13: =N7+N10 -> 871.951 | O13: =O7+O10 -> 1046.3412 | P13: =P7+P10 -> 1224.2192 | Q13: =Q7+Q10 -> 1395.6099 | R13: =R7+R10 -> 1535.1709 | S13: =S7+S10 -> 1642.6328
B15: Current Liabilities
B16: Accounts Payable | K16: =BS!B43 -> 371.61 | L16: =BS!C43 -> 438.99 | M16: =BS!D43 -> 431.288 | N16: =BS!E43 -> 329.866 | O16: =O17*'Operating Model'!M$18 -> 479.20859 | P16: =P17*'Operating Model'!N$18 -> 507.00201 | Q16: =Q17*'Operating Model'!O$18 -> 528.4482 | R16: =R17*'Operating Model'!P$18 -> 592.6528 | S16: =S17*'Operating Model'!Q$18 -> 606.53222
B17: % SG&A | K17: =K16/'Operating Model'!I$18 -> 1.5069343 | L17: =L16/'Operating Model'!J$18 -> 1.7337678 | M17: =M16/'Operating Model'!K$18 -> 1.5293901 | N17: =N16/'Operating Model'!L$18 -> 1.0758839 | O17: =AVERAGE(L17:N17) -> 1.4463472 | P17: =AVERAGE(M17:O17) -> 1.3505404 | Q17: =AVERAGE(N17:P17) -> 1.2909238 | R17: =AVERAGE(O17:Q17) -> 1.3626038 | S17: =AVERAGE(P17:R17) -> 1.3346894
B19: Other Accruals | K19: =BS!B46 -> 97.171 | L19: =BS!C46 -> 103.638 | M19: =BS!D46 -> 94.95 | N19: =BS!E46 -> 85.114 | O19: =O20*'Operating Model'!M$18 -> 113.04983 | P19: =P20*'Operating Model'!N$18 -> 119.56895 | Q19: =Q20*'Operating Model'!O$18 -> 127.8991 | R19: =R20*'Operating Model'!P$18 -> 140.94295 | S19: =S20*'Operating Model'!Q$18 -> 144.66166
B20: % SG&A | K20: =K19/'Operating Model'!I$18 -> 0.39404298 | L20: =L19/'Operating Model'!J$18 -> 0.4093128 | M20: =M19/'Operating Model'!K$18 -> 0.33670213 | N20: =N19/'Operating Model'!L$18 -> 0.277606 | O20: =AVERAGE(L20:N20) -> 0.34120698 | P20: =AVERAGE(M20:O20) -> 0.31850503 | Q20: =AVERAGE(N20:P20) -> 0.31243934 | R20: =AVERAGE(O20:Q20) -> 0.32405045 | S20: =AVERAGE(P20:R20) -> 0.31833161
B22: =CFS!A24 -> Other Assets/Liabilities | O22: =O23*'Operating Model'!M$18 -> 0 | P22: =P23*'Operating Model'!N$18 -> 0 | Q22: =Q23*'Operating Model'!O$18 -> 0 | R22: =R23*'Operating Model'!P$18 -> 0 | S22: =S23*'Operating Model'!Q$18 -> 0
B23: % SG&A | K23: =K22/'Operating Model'!I$18 -> 0 | L23: =L22/'Operating Model'!J$18 -> 0 | M23: =M22/'Operating Model'!K$18 -> 0 | N23: =N22/'Operating Model'!L$18 -> 0 | O23: =AVERAGE(L23:N23) -> 0 | P23: =AVERAGE(M23:O23) -> 0 | Q23: =AVERAGE(N23:P23) -> 0 | R23: =AVERAGE(O23:Q23) -> 0 | S23: =AVERAGE(P23:R23) -> 0
B25: Total CL | J25: ='Case Assumptions'!J22 -> 0.08862741 | K25: =K16+K19+K22 -> 468.781 | L25: =L16+L19+L22 -> 542.628 | M25: =M16+M19+M22 -> 526.238 | N25: =N16+N19+N22 -> 414.98 | O25: =O16+O19+O22 -> 592.25842 | P25: =P16+P19+P22 -> 626.57096 | Q25: =Q16+Q19+Q22 -> 656.3473 | R25: =R16+R19+R22 -> 733.59575 | S25: =S16+S19+S22 -> 751.19388
B27: Net Working Capital | J27: ='Case Assumptions'!J24 -> 0 | K27: =K13-K25 -> 233.219 | L27: =L13-L25 -> 235.863 | M27: =M13-M25 -> 394.045 | N27: =N13-N25 -> 456.971 | O27: =O13-O25 -> 454.08278 | P27: =P13-P25 -> 597.64825 | Q27: =Q13-Q25 -> 739.26259 | R27: =R13-R25 -> 801.57513 | S27: =S13-S25 -> 891.43896
B28: Change in NWC | L28: =L27-K27 -> 2.644 | M28: =M27-L27 -> 158.182 | N28: =N27-M27 -> 62.926 | O28: =O27-N27 -> -2.8882163 | P28: =P27-O27 -> 143.56546 | Q28: =Q27-P27 -> 141.61434 | R28: =R27-Q27 -> 62.312537 | S28: =S27-R27 -> 89.863833
M1048576: =SUM(M1:M1048575) -> 5471.5118

Sheet Public Comps Analysis
B2: Public Comps Analysis
B5: Enter Ticker Symbols Below
B6: Comparable Company 1 | C6: JBL-USA
B7: Comparable Company 2 | C7: SANM-USA
B8: Comparable Company 3 | C8: FLEX-USA
B9: Comparable Company 4 | C9: PLXS-USA
B10: Comparable Company 5 | C10: BHE-USA
B11: Comparable Company 6 | C11: CLS-USA
B12: Comparable Company 7 | C12: FN-USA
B13: Comparable Company 8
B14: Comparable Company 9
B15: Comparable Company 10
D18: Market Data ($) | J18: Financials ($) | T18: Growth and Margins (%) | AA18: Valuation Multiples (x)
E19: Share | F19: Share | G19: Market | H19: Enterprise | J19: Revenue | M19: EBIT | O19: EBITDA | Q19: Net Income | T19: Revenue Growth | V19: EBITDA Margin | X19: Profit Margin | AA19: EV/Revenue | AC19: EV/EBITDA | AE19: P/E
B20: Company Name | D20: Ticker | E20: Price | F20: Count | G20: Cap | H20: Value | J20: =_xlfn.CONCAT("'",RIGHT(DCF!M16,2)) -> '24 | K20: =_xlfn.CONCAT("'",RIGHT(DCF!N16,2)) -> '25 | L20: =_xlfn.CONCAT("'",RIGHT(DCF!O16,2)) -> '26 | M20: =K20 -> '25 | N20: =L20 -> '26 | O20: =M20 -> '25 | P20: =N20 -> '26 | Q20: =O20 -> '25 | R20: =P20 -> '26 | T20: =_xlfn.CONCAT(J20,"-",K20) -> '24-'25 | U20: =_xlfn.CONCAT(K20,"-",L20) -> '25-'26 | V20: =O20 -> '25 | W20: =P20 -> '26 | X20: =O20 -> '25 | Y20: =P20 -> '26 | AA20: =V20 -> '25 | AB20: =Y20 -> '26 | AC20: =AA20 -> '25 | AD20: =AB20 -> '26 | AE20: =AC20 -> '25 | AF20: =AD20 -> '26
B22: {=_xll.FDSLIVE(D22,"RTP_NAME")} -> TTM Technologies, Inc. | D22: =DCF!D4 -> TTMI-USA | E22: {=_xll.FDSLIVE(D22,"RTP_PRICE")} -> 95.47 | F22: {=_xll.FDSLIVE(D22,"RTP_SHS_OUT")} -> 103.40492 | G22: 10185.79 | H22: 8010.41 | J22: {=_xll.FDSLIVE($D22,"RTP_SALES(ANN,-1)")} -> 2442.7529 | K22: {=_xll.FDSLIVE($D22,"RTP_SALES(ANN,0)")} -> 2906.345 | L22: {=_xll.FDSLIVE($D22,"RTP_SALES(ANN,+1)")} -> 3404.051 | M22: {=_xll.FDSLIVE(D22,"RTP_EBIT(ANN,0)")} -> 267.531 | N22: {=_xll.FDSLIVE(D22,"RTP_EBIT(ANN,+1)")} -> 429.75781 | O22: {=_xll.FDSLIVE($D22,"RTP_EBITDA(ANN,0)")} -> 414.702 | P22: {=_xll.FDSLIVE($D22,"RTP_EBITDA(ANN,+1)")} -> 550.98151 | Q22: {=_xll.FDSLIVE($D22,"RTP_NET_INC(ANN,0)")} -> 177.448 | R22: {=_xll.FDSLIVE($D22,"RTP_NET_INC(ANN,+1)")} -> 343.6524 | T22: =(K22-J22)/J22 -> 0.18978263 | U22: =(L22-K22)/K22 -> 0.17124809 | V22: =O22/K22 -> 0.1426885 | W22: =P22/L22 -> 0.16186053 | X22: =Q22/K22 -> 0.061055381 | Y22: =R22/L22 -> 0.10095395 | AA22: =H22/K22 -> 2.75618 | AB22: =H22/L22 -> 2.3531992 | AC22: =H22/O22 -> 19.316063 | AD22: =H22/P22 -> 14.538437 | AE22: {=$E22/(_xll.FDSLIVE(D22,"RTP_EPS(ANN,0)"))} -> 56.736198 | AF22: {=$E22/(_xll.FDSLIVE(D22,"RTP_EPS(ANN,+1)"))} -> 56.736198
A24: 1 | B24: {=_xll.FDSLIVE(D24,"RTP_NAME")} -> Jabil Inc. | D24: =C6 -> JBL-USA | E24: 261.1 | F24: {=_xll.FDSLIVE(D24,"RTP_SHS_OUT")} -> 105.59527 | G24: {=_xll.FDSLIVE(D24,"RTP_MKT_CAP")} -> 27570.926 | H24: {=_xll.FDSLIVE(D24,"RTP_EV_EST(+1)")} -> 29436.361 | J24: {=_xll.FDSLIVE($D24,"RTP_SALES(ANN,-1)")} -> 28883 | K24: {=_xll.FDSLIVE($D24,"RTP_SALES(ANN,0)")} -> 29802 | L24: {=_xll.FDSLIVE($D24,"RTP_SALES(ANN,+1)")} -> 34069.359 | M24: {=_xll.FDSLIVE(D24,"RTP_EBIT(ANN,0)")} -> 1486 | N24: {=_xll.FDSLIVE(D24,"RTP_EBIT(ANN,+1)")} -> 1942.4791 | O24: {=_xll.FDSLIVE($D24,"RTP_EBITDA(ANN,0)")} -> 2160 | P24: {=_xll.FDSLIVE($D24,"RTP_EBITDA(ANN,+1)")} -> 2655.8809 | Q24: {=_xll.FDSLIVE($D24,"RTP_NET_INC(ANN,0)")} -> 657 | R24: {=_xll.FDSLIVE($D24,"RTP_NET_INC(ANN,+1)")} -> 1292.3939 | T24: =(K24-J24)/J24 -> 0.031818024 | U24: =(L24-K24)/K24 -> 0.14319037 | V24: =O24/K24 -> 0.072478357 | W24: =P24/L24 -> 0.077955116 | X24: =Q24/K24 -> 0.0220455 | Y24: =R24/L24 -> 0.037934201 | AA24: =H24/K24 -> 0.98773107 | AB24: =H24/L24 -> 0.86401276 | AC24: =H24/O24 -> 13.627945 | AD24: =H24/P24 -> 11.083465 | AE24: {=$E24/(_xll.FDSLIVE(D24,"RTP_EPS(ANN,0)"))} -> 44.072717 | AF24: {=$E24/(_xll.FDSLIVE(D24,"RTP_EPS(ANN,+1)"))} -> 21.207407
A25: 2 | B25: {=_xll.FDSLIVE(D25,"RTP_NAME")} -> Sanmina Corporation | D25: =C7 -> SANM-USA | E25: 130.9 | F25: {=_xll.FDSLIVE(D25,"RTP_SHS_OUT")} -> 54.604889 | G25: {=_xll.FDSLIVE(D25,"RTP_MKT_CAP")} -> 7147.7798 | H25: {=_xll.FDSLIVE(D25,"RTP_EV_EST(+1)")} -> 7885.8799 | J25: {=_xll.FDSLIVE($D25,"RTP_SALES(ANN,-1)")} -> 7568.3281 | K25: {=_xll.FDSLIVE($D25,"RTP_SALES(ANN,0)")} -> 8128.382 | L25: {=_xll.FDSLIVE($D25,"RTP_SALES(ANN,+1)")} -> 14021.803 | M25: {=_xll.FDSLIVE(D25,"RTP_EBIT(ANN,0)")} -> 395.049 | N25: {=_xll.FDSLIVE(D25,"RTP_EBIT(ANN,+1)")} -> 838.1123 | O25: {=_xll.FDSLIVE($D25,"RTP_EBITDA(ANN,0)")} -> 514.515 | P25: {=_xll.FDSLIVE($D25,"RTP_EBITDA(ANN,+1)")} -> 1009.7316 | Q25: {=_xll.FDSLIVE($D25,"RTP_NET_INC(ANN,0)")} -> 245.893 | R25: {=_xll.FDSLIVE($D25,"RTP_NET_INC(ANN,+1)")} -> 567.5733 | T25: =(K25-J25)/J25 -> 0.073999682 | U25: =(L25-K25)/K25 -> 0.72504229 | V25: =O25/K25 -> 0.063298575 | W25: =P25/L25 -> 0.072011537 | X25: =Q25/K25 -> 0.030251162 | Y25: =R25/L25 -> 0.040477912 | AA25: =H25/K25 -> 0.970166 | AB25: =H25/L25 -> 0.56240129 | AC25: =H25/O25 -> 15.326822 | AD25: =H25/P25 -> 7.8098775 | AE25: {=$E25/(_xll.FDSLIVE(D25,"RTP_EPS(ANN,0)"))} -> 29.373485 | AF25: {=$E25/(_xll.FDSLIVE(D25,"RTP_EPS(ANN,+1)"))} -> 13.018399
A26: 3 | B26: {=_xll.FDSLIVE(D26,"RTP_NAME")} -> Flex Ltd | D26: =C8 -> FLEX-USA | E26: 64.8 | F26: {=_xll.FDSLIVE(D26,"RTP_SHS_OUT")} -> 367.67392 | G26: {=_xll.FDSLIVE(D26,"RTP_MKT_CAP")} -> 23825.271 | H26: {=_xll.FDSLIVE(D26,"RTP_EV_EST(+1)")} -> 25294.33 | J26: {=_xll.FDSLIVE($D26,"RTP_SALES(ANN,-1)")} -> 26415 | K26: {=_xll.FDSLIVE($D26,"RTP_SALES(ANN,0)")} -> 25813 | L26: {=_xll.FDSLIVE($D26,"RTP_SALES(ANN,+1)")} -> 27390.145 | M26: {=_xll.FDSLIVE(D26,"RTP_EBIT(ANN,0)")} -> 1255 | N26: {=_xll.FDSLIVE(D26,"RTP_EBIT(ANN,+1)")} -> 1730.5802 | O26: {=_xll.FDSLIVE($D26,"RTP_EBITDA(ANN,0)")} -> 1764 | P26: {=_xll.FDSLIVE($D26,"RTP_EBITDA(ANN,+1)")} -> 2234.1482 | Q26: {=_xll.FDSLIVE($D26,"RTP_NET_INC(ANN,0)")} -> 838 | R26: {=_xll.FDSLIVE($D26,"RTP_NET_INC(ANN,+1)")} -> 1209.075 | T26: =(K26-J26)/J26 -> -0.022790081 | U26: =(L26-K26)/K26 -> 0.061098847 | V26: =O26/K26 -> 0.068337659 | W26: =P26/L26 -> 0.081567594 | X26: =Q26/K26 -> 0.032464262 | Y26: =R26/L26 -> 0.044142701 | AA26: =H26/K26 -> 0.97990664 | AB26: =H26/L26 -> 0.9234829 | AC26: =H26/O26 -> 14.339189 | AD26: =H26/P26 -> 11.321689 | AE26: {=$E26/(_xll.FDSLIVE(D26,"RTP_EPS(ANN,0)"))} -> 30.776538 | AF26: {=$E26/(_xll.FDSLIVE(D26,"RTP_EPS(ANN,+1)"))} -> 19.964709
A27: 4 | B27: {=_xll.FDSLIVE(D27,"RTP_NAME")} -> Plexus Corp. | D27: =C9 -> PLXS-USA | E27: 194.13 | F27: {=_xll.FDSLIVE(D27,"RTP_SHS_OUT")} -> 26.786467 | G27: {=_xll.FDSLIVE(D27,"RTP_MKT_CAP")} -> 5335.0605 | H27: 3787.7 | J27: {=_xll.FDSLIVE($D27,"RTP_SALES(ANN,-1)")} -> 3960.8269 | K27: {=_xll.FDSLIVE($D27,"RTP_SALES(ANN,0)")} -> 4032.966 | L27: {=_xll.FDSLIVE($D27,"RTP_SALES(ANN,+1)")} -> 4519.2505 | M27: {=_xll.FDSLIVE(D27,"RTP_EBIT(ANN,0)")} -> 204.078 | N27: {=_xll.FDSLIVE(D27,"RTP_EBIT(ANN,+1)")} -> 270.42001 | O27: {=_xll.FDSLIVE($D27,"RTP_EBITDA(ANN,0)")} -> 281.87 | P27: {=_xll.FDSLIVE($D27,"RTP_EBITDA(ANN,+1)")} -> 347.25 | Q27: {=_xll.FDSLIVE($D27,"RTP_NET_INC(ANN,0)")} -> 172.885 | R27: {=_xll.FDSLIVE($D27,"RTP_NET_INC(ANN,+1)")} -> 209.25999 | T27: =(K27-J27)/J27 -> 0.01821314 | U27: =(L27-K27)/K27 -> 0.12057738 | V27: =O27/K27 -> 0.069891489 | W27: =P27/L27 -> 0.076837963 | X27: =Q27/K27 -> 0.042867954 | Y27: =R27/L27 -> 0.046304137 | AA27: =H27/K27 -> 0.93918471 | AB27: =H27/L27 -> 0.8381257 | AC27: =H27/O27 -> 13.437755 | AD27: =H27/P27 -> 10.907703 | AE27: {=$E27/(_xll.FDSLIVE(D27,"RTP_EPS(ANN,0)"))} -> 31.009696 | AF27: {=$E27/(_xll.FDSLIVE(D27,"RTP_EPS(ANN,+1)"))} -> 25.225728
A28: 5 | B28: {=_xll.FDSLIVE(D28,"RTP_NAME")} -> Benchmark Electronics, Inc. | D28: =C10 -> BHE-USA | E28: 55.61 | F28: {=_xll.FDSLIVE(D28,"RTP_SHS_OUT")} -> 35.667046 | G28: {=_xll.FDSLIVE(D28,"RTP_MKT_CAP")} -> 1983.4445 | H28: 1479.02 | J28: {=_xll.FDSLIVE($D28,"RTP_SALES(ANN,-1)")} -> 2656.105 | K28: {=_xll.FDSLIVE($D28,"RTP_SALES(ANN,0)")} -> 2659.108 | L28: {=_xll.FDSLIVE($D28,"RTP_SALES(ANN,+1)")} -> 2817.05 | M28: {=_xll.FDSLIVE(D28,"RTP_EBIT(ANN,0)")} -> 105.289 | N28: {=_xll.FDSLIVE(D28,"RTP_EBIT(ANN,+1)")} -> 132.23233 | O28: {=_xll.FDSLIVE($D28,"RTP_EBITDA(ANN,0)")} -> 152.152 | P28: {=_xll.FDSLIVE($D28,"RTP_EBITDA(ANN,+1)")} -> 192.7 | Q28: {=_xll.FDSLIVE($D28,"RTP_NET_INC(ANN,0)")} -> 24.852 | R28: {=_xll.FDSLIVE($D28,"RTP_NET_INC(ANN,+1)")} -> 68.665337 | T28: =(K28-J28)/J28 -> 0.0011306103 | U28: =(L28-K28)/K28 -> 0.059396628 | V28: =O28/K28 -> 0.057219188 | W28: =P28/L28 -> 0.068404889 | X28: =Q28/K28 -> 0.0093459912 | Y28: =R28/L28 -> 0.024374908 | AA28: =H28/K28 -> 0.55620907 | AB28: =H28/L28 -> 0.5250244 | AC28: =H28/O28 -> 9.7206741 | AD28: =H28/P28 -> 7.6752466 | AE28: {=$E28/(_xll.FDSLIVE(D28,"RTP_EPS(ANN,0)"))} -> 81.229915 | AF28: {=$E28/(_xll.FDSLIVE(D28,"RTP_EPS(ANN,+1)"))} -> 21.829244
A29: 6 | B29: {=_xll.FDSLIVE(D29,"RTP_NAME")} -> Celestica Inc. | D29: =C11 -> CLS-USA | E29: 280.22 | F29: {=_xll.FDSLIVE(D29,"RTP_SHS_OUT")} -> 114.96786 | G29: {=_xll.FDSLIVE(D29,"RTP_MKT_CAP")} -> 32188.018 | H29: {=_xll.FDSLIVE(D29,"RTP_EV_EST(+1)")} -> 32034.938 | J29: {=_xll.FDSLIVE($D29,"RTP_SALES(ANN,-1)")} -> 9646 | K29: {=_xll.FDSLIVE($D29,"RTP_SALES(ANN,0)")} -> 12390.9 | L29: {=_xll.FDSLIVE($D29,"RTP_SALES(ANN,+1)")} -> 17361.346 | M29: {=_xll.FDSLIVE(D29,"RTP_EBIT(ANN,0)")} -> 810.5 | N29: {=_xll.FDSLIVE(D29,"RTP_EBIT(ANN,+1)")} -> 1353.6864 | O29: {=_xll.FDSLIVE($D29,"RTP_EBITDA(ANN,0)")} -> 986.2 | P29: {=_xll.FDSLIVE($D29,"RTP_EBITDA(ANN,+1)")} -> 1606.3098 | Q29: {=_xll.FDSLIVE($D29,"RTP_NET_INC(ANN,0)")} -> 832.5 | R29: {=_xll.FDSLIVE($D29,"RTP_NET_INC(ANN,+1)")} -> 1039.4753 | T29: =(K29-J29)/J29 -> 0.28456355 | U29: =(L29-K29)/K29 -> 0.40113678 | V29: =O29/K29 -> 0.079590667 | W29: =P29/L29 -> 0.092522195 | X29: =Q29/K29 -> 0.067186403 | Y29: =R29/L29 -> 0.059872971 | AA29: =H29/K29 -> 2.58536 | AB29: =H29/L29 -> 1.8451875 | AC29: =H29/O29 -> 32.483206 | AD29: =H29/P29 -> 19.943187 | AE29: {=$E29/(_xll.FDSLIVE(D29,"RTP_EPS(ANN,0)"))} -> 39.112836 | AF29: {=$E29/(_xll.FDSLIVE(D29,"RTP_EPS(ANN,+1)"))} -> 39.112836
A30: 7 | B30: {=_xll.FDSLIVE(D30,"RTP_NAME")} -> Fabrinet | D30: =C12 -> FN-USA | E30: 551.97 | F30: {=_xll.FDSLIVE(D30,"RTP_SHS_OUT")} -> 35.826118 | G30: {=_xll.FDSLIVE(D30,"RTP_MKT_CAP")} -> 19774.941 | H30: {=_xll.FDSLIVE(D30,"RTP_EV_EST(+1)")} -> 19397.943 | J30: {=_xll.FDSLIVE($D30,"RTP_SALES(ANN,-1)")} -> 2882.967 | K30: {=_xll.FDSLIVE($D30,"RTP_SALES(ANN,0)")} -> 3419.327 | L30: {=_xll.FDSLIVE($D30,"RTP_SALES(ANN,+1)")} -> 4542.7017 | M30: {=_xll.FDSLIVE(D30,"RTP_EBIT(ANN,0)")} -> 324.921 | N30: {=_xll.FDSLIVE(D30,"RTP_EBIT(ANN,+1)")} -> 492.79086 | O30: {=_xll.FDSLIVE($D30,"RTP_EBITDA(ANN,0)")} -> 378.354 | P30: {=_xll.FDSLIVE($D30,"RTP_EBITDA(ANN,+1)")} -> 561.91388 | Q30: {=_xll.FDSLIVE($D30,"RTP_NET_INC(ANN,0)")} -> 332.527 | R30: {=_xll.FDSLIVE($D30,"RTP_NET_INC(ANN,+1)")} -> 491.96964 | T30: =(K30-J30)/J30 -> 0.18604443 | U30: =(L30-K30)/K30 -> 0.32853677 | V30: =O30/K30 -> 0.1106516 | W30: =P30/L30 -> 0.12369597 | X30: =Q30/K30 -> 0.097249254 | Y30: =R30/L30 -> 0.10829891 | AA30: =H30/K30 -> 5.6730296 | AB30: =H30/L30 -> 4.2701337 | AC30: =H30/O30 -> 51.269296 | AD30: =H30/P30 -> 34.521203 | AE30: {=$E30/(_xll.FDSLIVE(D30,"RTP_EPS(ANN,0)"))} -> 60.200242 | AF30: {=$E30/(_xll.FDSLIVE(D30,"RTP_EPS(ANN,+1)"))} -> 40.636796
A31: 8 | B31: {=_xll.FDSLIVE(D31,"RTP_NAME")} -> #N/A | D31: =C13 -> 0 | E31: {=_xll.FDSLIVE(D31,"RTP_PRICE")} -> #N/A | F31: {=_xll.FDSLIVE(D31,"RTP_SHS_OUT")} -> #N/A | G31: {=_xll.FDSLIVE(D31,"RTP_MKT_CAP")} -> #N/A | H31: {=_xll.FDSLIVE(D31,"RTP_EV_EST(+1)")} -> #N/A | J31: {=_xll.FDSLIVE($D31,"RTP_SALES(ANN,-1)")} -> #N/A | K31: {=_xll.FDSLIVE($D31,"RTP_SALES(ANN,0)")} -> #N/A | L31: {=_xll.FDSLIVE($D31,"RTP_SALES(ANN,+1)")} -> #N/A | M31: {=_xll.FDSLIVE(D31,"RTP_EBIT(ANN,0)")} -> #N/A | N31: {=_xll.FDSLIVE(D31,"RTP_EBIT(ANN,+1)")} -> #N/A | O31: {=_xll.FDSLIVE($D31,"RTP_EBITDA(ANN,0)")} -> #N/A | P31: {=_xll.FDSLIVE($D31,"RTP_EBITDA(ANN,+1)")} -> #N/A | Q31: {=_xll.FDSLIVE($D31,"RTP_NET_INC(ANN,0)")} -> #N/A | R31: {=_xll.FDSLIVE($D31,"RTP_NET_INC(ANN,+1)")} -> #N/A | T31: =(K31-J31)/J31 -> #N/A | U31: =(L31-K31)/K31 -> #N/A | V31: =O31/K31 -> #N/A | W31: =P31/L31 -> #N/A | X31: =Q31/K31 -> #N/A | Y31: =R31/L31 -> #N/A | AA31: =H31/K31 -> #N/A | AB31: =H31/L31 -> #N/A | AC31: =H31/O31 -> #N/A | AD31: =H31/P31 -> #N/A | AE31: {=$E31/(_xll.FDSLIVE(D31,"RTP_EPS(ANN,0)"))} -> #N/A | AF31: {=$E31/(_xll.FDSLIVE(D31,"RTP_EPS(ANN,+1)"))} -> #N/A
A32: 9 | B32: {=_xll.FDSLIVE(D32,"RTP_NAME")} -> #N/A | D32: =C14 -> 0 | E32: {=_xll.FDSLIVE(D32,"RTP_PRICE")} -> #N/A | F32: {=_xll.FDSLIVE(D32,"RTP_SHS_OUT")} -> #N/A | G32: {=_xll.FDSLIVE(D32,"RTP_MKT_CAP")} -> #N/A | H32: {=_xll.FDSLIVE(D32,"RTP_EV_EST(+1)")} -> #N/A | J32: {=_xll.FDSLIVE($D32,"RTP_SALES(ANN,-1)")} -> #N/A | K32: {=_xll.FDSLIVE($D32,"RTP_SALES(ANN,0)")} -> #N/A | L32: {=_xll.FDSLIVE($D32,"RTP_SALES(ANN,+1)")} -> #N/A | M32: {=_xll.FDSLIVE(D32,"RTP_EBIT(ANN,0)")} -> #N/A | N32: {=_xll.FDSLIVE(D32,"RTP_EBIT(ANN,+1)")} -> #N/A | O32: {=_xll.FDSLIVE($D32,"RTP_EBITDA(ANN,0)")} -> #N/A | P32: {=_xll.FDSLIVE($D32,"RTP_EBITDA(ANN,+1)")} -> #N/A | Q32: {=_xll.FDSLIVE($D32,"RTP_NET_INC(ANN,0)")} -> #N/A | R32: {=_xll.FDSLIVE($D32,"RTP_NET_INC(ANN,+1)")} -> #N/A | T32: =(K32-J32)/J32 -> #N/A | U32: =(L32-K32)/K32 -> #N/A | V32: =O32/K32 -> #N/A | W32: =P32/L32 -> #N/A | X32: =Q32/K32 -> #N/A | Y32: =R32/L32 -> #N/A | AA32: =H32/K32 -> #N/A | AB32: =H32/L32 -> #N/A | AC32: =H32/O32 -> #N/A | AD32: =H32/P32 -> #N/A | AE32: {=$E32/(_xll.FDSLIVE(D32,"RTP_EPS(ANN,0)"))} -> #N/A | AF32: {=$E32/(_xll.FDSLIVE(D32,"RTP_EPS(ANN,+1)"))} -> #N/A
A33: 10 | B33: {=_xll.FDSLIVE(D33,"RTP_NAME")} -> #N/A | D33: =C15 -> 0 | E33: {=_xll.FDSLIVE(D33,"RTP_PRICE")} -> #N/A | F33: {=_xll.FDSLIVE(D33,"RTP_SHS_OUT")} -> #N/A | G33: {=_xll.FDSLIVE(D33,"RTP_MKT_CAP")} -> #N/A | H33: {=_xll.FDSLIVE(D33,"RTP_EV_EST(+1)")} -> #N/A | J33: {=_xll.FDSLIVE($D33,"RTP_SALES(ANN,-1)")} -> #N/A | K33: {=_xll.FDSLIVE($D33,"RTP_SALES(ANN,0)")} -> #N/A | L33: {=_xll.FDSLIVE($D33,"RTP_SALES(ANN,+1)")} -> #N/A | M33: {=_xll.FDSLIVE(D33,"RTP_EBIT(ANN,0)")} -> #N/A | N33: {=_xll.FDSLIVE(D33,"RTP_EBIT(ANN,+1)")} -> #N/A | O33: {=_xll.FDSLIVE($D33,"RTP_EBITDA(ANN,0)")} -> #N/A | P33: {=_xll.FDSLIVE($D33,"RTP_EBITDA(ANN,+1)")} -> #N/A | Q33: {=_xll.FDSLIVE($D33,"RTP_NET_INC(ANN,0)")} -> #N/A | R33: {=_xll.FDSLIVE($D33,"RTP_NET_INC(ANN,+1)")} -> #N/A | T33: =(K33-J33)/J33 -> #N/A | U33: =(L33-K33)/K33 -> #N/A | V33: =O33/K33 -> #N/A | W33: =P33/L33 -> #N/A | X33: =Q33/K33 -> #N/A | Y33: =R33/L33 -> #N/A | AA33: =H33/K33 -> #N/A | AB33: =H33/L33 -> #N/A | AC33: =H33/O33 -> #N/A | AD33: =H33/P33 -> #N/A | AE33: {=$E33/(_xll.FDSLIVE(D33,"RTP_EPS(ANN,0)"))} -> #N/A | AF33: {=$E33/(_xll.FDSLIVE(D33,"RTP_EPS(ANN,+1)"))} -> #N/A
C36: Mean | AA36: =_xlfn.AGGREGATE(1,3,AA22:AA33) -> 1.9309709 | AB36: =_xlfn.AGGREGATE(1,3,AB22:AB33) -> 1.5226959 | AC36: =_xlfn.AGGREGATE(1,3,AC22:AC33) -> 21.190119 | AD36: =_xlfn.AGGREGATE(1,3,AD22:AD33) -> 14.725101 | AE36: =_xlfn.AGGREGATE(1,3,AE22:AE33) -> 46.563953 | AF36: =_xlfn.AGGREGATE(1,3,AF22:AF33) -> 29.716415
C37: Median | AA37: =_xlfn.AGGREGATE(12,3,AA22:AA33) -> 0.98381885 | AB37: =_xlfn.AGGREGATE(12,3,AB22:AB33) -> 0.89374783 | AC37: =_xlfn.AGGREGATE(12,3,AC22:AC33) -> 14.833006 | AD37: =_xlfn.AGGREGATE(12,3,AD22:AD33) -> 11.202577 | AE37: =_xlfn.AGGREGATE(12,3,AE22:AE33) -> 41.592777 | AF37: =_xlfn.AGGREGATE(12,3,AF22:AF33) -> 23.527486
C38: StDev | AA38: =_xlfn.AGGREGATE(7,3,AA22:AA33) -> 1.7197666 | AB38: =_xlfn.AGGREGATE(7,3,AB22:AB33) -> 1.2829219 | AC38: =_xlfn.AGGREGATE(7,3,AC22:AC33) -> 13.969099 | AD38: =_xlfn.AGGREGATE(7,3,AD22:AD33) -> 8.9129678 | AE38: =_xlfn.AGGREGATE(7,3,AE22:AE33) -> 18.28179 | AF38: =_xlfn.AGGREGATE(7,3,AF22:AF33) -> 14.47319
AA40: Unlevering and Relevering Beta
D41: =_xlfn.CONCAT(DCF!O16," Trading Multiple") -> 2026 Trading Multiple | H41: =_xlfn.CONCAT(DCF!O16," Financial Metric") -> 2026 Financial Metric | L41: Implied Enterprise Value | P41: =D22 -> TTMI-USA | R41: Implied Equity Value | V41: Implied Equity Value Per Share | AC41: Levered | AD41: Tax | AE41: Debt/Equity | AF41: Unlevered
B42: Calculating Implied Share Price | D42: EV/Revenue | E42: EV/EBITDA | F42: P/E | H42: Revenue | I42: EBITDA | J42: EPS | L42: Revenue | M42: EBITDA | N42: Net Income | P42: Net Debt | R42: Revenue | S42: EBITDA | T42: Net Income | V42: Revenue | W42: EBITDA | X42: Net Income | AA42: Ticker | AC42: Beta | AD42: Rate | AE42: Ratio | AF42: Beta
B43: Minimum | D43: =_xlfn.AGGREGATE(5,3,AB22:AB33) -> 0.5250244 | E43: =_xlfn.AGGREGATE(5,3,AD22:AD33) -> 7.6752466 | F43: =_xlfn.AGGREGATE(5,3,AF22:AF33) -> 13.018399 | H43: =$L$22 -> 3404.051 | I43: =$P$22 -> 550.98151 | J43: {=_xll.FDSLIVE($D$22,"RTP_EPS(ANN,+1)")} -> 1.6827 | L43: =H43*D43 -> 1787.2098 | M43: =I43*E43 -> 4228.9189 | N43: 0 | P43: =-($H$22-$G$22) -> 2175.38 | R43: =L43-$P$43 -> -388.17017 | S43: =M43-$P$43 -> 2053.5389 | T43: =F43*J43*$F$22 -> 2265.1944 | V43: =R43/$F$22 -> -3.7538848 | W43: =S43/$F$22 -> 19.859199 | X43: =T43/$F$22 -> 21.90606
B44: Mean | D44: =AB36 -> 1.5226959 | E44: =AD36 -> 14.725101 | F44: =AF36 -> 29.716415 | H44: =$L$22 -> 3404.051 | I44: =$P$22 -> 550.98151 | J44: {=_xll.FDSLIVE($D$22,"RTP_EPS(ANN,+1)")} -> 1.6827 | L44: =H44*D44 -> 5183.3346 | M44: =I44*E44 -> 8113.2584 | N44: 0 | P44: =-($H$22-$G$22) -> 2175.38 | R44: =L44-$P$43 -> 3007.9546 | S44: =M44-$P$43 -> 5937.8784 | T44: =F44*J44*$F$22 -> 5170.6402 | V44: =R44/$F$22 -> 29.089085 | W44: =S44/$F$22 -> 57.423556 | X44: =T44/$F$22 -> 50.003811 | AA44: =D22 -> TTMI-USA | AC44: {=_xll.FDSLIVE(AA44,"RTP_BETA")} -> 2.1040306 | AD44: 0.24 | AE44: {=_xll.FDSLIVE(AA44,"RTP_LTDEBT_EQ")/100} -> 0.57635822 | AF44: =IFERROR(AC44/(1+((1-AE44)*AD44)),"N/A") -> 1.9098486
B45: Median | D45: =AB37 -> 0.89374783 | E45: =AD37 -> 11.202577 | F45: =AF37 -> 23.527486 | H45: =$L$22 -> 3404.051 | I45: =$P$22 -> 550.98151 | J45: {=_xll.FDSLIVE($D$22,"RTP_EPS(ANN,+1)")} -> 1.6827 | L45: =H45*D45 -> 3042.3632 | M45: =I45*E45 -> 6172.4125 | N45: 0 | P45: =-($H$22-$G$22) -> 2175.38 | R45: =L45-$P$43 -> 866.98322 | S45: =M45-$P$43 -> 3997.0325 | T45: =F45*J45*$F$22 -> 4093.77 | V45: =R45/$F$22 -> 8.3843515 | W45: =S45/$F$22 -> 38.65418 | X45: =T45/$F$22 -> 39.589701 | AA45: =D24 -> JBL-USA | AC45: {=_xll.FDSLIVE(AA45,"RTP_BETA")} -> 1.5297984 | AE45: {=IFERROR((_xll.FDSLIVE(AA45,"RTP_LTDEBT_EQ")/100),"N/A")} -> 1.9431593 | AF45: =IFERROR(AC45/(1+((1-AE45)*AD45)),"N/A") -> 1.5297984
