Workbook
Name __FDS_HYPERLINK_TOGGLE_STATE__: "ON"
Name __FDS_UNIQUE_RANGE_ID_GENERATOR_COUNTER: 5
Name __IntlFixup: TRUE
Name __q3: '[1]1601 Detail information'!$H$97:$H$129
Name _bdm.0052b2d879b443fb8b5b7f9b7e1d1cd2.edm: '[2]Precedent Transactions'!$1:$1048576
Name _bdm.006A679C67724FC79389DC4D22927E9A.edm: [3]Output!$A:$IV
Name _bdm.00a08cb028504395b46a809724d12a5d.edm: '[2]Football Field'!$1:$1048576
Name _bdm.00c6e94a41b24656b09a54c8f0719816.edm: '[4]Strat. Alt.'!$1:$1048576
Name _bdm.015D17FCDC584596B596D0D9D9E42423.edm: [3]Output!$A:$IV
Name _bdm.0260b451a590464bb4192c2c003e5ff7.edm: [4]DCF!$1:$1048576
Name _bdm.02cf64abf374488fa51fc1ec41a32c4e.edm: '[4]M&A Comps'!$1:$1048576
Name _bdm.02fca72f590d4af7b3e2c2954abe00c8.edm: [5]FF!$1:$1048576
Name _bdm.037EABD3E1C143E0A4C9EFAB96C2176C.edm: '[6]ghdx_gxdx output NEW'!$A:$IV
Name _bdm.03882b6fb0ef474bba0ef95ad063bcc3.edm: '[4]Football Field'!$1:$1048576
Name _bdm.03c17d6584414e4196fd5fce20d5c9ae.edm: '[2]Precedent Transactions'!$1:$1048576
Name _bdm.04b02edf28d94ee8b930259f38694521.edm: '[4]Strat. Alt.'!$1:$1048576
Name _bdm.04b7c7d82827448f95077a89ad31c896.edm: '[4]MP Charts 3.0'!$1:$1048576
Name _bdm.04d904f4c97e4d7296658df009e83741.edm: '[7]Fin Profile'!$1:$1048576
Name _bdm.0519f2ffd92b4534bd66ba989a17ab75.edm: '[7]LBO Summary'!$1:$1048576
Name _bdm.055852185cfd4528ade49f8915ecc655.edm: [5]FF!$1:$1048576
Name _bdm.05960a26cde14c82936a636b600ec85b.edm: '[7]LBO Summary'!$1:$1048576
Name _bdm.06000a289da64609969ecdd055070953.edm: '[4]Strat. Alt.'!$1:$1048576
Name _bdm.060F2793D9E2423998467AD3EC73BB2C.edm: [8]Output!$A:$IV
Name _bdm.06b66d61a14c4d479731f0e3143c6d48.edm: '[4]M&A Comps'!$1:$1048576
Name _bdm.0761830ae81b49f58448fda978756af4.edm: '[7]LBO Summary'!$1:$1048576
Name _bdm.07ba5318194a4b26b4697fe251d98fa8.edm: '[4]M&A Comps'!$1:$1048576
Name _bdm.0845d45cfd504654aa9ed88eac98d1e3.edm: '[4]Summary P.L'!$1:$1048576
Name _bdm.085e7abc2f75496fb1e071b3e4a5e59e.edm: '[4]Comps.2'!$1:$1048576
Name _bdm.08b6390c3de54834803333bfc8711f1e.edm: [4]AVP!$1:$1048576
Name _bdm.08C1D7BE819C4781A74CF6318805C5E2.edm: '[9]Spec. Pharma M&A Precedents'!$A:$IV
Name _bdm.0921c0170a6144df873c830ceeb4c7f4.edm: [4]Charts!$1:$1048576
Name _bdm.092f2dd0c7ce49d5a3bd0cf81be33132.edm: [5]DCF_2015!$1:$1048576
Name _bdm.098D708957BC4D3F8BBF2C8937342EBA.edm: [3]Output!$A:$IV
Name _bdm.09d586f35a89421eaf61944923137dc2.edm: '[4]M&A Comps'!$1:$1048576
Name _bdm.0A2E67B530F240BBBBDC3B4DC5001469.edm: [3]Output!$A:$IV
Name _bdm.0A9A50A4D9834205863153CF17E3B531.edm: [10]Charts!$A:$IV
Name _bdm.0AC2A1A0F3DD4A8BA18D8B4DA9E7CA5B.edm: [8]GXDX_IPO!$A:$IV
Name _bdm.0adb85cc32c04880bda5c8e99564a438.edm: '[7]Fin Profile'!$1:$1048576
Name _bdm.0b13a4d3931044539d21ac8f0fcd4444.edm: [4]DCF!$1:$1048576
Name _bdm.0b3c4a7be18446b2a153c2d1c8dd5c6e.edm: '[7]LBO Summary'!$1:$1048576
Name _bdm.0b7059d39d334c30959e118c5f0bf441.edm: '[7]LBO Summary'!$1:$1048576
Name _bdm.0bc7c6ddbe0f44efba274db558b3aec4.edm: '[7]LBO Summary'!$1:$1048576
Name _bdm.0bfb419883cb4b36826dab2bfdf29fd7.edm: [4]DCF!$1:$1048576
Name _bdm.0C60A6498314461E91091A5BC4B2CC02.edm: '[6]ghdx_gxdx output NEW'!$A:$IV
Name _bdm.0d13198c568342d1bfddc65de125a842.edm: '[4]M&A Comps'!$1:$1048576
Name _bdm.0d3c0384f46845d49626641f4044ba2d.edm: [7]IS!$1:$1048576
Name _bdm.0da3f46c7de146b598f9c074ef7cfc33.edm: [5]FF!$1:$1048576
Name _bdm.0eb9bfa0140945f1bbb693e439a697a9.edm: [4]DCF!$1:$1048576
Name _bdm.0ed65bae934742c59e0407895da36f8b.edm: [5]FF!$1:$1048576
Name _bdm.0f17cba32be64ef29b27fc1162234c18.edm: '[4]Strat. Alt.'!$1:$1048576
Name _bdm.0f4ea587d40948f59c1bc31c3573b963.edm: [2]AVP!$1:$1048576
Name _bdm.0FE355E66A5E41AC8F880A3AA51226B8.edm: '[9]SP Comps'!$A:$IV
Name _bdm.0fe9c490c9134e2ba6a6e35f5ed6aa57.edm: '[7]LBO Summary'!$1:$1048576
Name _bdm.1036a40be0a24a779dd008958eaac621.edm: '[4]MP Charts 3.0'!$1:$1048576
Name _bdm.1080a96a06e340e1a3cd6799139b7ac5.edm: '[7]LBO Summary'!$1:$1048576
Name _bdm.10A1BA92E6AF42689069FA0C225AE53E.edm: [10]Charts!$A:$IV
Name _bdm.115087044f204ca8ac825c0da8260cd6.edm: '[7]LBO Summary'!$1:$1048576
Name _bdm.12fbfc733a914c22a3982519f6484a19.edm: [5]FF!$1:$1048576
Name _bdm.132db457ce734dd0a95cac7dbcbb5842.edm: '[4]M&A Comps'!$1:$1048576
Name _bdm.13AC5C95A4324304BFB4E0F0B43DBAA6.edm: [10]Charts!$IV$1

Sheet Cover
C5: Buy: | D5: OTCMKTS: LKNCY
C7: By: | D7: Tej Prattipati, Ranai Shah, Nirav Singhal, Sean Lu
C9: Operating Scenario: | F9: 2
C10: 1 = Bull | D10: 2 = Base | E10: 3 = Bear

Sheet LBO Model
B2: Luckin Coffee Inc (OTCMKTS: LKNCY)
B3: Revenue Build
B4: In Millions of $USD (except share price)
B6: Sources: Factset Fundamentals, Luckin 20-F Filings, NYU Stern Country Default Spreads and Risk Premiums
B8: Control | L8: Uses Calculation
B10: Base Assumptions | L10: Equity Purchase Price
B12: Base Year | D12: 2026 | L12: FD Shares (M) | O12: =DCF!D12 -> 320.8
B13: Exit Multiple | D13: =Precedents!G13-3 -> 10.3 | E13: *IPO Exit discounts multiple based on precedent transactions | L13: Current PPS | O13: =DCF!D11 -> 31.7
B14: Tax Rate (%) | D14: 0.28 | E14: *Current marginal tax rate | L14: Offer Premium | O14: 0.25
L15: Offer PPS | O15: =O13*(1+O14) -> 39.625
B16: Debt Assumptions | L16: Equity Offer Price | O16: =O12*O15 -> 12711.7
B18: Debt | D18: Multiple | E18: Interest Rate | L18: Other Uses
B19: Revolver | D19: 0.5 | E19: 0.03 | F19: *Low interest rate, reflective of revolver of China comparable companies
B20: First Lien Term Loan | D20: 1.5 | E20: 0.04 | F20: *Lower in capital structure, reflective of premium over China government bonds | L20: Cash | O20: =BS!I6 -> 1174.402
B21: Second Lien Term Loan | D21: 2 | E21: 0.05 | F21: *Analogous to first lien rate, simply more risk from capital structure placement | L21: Debt | O21: =-BS!I40-BS!I47 -> -1039.497
B22: High Yield Bonds | D22: 1 | E22: 0.06 | L22: Refinance Net Debt | O22: =O20+O21 -> 134.90495
B23: Total Debt/EBITDA | D23: =SUM(D19:D22) -> 5 | F23: *Based off historic comps
B25: Sources & Uses | L25: Operating Model Output | O25: FY 26 | P25: FY 27 | Q25: FY 28 | R25: FY 29 | S25: FY 30 | T25: FY 31
B27: Sources | E27: Multiple | F27: % of Total | H27: Uses
B28: Revolver | D28: =E28*$O$30 -> 758.41162 | E28: =D19 -> 0.5 | F28: =D28/$D$33 -> 0.056252851 | H28: Purchase Equity | J28: =O16 -> 12711.7 | L28: Revenue | O28: ='Operating Model'!I46 -> 8638.5033 | P28: ='Operating Model'!J46 -> 10500.037 | Q28: ='Operating Model'!K46 -> 12430.608 | R28: ='Operating Model'!L46 -> 14318.129 | S28: ='Operating Model'!M46 -> 16037.068 | T28: ='Operating Model'!N46 -> 17518.546
B29: First Lien Term Loan | D29: =E29*$O$30 -> 2275.2349 | E29: =D20 -> 1.5 | F29: =D29/$D$33 -> 0.16875855 | H29: Refinance Net Debt | J29: =O22 -> 134.90495 | L29: EBIT | O29: ='Operating Model'!I28 -> 725.77278 | P29: ='Operating Model'!J28 -> 840.00295 | Q29: ='Operating Model'!K28 -> 1019.3099 | R29: ='Operating Model'!L28 -> 1245.6772 | S29: ='Operating Model'!M28 -> 1411.262 | T29: ='Operating Model'!N28 -> 1629.2248
B30: Second Lien Term Loan | D30: =E30*$O$30 -> 3033.6465 | E30: =D21 -> 2 | F30: =D30/$D$33 -> 0.2250114 | H30: Transaction Fees | J30: =J28*0.05 -> 635.585 | L30: Adjusted EBITDA | O30: ='Operating Model'!I41 -> 1516.8232 | P30: ='Operating Model'!J41 -> 1790.4193 | Q30: ='Operating Model'!K41 -> 2072.8301 | R30: ='Operating Model'!L41 -> 2451.3805 | S30: ='Operating Model'!M41 -> 2675.5001 | T30: ='Operating Model'!N41 -> 3005.8029
B31: High Yield Bonds | D31: =E31*$O$30 -> 1516.8232 | E31: =D22 -> 1 | F31: =D31/$D$33 -> 0.1125057 | L31: UFCF | O31: =DCF!F29 -> 531.65703 | P31: =DCF!G29 -> 398.28354 | Q31: =DCF!H29 -> 642.5486 | R31: =DCF!I29 -> 875.55824 | S31: =DCF!J29 -> 896.36472 | T31: =DCF!K29 -> 1061.2958
B32: Sponsor Equity | D32: =D33-SUM(D28:D31) -> 5898.0737 | F32: =D32/$D$33 -> 0.43747149 | L32: Tax Accounted Interest Payment | O32: =E63*(1-$D$14) -> 0 | P32: =F63*(1-$D$14) -> 252.29644 | Q32: =G63*(1-$D$14) -> 245.24066 | R32: =H63*(1-$D$14) -> 236.57891 | S32: =I63*(1-$D$14) -> 221.94713 | T32: =J63*(1-$D$14) -> 203.03422
B33: Total | D33: =J33 -> 13482.19 | H33: Total | J33: =SUM(J28:J30) -> 13482.19 | L33: FCF | O33: =O31-O32 -> 531.65703 | P33: =P31-P32 -> 145.9871 | Q33: =Q31-Q32 -> 397.30794 | R33: =R31-R32 -> 638.97933 | S33: =S31-S32 -> 674.41759 | T33: =T31-T32 -> 858.26157
B35: Debt Schedule | D35: Interest Rate | E35: FY 26 | F35: FY 27 | G35: FY 28 | H35: FY 29 | I35: FY 30 | J35: FY 31 | L35: Returns Analysis
B37: Revolver | D37: =E19 -> 0.03 | L37: Terminal EBITDA | O37: =T30 -> 3005.8029 | Q37: Terminal EBITDA | T37: =T30 -> 3005.8029
B38: Beginning Balance | E38: =D28 -> 758.41162 | F38: =E40 -> 758.41162 | G38: =F40 -> 226.7546 | H38: =G40 -> 80.767499 | I38: =H40 -> 0 | J38: =I40 -> 0 | L38: Exit Multiple | O38: =D13 -> 10.3 | Q38: Exit Multiple | T38: =D13 -> 10.3
B39: Paydown | F39: =-MIN(E40,O33) -> -531.65703 | G39: =-MIN(F40,P33) -> -145.9871 | H39: =-MIN(G40,Q33) -> -80.767499 | I39: =-MIN(H40,R33) -> 0 | J39: =-MIN(I40,S33) -> 0 | L39: Enterprise Value | O39: =O37*O38 -> 30959.769 | Q39: Enterprise Value | T39: =T37*T38 -> 30959.769
B40: Ending Balance | E40: =SUM(E38:E39) -> 758.41162 | F40: =SUM(F38:F39) -> 226.7546 | G40: =SUM(G38:G39) -> 80.767499 | H40: =SUM(H38:H39) -> 0 | I40: =SUM(I38:I39) -> 0 | J40: =SUM(J38:J39) -> 0 | L40: (-) Net Debt | O40: =J62 -> 5195.7672 | Q40: (-) Net Debt | T40: =J62 -> 5195.7672
B41: General Interest Expense | F41: =AVERAGE(E40:F40)*$D$37 -> 14.777493 | G41: =AVERAGE(F40:G40)*$D$37 -> 4.6128314 | H41: =AVERAGE(G40:H40)*$D$37 -> 1.2115125 | I41: =AVERAGE(H40:I40)*$D$37 -> 0 | J41: =AVERAGE(I40:J40)*$D$37 -> 0 | L41: Equity Value at Exit | O41: =O39-O40 -> 25764.002 | Q41: Equity Value | T41: =T39-T40 -> 25764.002
B42: Reserve Interest Expense | D42: 0.0025 | F42: =$D$42*(1000-F40) -> 1.9331135 | G42: =$D$42*(1000-G40) -> 2.2980813 | H42: 0 | I42: 0 | J42: 0 | L42: Sponsor Ownership at Exit | O42: 1 | Q42: Sponsor Ownership at Exit | T42: 1
L43: Sponsor Equity at Exit | O43: =O41*O42 -> 25764.002 | Q43: Sponsor Equity at Closing | T43: =T41*T42 -> 25764.002
B44: First Lean Term Loan | D44: =E20 -> 0.04 | L44: Sponsor Equity at Closing | O44: =D32 -> 5898.0737 | Q44: Net Debt at Closing | T44: =SUM(D29:D31) -> 6825.7046
B45: Beginning Balance | E45: =D29 -> 2275.2349 | F45: =E47 -> 2275.2349 | G45: =F47 -> 2275.2349 | H45: =G47 -> 2275.2349 | I45: =H47 -> 1958.6944 | J45: =I47 -> 1319.7151 | L45: MOIC | O45: =O43/O44 -> 4.3682062 | Q45: Implied TEV at Closing | T45: =T43-T44 -> 18938.298
B46: Paydown | F46: =-MIN(F45,O33+F39) -> 0 | G46: =-MIN(G45,P33+G39) -> 0 | H46: =-MIN(H45,Q33+H39) -> -316.54045 | I46: =-MIN(I45,R33+I39) -> -638.97933 | J46: =-MIN(J45,S33+J39) -> -674.41759 | L46: IRR | O46: =O45^(1/6)-1 -> 0.27854845 | Q46: (-) Old Net Debt | T46: =O22 -> 134.90495
B47: Ending Balance | E47: =SUM(E45:E46) -> 2275.2349 | F47: =SUM(F45:F46) -> 2275.2349 | G47: =SUM(G45:G46) -> 2275.2349 | H47: =SUM(H45:H46) -> 1958.6944 | I47: =SUM(I45:I46) -> 1319.7151 | J47: =SUM(J45:J46) -> 645.2975 | Q47: (-) Transaction Fees | T47: =J30 -> 635.585
B48: Interest Expense | F48: =AVERAGE(E47:F47)*$D$44 -> 91.009395 | G48: =AVERAGE(F47:G47)*$D$44 -> 91.009395 | H48: =AVERAGE(G47:H47)*$D$44 -> 84.678586 | I48: =AVERAGE(H47:I47)*$D$44 -> 65.56819 | J48: =AVERAGE(I47:J47)*$D$44 -> 39.300252 | Q48: (-) Management Options | T48: =(T45-O16)*0.07 -> 435.86184
Q49: Equity Purchase Price | T49: =T45-T46-T47-T48 -> 17731.946
B50: Second Lean Term Loan | D50: =E21 -> 0.05 | Q50: FD Shares | T50: =O12 -> 320.8
...

Sheet DCF
B2: Luckin Coffee Inc (OTCMKTS: LKNCY)
B3: DCF Valuation
B4: In Millions of $USD (except share price)
B6: Sources: Factset Fundamentals, Luckin 20-F Filings, NYU Stern Country Default Spreads and Risk Premiums
B8: Control
B10: Inputs / Assumptions
B11: Share Price | D11: 31.7
B12: Shares out. (M) | D12: 320.8
B13: Net Debt (M) | D13: =BS!I47-BS!I6 -> -556.81246
B14: Exit Multiple | D14: =AVERAGE(Comps!K29,Comps!K34) -> 11.196 | E14: *Variable multiples, thus average of median and Q1 used
B15: WACC (%) | D15: =WACC!D27 -> 0.068744188
B16: Tax Rate (%) | D16: 0.28
B17: PGR Growth Rate (%) | D17: 0.0225
B19: all figures in M unless otherwise stated | F19: FY 26 | G19: FY 27 | H19: FY 28 | I19: FY 29 | J19: FY 30 | K19: FY 31
B21: UFCF Calculation
B23: EBIT | F23: ='Operating Model'!I28 -> 725.77278 | G23: ='Operating Model'!J28 -> 840.00295 | H23: ='Operating Model'!K28 -> 1019.3099 | I23: ='Operating Model'!L28 -> 1245.6772 | J23: ='Operating Model'!M28 -> 1411.262 | K23: ='Operating Model'!N28 -> 1629.2248
B24: (-) Taxes | F24: =F23*$D$16 -> 203.21638 | G24: =G23*$D$16 -> 235.20083 | H24: =H23*$D$16 -> 285.40677 | I24: =I23*$D$16 -> 348.78963 | J24: =J23*$D$16 -> 395.15335 | K24: =K23*$D$16 -> 456.18294
B25: NOPAT | F25: =F23-F24 -> 522.5564 | G25: =G23-G24 -> 604.80213 | H25: =H23-H24 -> 733.90312 | I25: =I23-I24 -> 896.88762 | J25: =J23-J24 -> 1016.1086 | K25: =K23-K24 -> 1173.0418
B26: (+) D&A | F26: ='Operating Model'!I23 -> 734.27278 | G26: ='Operating Model'!J23 -> 892.50314 | H26: ='Operating Model'!K23 -> 994.44867 | I26: ='Operating Model'!L23 -> 1145.4503 | J26: ='Operating Model'!M23 -> 1202.7801 | K26: ='Operating Model'!N23 -> 1313.8909
B27: (-) Δ NWC | F27: ='Operating Model'!I67 -> -302.80973 | G27: ='Operating Model'!J67 -> 59.518074 | H27: ='Operating Model'!K67 -> 103.78512 | I27: ='Operating Model'!L67 -> 42.80657 | J27: ='Operating Model'!M67 -> 63.614164 | K27: ='Operating Model'!N67 -> 50.431135
B28: (-) Cash from Investing | F28: ='Operating Model'!I78*-1 -> 1027.9819 | G28: ='Operating Model'!J78*-1 -> 1039.5037 | H28: ='Operating Model'!K78*-1 -> 982.01806 | I28: ='Operating Model'!L78*-1 -> 1123.9731 | J28: ='Operating Model'!M78*-1 -> 1258.9098 | K28: ='Operating Model'!N78*-1 -> 1375.2059
B29: UFCF | F29: =F25+F26-F27-F28 -> 531.65703 | G29: =G25+G26-G27-G28 -> 398.28354 | H29: =H25+H26-H27-H28 -> 642.5486 | I29: =I25+I26-I27-I28 -> 875.55824 | J29: =J25+J26-J27-J28 -> 896.36472 | K29: =K25+K26-K27-K28 -> 1061.2958
B31: Period | F31: 0.5 | G31: =1+F31 -> 1.5 | H31: =1+G31 -> 2.5 | I31: =1+H31 -> 3.5 | J31: =1+I31 -> 4.5 | K31: =1+J31 -> 5.5
B32: Discount Rate | F32: =$D$15 -> 0.068744188 | G32: =F32 -> 0.068744188 | H32: =$D$15 -> 0.068744188 | I32: =$D$15 -> 0.068744188 | J32: =$D$15 -> 0.068744188 | K32: =$D$15 -> 0.068744188
B33: Discounted FCFs | F33: =F29/(1+F32)^F31 -> 514.27413 | G33: =G29/(1+G32)^G31 -> 360.48044 | H33: =H29/(1+H32)^H31 -> 544.15368 | I33: =I29/(1+I32)^I31 -> 693.78812 | J33: =J29/(1+J32)^J31 -> 664.58848 | K33: =K29/(1+K32)^K31 -> 736.25919
B35: DCF
B37: Exit Multiples Method | G37: Perpetuity Growth Method
B38: PV of FCFFs | E38: =SUM(F33:L33) -> 3513.544 | G38: PV of FCFFs | J38: =SUM(F33:K33) -> 3513.544
B39: Final Year EBITDA | E39: ='Operating Model'!N31 -> 2943.1157 | G39: Terminal Value | J39: =K29*(1+D17)/(D15-D17) -> 23466.191
B40: EV/EBITDA Multiple | E40: =D14 -> 11.196 | G40: PV of TV | J40: =J39/(1+$D$15)^$K$31 -> 16279.344
B41: TV in Final Year | E41: =E39*E40 -> 32951.124 | G41: Total Enterprise Value (TEV) | J41: =J38+J40 -> 19792.888
B42: PV of TV | E42: =E41/(1+$D$15)^$K$31 -> 22859.384 | G42: (-) Net Debt | J42: =D13 -> -556.81246
B43: Total Enterprise Value (TEV) | E43: =E38+E42 -> 26372.928 | G43: Equity Value | J43: =J41-J42 -> 20349.7
B44: (-) Net Debt | E44: =D13 -> -556.81246 | G44: Shares Oustanding | J44: =D12 -> 320.8
B45: Equity Value | E45: =E43-E44 -> 26929.74 | G45: Implied Share Price | J45: =J43/J44 -> 63.434227
B46: Shares Oustanding | E46: =D12 -> 320.8 | G46: Current Market Share Price | J46: =$D$11 -> 31.7
B47: Implied Share Price | E47: =E45/E46 -> 83.945574 | G47: Implied Upside | J47: =J45/J46-1 -> 1.0010797
B48: Current Market Share Price | E48: =$D$11 -> 31.7 | G48: Implied % Growth | J48: =((1+J47)^(1/5)-1) -> 0.14882236
B49: Implied Upside | E49: =E47/E48-1 -> 1.6481254
B50: Implied % Growth | E50: =((1+E49)^(1/5)-1) -> 0.21503198
...

Sheet WACC
B2: Luckin Coffee Inc (OTCMKTS: LKNCY)
B3: WACC Calculation
B4: In Millions of $USD (except share price)
B6: Sources: Factset Fundamentals, Luckin 20-F Filings, NYU Stern Country Default Spreads and Risk Premiums
B8: WACC Calculation | K8: SID Relevered Beta
B9: Target Capital Structure | O9: Target | P9: Target
B10: Debt-to-Total Capitalization | D10: =(BS!I40+BS!I47)/(BS!I40+BS!I47+Comps!F11) -> 0.098153751 | N10: Unlevered | O10: Debt/ | P10: Marginal | Q10: Relevered
B11: Equity-to-Total Capitalization | D11: =1-D10 -> 0.90184625 | N11: Beta | O11: Equity | P11: Tax Rate | Q11: Beta
K12: Relevered Beta | N12: =Comps!R29 -> 0.75579483 | O12: =(BS!I40+BS!I47)/Comps!F11 -> 0.10883646 | P12: =D15 -> 0.28 | Q12: =N12*(1+(1-P12)*(O12)) -> 0.81502061
B13: Cost of Debt
B14: Pre-Tax Cost of Debt | D14: 0.053 | E14: *Based on current yields for converitble debt at bbb rating | K14: WACC Sensitivity Analysis
B15: Tax Rate | D15: 0.28 | M15: Pre-tax Cost of Debt
B16: After-tax Cost of Debt | D16: =+D14*(1-D15) -> 0.03816 | L16: -- | M16: =D14-0.01 -> 0.043 | N16: =D14-0.005 -> 0.048 | O16: =$D$14 -> 0.053 | P16: =$D$14+0.005 -> 0.058 | Q16: =$D$14+0.01 -> 0.063
K17: Debt-to-Total Capitalization | L17: =L18-0.01 -> 0.078153751 | M17: =($D$24*$D$11)+($L$17*((1-$D$15)*(M16))) -> 0.067418281 | N17: =($D$24*$D$11)+($L$17*((1-$D$15)*(N16))) -> 0.067699634 | O17: =($D$24*$D$11)+($L$17*((1-$D$15)*(O16))) -> 0.067980988 | P17: =($D$24*$D$11)+($L$17*((1-$D$15)*(P16))) -> 0.068262341 | Q17: =($D$24*$D$11)+($L$17*((1-$D$15)*(Q16))) -> 0.068543695
B18: Cost of Equity | L18: =L19-0.01 -> 0.088153751 | M18: =($D$24*$D$11)+($L$18*((1-$D$15)*(M16))) -> 0.067727881 | N18: =($D$24*$D$11)+($L$18*((1-$D$15)*(N16))) -> 0.068045234 | O18: =($D$24*$D$11)+($L$18*((1-$D$15)*(O16))) -> 0.068362588 | P18: =($D$24*$D$11)+($L$18*((1-$D$15)*(P16))) -> 0.068679941 | Q18: =($D$24*$D$11)+($L$18*((1-$D$15)*(Q16))) -> 0.068997295
B19: Risk-free Rate | D19: 0.0182 | E19: *China Risk Free Rate | L19: =D10 -> 0.098153751 | M19: =($D$24*$D$11)+($L$19*((1-$D$15)*(M16))) -> 0.068037481 | N19: =($D$24*$D$11)+($L$19*((1-$D$15)*(N16))) -> 0.068390834 | O19: =($D$24*$D$11)+($L$19*((1-$D$15)*(O16))) -> 0.068744188 | P19: =($D$24*$D$11)+($L$19*((1-$D$15)*(P16))) -> 0.069097541 | Q19: =($D$24*$D$11)+($L$19*((1-$D$15)*(Q16))) -> 0.069450895
B20: Market Risk Premium | D20: 0.057 | L20: =L19+0.01 -> 0.10815375 | M20: =($D$24*$D$11)+($L$20*((1-$D$15)*(M16))) -> 0.068347081 | N20: =($D$24*$D$11)+($L$20*((1-$D$15)*(N16))) -> 0.068736434 | O20: =($D$24*$D$11)+($L$20*((1-$D$15)*(O16))) -> 0.069125788 | P20: =($D$24*$D$11)+($L$20*((1-$D$15)*(P16))) -> 0.069515141 | Q20: =($D$24*$D$11)+($L$20*((1-$D$15)*(Q16))) -> 0.069904495
B21: Country Risk Premium | D21: 0.0091 | E21: *Adjustment based on China country risk | L21: =L20+0.01 -> 0.11815375 | M21: =($D$24*$D$11)+($L$21*((1-$D$15)*(M16))) -> 0.068656681 | N21: =($D$24*$D$11)+($L$21*((1-$D$15)*(N16))) -> 0.069082034 | O21: =($D$24*$D$11)+($L$21*((1-$D$15)*(O16))) -> 0.069507388 | P21: =($D$24*$D$11)+($L$21*((1-$D$15)*(P16))) -> 0.069932741 | Q21: =($D$24*$D$11)+($L$21*((1-$D$15)*(Q16))) -> 0.070358095
B22: Levered Beta | D22: =Q12 -> 0.81502061
M23: Levered Beta
B24: Cost of Equity | D24: =D19+(D22*(D21+D20)) -> 0.072072862 | L24: =D28 -> 0 | M24: =N24-0.25 -> 0.31502061 | N24: =O24-0.25 -> 0.56502061 | O24: =Q12 -> 0.81502061 | P24: =O24+0.25 -> 1.0650206 | Q24: =P24+0.25 -> 1.3150206
K25: MRP | L25: =L26-0.0025 -> 0.052 | M25: =($D$10*$D$16)+($D$11*($D$19+($L$25*M24))) -> 0.034932357 | N25: =($D$10*$D$16)+($D$11*($D$19+($L$25*N24))) -> 0.046656358 | O25: =($D$10*$D$16)+($D$11*($D$19+($L$25*O24))) -> 0.058380359 | P25: =($D$10*$D$16)+($D$11*($D$19+($L$25*P24))) -> 0.070104361 | Q25: =($D$10*$D$16)+($D$11*($D$19+($L$25*Q24))) -> 0.081828362
L26: =L27-0.0025 -> 0.0545 | M26: =($D$10*$D$16)+($D$11*($D$19+($L$26*M24))) -> 0.035642607 | N26: =($D$10*$D$16)+($D$11*($D$19+($L$26*N24))) -> 0.047930263 | O26: =($D$10*$D$16)+($D$11*($D$19+($L$26*O24))) -> 0.060217918 | P26: =($D$10*$D$16)+($D$11*($D$19+($L$26*P24))) -> 0.072505573 | Q26: =($D$10*$D$16)+($D$11*($D$19+($L$26*Q24))) -> 0.084793228
B27: WACC | D27: =(D10*D16)+(D11*D24) -> 0.068744188 | L27: =D20 -> 0.057 | M27: =($D$10*$D$16)+($D$11*($D$19+($L$27*M24))) -> 0.036352858 | N27: =($D$10*$D$16)+($D$11*($D$19+($L$27*N24))) -> 0.049204167 | O27: =($D$10*$D$16)+($D$11*($D$19+($L$27*O24))) -> 0.062055476 | P27: =($D$10*$D$16)+($D$11*($D$19+($L$27*P24))) -> 0.074906785 | Q27: =($D$10*$D$16)+($D$11*($D$19+($L$27*Q24))) -> 0.087758094
L28: =L27+0.0025 -> 0.0595 | M28: =($D$10*$D$16)+($D$11*($D$19+($L$28*M24))) -> 0.037063108 | N28: =($D$10*$D$16)+($D$11*($D$19+($L$28*N24))) -> 0.050478071 | O28: =($D$10*$D$16)+($D$11*($D$19+($L$28*O24))) -> 0.063893034 | P28: =($D$10*$D$16)+($D$11*($D$19+($L$28*P24))) -> 0.077307997 | Q28: =($D$10*$D$16)+($D$11*($D$19+($L$28*Q24))) -> 0.09072296
L29: =L28+0.0025 -> 0.062 | M29: =($D$10*$D$16)+($D$11*($D$19+($L$29*M24))) -> 0.037773359 | N29: =($D$10*$D$16)+($D$11*($D$19+($L$29*N24))) -> 0.051751975 | O29: =($D$10*$D$16)+($D$11*($D$19+($L$29*O24))) -> 0.065730592 | P29: =($D$10*$D$16)+($D$11*($D$19+($L$29*P24))) -> 0.079709209 | Q29: =($D$10*$D$16)+($D$11*($D$19+($L$29*Q24))) -> 0.093687826

Sheet Revenue Build
B2: Luckin Coffee Inc (OTCMKTS: LKNCY)
B3: Revenue Build
B4: In Millions of $USD (except share price)
B6: Sources: Factset Fundamentals, Luckin 20-F Filings, Bank of America Currency
B8: all figures in M unless otherwise stated | C8: FY 20 | D8: FY 21 | E8: FY 22 | F8: FY 23 | G8: FY 24 | H8: FY 25 | I8: FY 26 | J8: FY 27 | K8: FY 28 | L8: FY 29 | M8: FY 30 | N8: FY 31
B10: Total Revenue Projected
B12: Total Revenue | C12: =SUM(C15,C19,C23,C27,) -> 584.84561 | D12: =SUM(D15,D19,D23,D27,) -> 1217.1014 | E12: =SUM(E15,E19,E23,E27,) -> 2086.9982 | F12: =SUM(F15,F19,F23,F27,) -> 3625.901 | G12: =SUM(G15,G19,G23,G27,) -> 4781.6567 | H12: =SUM(H15,H19,H23,H27,) -> 6791.8988 | I12: =SUM(I15,I19,I23,I27,) -> 8638.5033 | J12: =SUM(J15,J19,J23,J27,) -> 10500.037 | ... N12: =SUM(N15,N19,N23,N27,) -> 17518.546
B13: % Growth | D13: =(D12-C12)/C12 -> 1.0810644 | E13: =(E12-D12)/D12 -> 0.71472833 | F13: =(F12-E12)/E12 -> 0.73737621 | G13: =(G12-F12)/F12 -> 0.31874994 | H13: =(H12-G12)/G12 -> 0.42040703 | I13: =(I12-H12)/H12 -> 0.2718834 | J13: =(J12-I12)/I12 -> 0.21549261 | K13: =(K12-J12)/J12 -> 0.1838633 | ... N13: =(N12-M12)/M12 -> 0.092378359
B15: Freshly Brewed Drinks | C15: =C37*C$31 -> 466.71237 | D15: =D37*D$31 -> 902.99528 | E15: =E37*E$31 -> 1425.4578 | F15: =F37*F$31 -> 2457.4193 | G15: =G37*G$31 -> 3398.3005 | H15: =H37*H$31 -> 4770.195 | I15: =H15*(1+I16) -> 6105.8497 | J15: =I15*(1+J16) -> 7449.1366 | K15: =J15*(1+K16) -> 8789.9812 | L15: =K15*(1+L16) -> 10020.579 | M15: =L15*(1+M16) -> 11122.842 | N15: =M15*(1+N16) -> 12123.898
B16: % Growth | D16: =(D15-C15)/C15 -> 0.93480041 | E16: =(E15-D15)/D15 -> 0.5785883 | F16: =(F15-E15)/E15 -> 0.72395096 | G16: =(G15-F15)/F15 -> 0.38287367 | H16: =(H15-G15)/G15 -> 0.40370019 | I16: ='Revenue Assumptions'!F9 -> 0.28 | J16: ='Revenue Assumptions'!G9 -> 0.22 | K16: ='Revenue Assumptions'!H9 -> 0.18 | L16: ='Revenue Assumptions'!I9 -> 0.14 | M16: ='Revenue Assumptions'!J9 -> 0.11 | N16: ='Revenue Assumptions'!K9 -> 0.09 | O16: *Reflective of non-franchise stores opening in China as they expand to untapped regions
B17: % of total revenue | C17: =C15/C$12 -> 0.79800953 | D17: =D15/D$12 -> 0.74192283 | E17: =E15/E$12 -> 0.68301823 | F17: =F15/F$12 -> 0.67774033 | G17: =G15/G$12 -> 0.7106952 | H17: =H15/H$12 -> 0.702336 | I17: =I15/I$12 -> 0.706818 | J17: =J15/J$12 -> 0.70943908 | ... N17: =N15/N$12 -> 0.69206074
B19: Other Product Revenue | C19: =C38*C$31 -> 44.913025 | D19: =D38*D$31 -> 60.443554 | E19: =E38*E$31 -> 107.83341 | F19: =F38*F$31 -> 180.81598 | G19: =G38*G$31 -> 233.76678 | H19: =H38*H$31 -> 319.57198 | I19: =H19*(1+I20) -> 399.46497 | J19: =I19*(1+J20) -> 479.35797 | K19: =J19*(1+K20) -> 565.6424 | L19: =K19*(1+L20) -> 650.48877 | M19: =L19*(1+M20) -> 728.54742 | N19: =M19*(1+N20) -> 794.11668
B20: % Growth | D20: =(D19-C19)/C19 -> 0.34579121 | E20: =(E19-D19)/D19 -> 0.78403487 | F20: =(F19-E19)/E19 -> 0.67680854 | G20: =(G19-F19)/F19 -> 0.2928436 | H20: =(H19-G19)/G19 -> 0.3670547 | I20: ='Revenue Assumptions'!F14 -> 0.25 | J20: ='Revenue Assumptions'!G14 -> 0.2 | K20: ='Revenue Assumptions'!H14 -> 0.18 | L20: ='Revenue Assumptions'!I14 -> 0.15 | M20: ='Revenue Assumptions'!J14 -> 0.12 | N20: ='Revenue Assumptions'!K14 -> 0.09 | O20: *Strong growth as new stores expand, leading to similar growth relative to drinks
B21: % of total revenue | C21: =C19/C$12 -> 0.076794669 | D21: =D19/D$12 -> 0.049661891 | E21: =E19/E$12 -> 0.051669144 | F21: =F19/F$12 -> 0.049867876 | G21: =G19/G$12 -> 0.048888241 | H21: =H19/H$12 -> 0.047051935 | I21: =I19/I$12 -> 0.046242382 | J21: =J19/J$12 -> 0.045652979 | ... N21: =N19/N$12 -> 0.045330057
B23: Miscellaneous Store Revenue | C23: =C39*C$31 -> 27.3093 | D23: =D39*D$31 -> 54.089672 | E23: =E39*E$31 -> 71.832838 | F23: =F39*F$31 -> 81.192675 | G23: =G39*G$31 -> 75.317567 | H23: =H39*H$31 -> 104.5213 | I23: =H23*(1+I24) -> 120.19949 | J23: =I23*(1+J24) -> 135.82543 | K23: =J23*(1+K24) -> 152.12448 | L23: =K23*(1+L24) -> 168.85817 | M23: =L23*(1+M24) -> 185.74399 | N23: =M23*(1+N24) -> 200.60351
B24: % Growth | D24: =(D23-C23)/C23 -> 0.98063195 | E24: =(E23-D23)/D23 -> 0.32803242 | F24: =(F23-E23)/E23 -> 0.13030026 | G24: =(G23-F23)/F23 -> -0.07236007 | H24: =(H23-G23)/G23 -> 0.38774131 | I24: ='Revenue Assumptions'!F19 -> 0.15 | J24: ='Revenue Assumptions'!G19 -> 0.13 | K24: ='Revenue Assumptions'!H19 -> 0.12 | L24: ='Revenue Assumptions'!I19 -> 0.11 | M24: ='Revenue Assumptions'!J19 -> 0.1 | N24: ='Revenue Assumptions'!K19 -> 0.08 | O24: *Slow growth from merchandise and associated products as new stores open with relatively lower % sales
B25: % of total revenue | C25: =C23/C$12 -> 0.046694888 | D25: =D23/D$12 -> 0.044441387 | E25: =E23/E$12 -> 0.034419215 | F25: =F23/F$12 -> 0.022392414 | G25: =G23/G$12 -> 0.015751354 | H25: =H23/H$12 -> 0.015389113 | I25: =I23/I$12 -> 0.013914389 | J25: =J23/J$12 -> 0.01293571 | ... N25: =N23/N$12 -> 0.011450922
B27: Partnership Store Revenue | C27: =C40*C$31 -> 45.910915 | D27: =D40*D$31 -> 199.57284 | E27: =E40*E$31 -> 481.87413 | F27: =F40*F$31 -> 906.47299 | G27: =G40*G$31 -> 1074.2719 | H27: =H40*H$31 -> 1597.6105 | I27: =H27*(1+I28) -> 2012.9892 | J27: =I27*(1+J28) -> 2435.7169 | K27: =J27*(1+K28) -> 2922.8603 | L27: =K27*(1+L28) -> 3478.2038 | M27: =L27*(1+M28) -> 3999.9344 | N27: =M27*(1+N28) -> 4399.9278
B28: % Growth | D28: =(D27-C27)/C27 -> 3.3469585 | E28: =(E27-D27)/D27 -> 1.4145276 | F28: =(F27-E27)/E27 -> 0.88114058 | G28: =(G27-F27)/F27 -> 0.18511183 | H28: =(H27-G27)/G27 -> 0.48715659 | I28: ='Revenue Assumptions'!F24 -> 0.26 | J28: ='Revenue Assumptions'!G24 -> 0.21 | K28: ='Revenue Assumptions'!H24 -> 0.2 | L28: ='Revenue Assumptions'!I24 -> 0.19 | M28: ='Revenue Assumptions'!J24 -> 0.15 | N28: ='Revenue Assumptions'!K24 -> 0.1 | O28: *Growth stagnates as initial international expansion will not be franchised,
B29: % of total revenue | C29: =C27/C$12 -> 0.078500914 | D29: =D27/D$12 -> 0.16397389 | E29: =E27/E$12 -> 0.23089341 | F29: =F27/F$12 -> 0.24999938 | G29: =G27/G$12 -> 0.2246652 | H29: =H27/H$12 -> 0.23522295 | I29: =I27/I$12 -> 0.23302523 | J29: =J27/J$12 -> 0.23197223 | ... N29: =N27/N$12 -> 0.25115828 | O29: and franchising model matures in China. International franchising leads to maintained growth rate in years 3-5
B31: Exchange Rate (CNY to USD) | C31: 0.145 | D31: 0.1528 | E31: 0.157 | F31: 0.1456 | G31: 0.1387 | H31: 0.1378 | I31: 0.145 | J31: 0.145 | K31: 0.145 | L31: 0.145 | M31: 0.145 | N31: 0.145 | O31: *Assume Constant from 2026 Onwards
B34: Revenue Breakdown in CNY
B37: Freshly Brewed Drinks | C37: 3218.706 | D37: 5909.655 | E37: 9079.349 | F37: 16877.88 | G37: 24501.085 | H37: 34616.8
B38: Other Product Revenue | C38: 309.745 | D38: 395.573 | E38: 686.837 | F38: 1241.868 | G38: 1685.413 | H38: 2319.1
B39: Miscellaneous Store Revenue | C39: 188.34 | D39: 353.99 | E39: 457.534 | F39: 557.642 | G39: 543.025 | H39: 758.5
B40: Partnership Store Revenue | C40: 316.627 | D40: 1306.105 | E40: 3069.262 | F40: 6225.776 | G40: 7745.291 | H40: 11593.69

Sheet Revenue Assumptions
B2: Luckin Coffee Inc (OTCMKTS: LKNCY)
B3: Revenue Build Assumptions
F5: FY 26 | G5: FY 27 | H5: FY 28 | I5: FY 29 | J5: FY 30 | K5: FY 31
B7: Revenue Build Breakdown
B9: Freshly Brewed Drinks % Growth | F9: =CHOOSE(Cover!$F$9, F10,F11,F12) -> 0.28 | G9: =CHOOSE(Cover!$F$9, G10,G11,G12) -> 0.22 | H9: =CHOOSE(Cover!$F$9, H10,H11,H12) -> 0.18 | I9: =CHOOSE(Cover!$F$9, I10,I11,I12) -> 0.14 | J9: =CHOOSE(Cover!$F$9, J10,J11,J12) -> 0.11 | K9: =CHOOSE(Cover!$F$9, K10,K11,K12) -> 0.09
B10: Upside | F10: 0.3 | G10: 0.24 | H10: 0.2 | I10: 0.16 | J10: 0.13 | K10: 0.11 | L10: *Upside Case reflectives strong international growth and market demand
B11: Base | F11: 0.28 | G11: 0.22 | H11: 0.18 | I11: 0.14 | J11: 0.11 | K11: 0.09 | L11: *Base Case reflects sustained international growth
B12: Downside | F12: 0.24 | G12: 0.18 | H12: 0.15 | I12: 0.11 | J12: 0.08 | K12: 0.06 | L12: *Downside Case reflective of only China growth
B14: Other Products Revenue | F14: =CHOOSE(Cover!$F$9, F15,F16,F17) -> 0.25 | G14: =CHOOSE(Cover!$F$9, G15,G16,G17) -> 0.2 | H14: =CHOOSE(Cover!$F$9, H15,H16,H17) -> 0.18 | I14: =CHOOSE(Cover!$F$9, I15,I16,I17) -> 0.15 | J14: =CHOOSE(Cover!$F$9, J15,J16,J17) -> 0.12 | K14: =CHOOSE(Cover!$F$9, K15,K16,K17) -> 0.09
B15: Upside | F15: 0.26 | G15: 0.21 | H15: 0.19 | I15: 0.16 | J15: 0.13 | K15: 0.1
B16: Base | F16: 0.25 | G16: 0.2 | H16: 0.18 | I16: 0.15 | J16: 0.12 | K16: 0.09
B17: Downside | F17: 0.22 | G17: 0.17 | H17: 0.16 | I17: 0.13 | J17: 0.1 | K17: 0.08
B19: Miscellaneous Store Revenue | F19: =CHOOSE(Cover!$F$9, F20,F21,F22) -> 0.15 | G19: =CHOOSE(Cover!$F$9, G20,G21,G22) -> 0.13 | H19: =CHOOSE(Cover!$F$9, H20,H21,H22) -> 0.12 | I19: =CHOOSE(Cover!$F$9, I20,I21,I22) -> 0.11 | J19: =CHOOSE(Cover!$F$9, J20,J21,J22) -> 0.1 | K19: =CHOOSE(Cover!$F$9, K20,K21,K22) -> 0.08
B20: Upside | F20: 0.17 | G20: 0.15 | H20: 0.14 | I20: 0.13 | J20: 0.12 | K20: 0.1
B21: Base | F21: 0.15 | G21: 0.13 | H21: 0.12 | I21: 0.11 | J21: 0.1 | K21: 0.08
B22: Downside | F22: 0.13 | G22: 0.11 | H22: 0.1 | I22: 0.09 | J22: 0.08 | K22: 0.07
B24: Partnership Store Revenue | F24: =CHOOSE(Cover!$F$9, F25,F26,F27) -> 0.26 | G24: =CHOOSE(Cover!$F$9, G25,G26,G27) -> 0.21 | H24: =CHOOSE(Cover!$F$9, H25,H26,H27) -> 0.2 | I24: =CHOOSE(Cover!$F$9, I25,I26,I27) -> 0.19 | J24: =CHOOSE(Cover!$F$9, J25,J26,J27) -> 0.15 | K24: =CHOOSE(Cover!$F$9, K25,K26,K27) -> 0.1
B25: Upside | F25: 0.28 | G25: 0.23 | H25: 0.22 | I25: 0.21 | J25: 0.17 | K25: 0.12
B26: Base | F26: 0.26 | G26: 0.21 | H26: 0.2 | I26: 0.19 | J26: 0.15 | K26: 0.1
B27: Downside | F27: 0.24 | G27: 0.19 | H27: 0.18 | I27: 0.17 | J27: 0.13 | K27: 0.08

Sheet Operating Model
B2: Luckin Coffee Inc (OTCMKTS: LKNCY)
B3: Operating Model
B4: In Millions of $USD (except share price)
B6: Sources: Factset Fundamentals, Luckin 20-F Filings
B8: all figures in M unless otherwise stated | C8: FY 20 | D8: FY 21 | E8: FY 22 | F8: FY 23 | G8: FY 24 | H8: FY 25 | I8: FY 26 | J8: FY 27 | K8: FY 28 | L8: FY 29 | M8: FY 30 | N8: FY 31
B10: Operating Statement
B12: Revenue | C12: =IS!D6 -> 584.3641 | D12: =IS!E6 -> 1235.0567 | E12: =IS!F6 -> 1974.0937 | F12: =IS!G6 -> 3514.8999 | G12: =IS!H6 -> 4790.2859 | H12: =IS!I6 -> 6856.5697 | I12: ='Revenue Build'!I12 -> 8638.5033 | J12: ='Revenue Build'!J12 -> 10500.037 | K12: ='Revenue Build'!K12 -> 12430.608 | L12: ='Revenue Build'!L12 -> 14318.129 | M12: ='Revenue Build'!M12 -> 16037.068 | N12: ='Revenue Build'!N12 -> 17518.546
B13: % growth | D13: =D12/C12-1 -> 1.1135054 | E13: =E12/D12-1 -> 0.59838305 | F13: =F12/E12-1 -> 0.78051322 | G13: =G12/F12-1 -> 0.36285133 | H13: =H12/G12-1 -> 0.43134873 | I13: =I12/H12-1 -> 0.25988705 | J13: =J12/I12-1 -> 0.21549261 | K13: =K12/J12-1 -> 0.1838633 | ... N13: =N12/M12-1 -> 0.092378359
B15: COGS (Excluding D&A) | C15: =IS!D8 -> 289.09189 | D15: =IS!E8 -> 391.61136 | E15: =IS!F8 -> 642.19583 | F15: =IS!G8 -> 1339.8695 | G15: =IS!H8 -> 1637.3043 | H15: =IS!I8 -> 2613.0053 | I15: =I12*I16 -> 3282.6313 | J15: =J12*J16 -> 3990.014 | K15: =K12*K16 -> 4847.9373 | L15: =L12*L16 -> 5584.0704 | M15: =M12*M16 -> 6414.8272 | N15: =N12*N16 -> 7007.4184
B16: % revenue | C16: =C15/C12 -> 0.49471193 | D16: =D15/D12 -> 0.31707967 | E16: =E15/E12 -> 0.32531173 | F16: =F15/F12 -> 0.38119707 | G16: =G15/G12 -> 0.34179677 | H16: =H15/H12 -> 0.38109513 | I16: ='Operating Assumptions'!F9 -> 0.38 | J16: ='Operating Assumptions'!G9 -> 0.38 | K16: ='Operating Assumptions'!H9 -> 0.39 | L16: ='Operating Assumptions'!I9 -> 0.39 | M16: ='Operating Assumptions'!J9 -> 0.4 | N16: ='Operating Assumptions'!K9 -> 0.4 | O16: *Increases 200 bps as revenue becomes more tied to low margin coffee
B17: Gross Profit | C17: =C12-C15 -> 295.27221 | D17: =D12-D15 -> 843.44531 | E17: =E12-E15 -> 1331.8978 | F17: =F12-F15 -> 2175.0303 | G17: =G12-G15 -> 3152.9817 | H17: =H12-H15 -> 4243.5644 | I17: =I12-I15 -> 5355.8721 | J17: =J12-J15 -> 6510.0229 | ... N17: =N12-N15 -> 10511.128
B18: GP margin (%) | C18: =C17/C12 -> 0.50528807 | D18: =D17/D12 -> 0.68292033 | E18: =E17/E12 -> 0.67468827 | F18: =F17/F12 -> 0.61880293 | G18: =G17/G12 -> 0.65820323 | H18: =H17/H12 -> 0.61890487 | I18: =I17/I12 -> 0.62 | J18: =J17/J12 -> 0.62 | ... N18: =N17/N12 -> 0.6
B20: OpEx
B21: SG&A | C21: =IS!D12 -> 519.42368 | D21: =IS!E12 -> 692.03226 | E21: =IS!F12 -> 925.62263 | F21: =IS!G12 -> 1452.973 | G21: =IS!H12 -> 2181.8698 | H21: =IS!I12 -> 3307.1678 | I21: =I22*I12 -> 3887.3265 | J21: =J22*J12 -> 4672.5164 | K21: =K22*K12 -> 5469.4677 | L21: =L22*L12 -> 6228.3862 | M21: =M22*M12 -> 6895.9392 | N21: =N22*N12 -> 7445.382
B22: % revenue | C22: =C21/C12 -> 0.88886994 | D22: =D21/D12 -> 0.5603243 | E22: =E21/E12 -> 0.46888486 | F22: =F21/F12 -> 0.41337535 | G22: =G21/G12 -> 0.45547799 | H22: =H21/H12 -> 0.48233562 | I22: ='Operating Assumptions'!F14 -> 0.45 | J22: ='Operating Assumptions'!G14 -> 0.445 | K22: ='Operating Assumptions'!H14 -> 0.44 | L22: ='Operating Assumptions'!I14 -> 0.435 | M22: ='Operating Assumptions'!J14 -> 0.43 | N22: ='Operating Assumptions'!K14 -> 0.425 | O22: *Management goal to lean down overall management, as they push towards profitability focus
B23: Depreciation | C23: =IS!D10 -> 70.038335 | D23: =IS!E10 -> 176.49725 | E23: =IS!F10 -> 185.11864 | F23: =IS!G10 -> 282.8189 | G23: =IS!H10 -> 489.37686 | H23: =IS!I10 -> 216.6508 | I23: =I24*I12 -> 734.27278 | J23: =J24*J12 -> 892.50314 | K23: =K24*K12 -> 994.44867 | L23: =L24*L12 -> 1145.4503 | M23: =M24*M12 -> 1202.7801 | N23: =N24*N12 -> 1313.8909
B24: % revenue | C24: =C23/C12 -> 0.11985393 | D24: =D23/D12 -> 0.14290619 | E24: =E23/E12 -> 0.093773993 | F24: =F23/F12 -> 0.080462862 | G24: =G23/G12 -> 0.10216026 | H24: =H23/H12 -> 0.031597549 | I24: ='Operating Assumptions'!F19 -> 0.085 | J24: ='Operating Assumptions'!G19 -> 0.085 | K24: ='Operating Assumptions'!H19 -> 0.08 | L24: ='Operating Assumptions'!I19 -> 0.08 | M24: ='Operating Assumptions'!J19 -> 0.075 | N24: ='Operating Assumptions'!K19 -> 0.075 | O24: *Decreases 100 bps as revenue per store scales relative to new store growth
B25: Other Operating Expenses | C25: =IS!D13 -> 0 | D25: =IS!E13 -> 39.025278 | E25: =IS!F13 -> 44.757618 | F25: =IS!G13 -> 47.82239 | G25: =IS!H13 -> 68.619914 | H25: =IS!I13 -> 0 | I25: 8.5 | J25: =J26*J12 -> 105.00037 | K25: =K26*K12 -> 99.444867 | L25: =L26*L12 -> 114.54503 | M25: =M26*M12 -> 112.25948 | N25: =N26*N12 -> 122.62982
B26: % revenue | C26: =C25/C12 -> 0 | D26: =D25/D12 -> 0.031597965 | E26: =E25/E12 -> 0.02267249 | F26: =F25/F12 -> 0.013605619 | G26: =G25/G12 -> 0.014324805 | H26: =H25/H12 -> 0 | I26: ='Operating Assumptions'!F24 -> 0.01 | J26: ='Operating Assumptions'!G24 -> 0.01 | K26: ='Operating Assumptions'!H24 -> 0.008 | L26: ='Operating Assumptions'!I24 -> 0.008 | M26: ='Operating Assumptions'!J24 -> 0.007 | N26: ='Operating Assumptions'!K24 -> 0.007 | O26: *Reflects R&D investment into Algorithmic Product Development, a fixed cost investment regardless of number of stores
B27: Total OpEx | C27: =C21+C23+C25 -> 589.46202 | D27: =D21+D23+D25 -> 907.55479 | E27: =E21+E23+E25 -> 1155.4989 | F27: =F21+F23+F25 -> 1783.6143 | G27: =G21+G23+G25 -> 2739.8666 | H27: =H21+H23+H25 -> 3523.8186 | I27: =I21+I23+I25 -> 4630.0993 | J27: =J21+J23+J25 -> 5670.0199 | ... N27: =N21+N23+N25 -> 8881.9028
B28: Operating Income (EBIT) | C28: =C17-C21-C23-C25 -> -294.18981 | D28: =D17-D21-D23-D25 -> -64.109479 | E28: =E17-E21-E23-E25 -> 176.39894 | F28: =F17-F21-F23-F25 -> 391.41606 | G28: =G17-G21-G23-G25 -> 413.1151 | H28: =H17-H21-H23-H25 -> 719.74576 | I28: =I17-I21-I23-I25 -> 725.77278 | J28: =J17-J21-J23-J25 -> 840.00295 | ... N28: =N17-N21-N23-N25 -> 1629.2248
B29: EBIT margin (%) | C29: =C28/C12 -> -0.5034358 | D29: =D28/D12 -> -0.051908127 | E29: =E28/E12 -> 0.089356925 | F29: =F28/F12 -> 0.11135909 | G29: =G28/G12 -> 0.086240175 | H29: =H28/H12 -> 0.1049717 | I29: =I28/I12 -> 0.084016033 | J29: =J28/J12 -> 0.08 | ... N29: =N28/N12 -> 0.093 | O29: *Reflects management goals of targeted margins by 2028
B31: EBITDA | C31: =C28+C23 -> -224.15147 | D31: =D28+D23 -> 112.38777 | E31: =E28+E23 -> 361.51758 | F31: =F28+F23 -> 674.23496 | G31: =G28+G23 -> 902.49196 | H31: =H28+H23 -> 936.39656 | I31: =I28+I23 -> 1460.0456 | J31: =J28+J23 -> 1732.5061 | ... N31: =N28+N23 -> 2943.1157
B32: EBITDA margin (%) | C32: =C31/C12 -> -0.38358187 | D32: =D31/D12 -> 0.090998067 | E32: =E31/E12 -> 0.18313092 | F32: =F31/F12 -> 0.19182196 | G32: =G31/G12 -> 0.18840044 | H32: =H31/H12 -> 0.13656925 | I32: =I31/I12 -> 0.16901603 | J32: =J31/J12 -> 0.165 | ... N32: =N31/N12 -> 0.168
B34: Interest Payment | C34: =IS!D20 -> 16.874391 | D34: =IS!E20 -> 5.502873 | E34: =IS!F20 -> 3.487526 | F34: =IS!G20 -> 0 | G34: =IS!H20 -> 0.545241 | H34: =IS!I20 -> 0.017389 | I34: =I28*0.08 -> 58.061823 | J34: =J28*0.08 -> 67.200236 | K34: =K28*0.08 -> 81.544791 | L34: =L28*0.08 -> 99.65418 | M34: =M28*0.08 -> 112.90096 | N34: =N28*0.08 -> 130.33798 | O34: *As debt is taken on through LBO, interest payment will grow accordingly
B36: EBITDA Adjustment
B38: EBITDA | C38: =C31 -> -224.15147 | D38: =D31 -> 112.38777 | E38: =E31 -> 361.51758 | F38: =F31 -> 674.23496 | G38: =G31 -> 902.49196 | H38: =H31 -> 936.39656 | I38: =I31 -> 1460.0456 | J38: =J31 -> 1732.5061 | ... N38: =N31 -> 2943.1157
B39: Unusual Expenses | C39: =IS!D22 -> 592.54899 | D39: =IS!E22 -> -97.720575 | E39: =IS!F22 -> 68.197581 | F39: =IS!G22 -> 9.725578 | G39: =IS!H22 -> -19.544472 | H39: =IS!I22 -> 7.071624 | I39: =AVERAGE(E39:H39) -> 16.362578 | J39: =I39*(1+0.02) -> 16.689829 | K39: =J39*(1+0.02) -> 17.023626 | L39: =K39*(1+0.02) -> 17.364098 | M39: =L39*(1+0.02) -> 17.71138 | N39: =M39*(1+0.02) -> 18.065608 | O39: *Used historical average of non-irregular figures, then base projection rate used
B40: Stock-Based Compensation | C40: =IS!D55 -> 2.393681 | D40: =IS!E55 -> 29.482352 | E40: =IS!F55 -> 35.297275 | F40: =IS!G55 -> 25.353391 | G40: =IS!H55 -> 38.021597 | H40: =IS!I55 -> 62.988133 | I40: =AVERAGE(E40:H40) -> 40.415099 | J40: =I40*1.02 -> 41.223401 | K40: =J40*1.02 -> 42.047869 | L40: =K40*1.02 -> 42.888826 | M40: =L40*1.02 -> 43.746603 | N40: =M40*1.02 -> 44.621535 | O40: *Used historical average of non-irregular figures, then base projection rate used
B41: Adjusted EBITDA | C41: =C38+C39+C40 -> 370.7912 | D41: =D38+D39+D40 -> 44.149547 | E41: =E38+E39+E40 -> 465.01244 | F41: =F38+F39+F40 -> 709.31393 | G41: =G38+G39+G40 -> 920.96909 | H41: =H38+H39+H40 -> 1006.4563 | I41: =I38+I39+I40 -> 1516.8232 | J41: =J38+J39+J40 -> 1790.4193 | ... N41: =N38+N39+N40 -> 3005.8029
B44: Working Capital
B46: Revenue | C46: =C12 -> 584.3641 | D46: =D12 -> 1235.0567 | E46: =E12 -> 1974.0937 | F46: =F12 -> 3514.8999 | G46: =G12 -> 4790.2859 | H46: =H12 -> 6856.5697 | I46: =I12 -> 8638.5033 | J46: =J12 -> 10500.037 | ... N46: =N12 -> 17518.546
B47: COGS | C47: =C15 -> 289.09189 | D47: =D15 -> 391.61136 | E47: =E15 -> 642.19583 | F47: =F15 -> 1339.8695 | G47: =G15 -> 1637.3043 | H47: =H15 -> 2613.0053 | I47: =I15 -> 3282.6313 | J47: =J15 -> 3990.014 | ... N47: =N15 -> 7007.4184
B50: Non-Cash Current Assets
B51: Short-Term Receivables | C51: =BS!D9 -> 100.24833 | D51: =BS!E9 -> 133.59536 | E51: =BS!F9 -> 137.80442 | F51: =BS!G9 -> 199.09605 | G51: =BS!H9 -> 275.91232 | H51: =(H52/365)*H46 -> 394.48757 | I51: =(I52/365)*I46 -> 473.34265 | J51: =(J52/365)*J46 -> 575.34449 | K51: =(K52/365)*K46 -> 681.12923 | L51: =(L52/365)*L46 -> 745.32728 | M51: =(M52/365)*M46 -> 834.80628 | N51: =(N52/365)*N46 -> 911.92431
B52: DSO | C52: =C51/C46*365 -> 62.616165 | D52: =D51/D46*365 -> 39.481838 | E52: =E51/E46*365 -> 25.479345 | F52: =F51/F46*365 -> 20.674859 | G52: =G51/G46*365 -> 21.023379 | H52: 21 | I52: ='Operating Assumptions'!Q9 -> 20 | J52: ='Operating Assumptions'!R9 -> 20 | K52: ='Operating Assumptions'!S9 -> 20 | L52: ='Operating Assumptions'!T9 -> 19 | M52: ='Operating Assumptions'!U9 -> 19 | N52: ='Operating Assumptions'!V9 -> 19 | O52: *As Luckin scales, gets more payment power over partnership stores for royalties
B53: Inventory | C53: =BS!D13 -> 42.137068 | D53: =BS!E13 -> 93.097037 | E53: =BS!F13 -> 173.54992 | F53: =BS!G13 -> 310.76394 | G53: =BS!H13 -> 338.85577 | H53: =(H54/365)*H47 -> 536.9189 | I53: =(I54/365)*I47 -> 674.51327 | J53: =(J54/365)*J47 -> 819.8659 | K53: =(K54/365)*K47 -> 996.15149 | L53: =(L54/365)*L47 -> 1162.7106 | M53: =(M54/365)*M47 -> 1335.69 | N53: =(N54/365)*N47 -> 1459.0789
B54: DIO | C54: =C53/C47*365 -> 53.20118 | D54: =D53/D47*365 -> 86.770767 | E54: =E53/E47*365 -> 98.639261 | F54: =F53/F47*365 -> 84.656628 | G54: =G53/G47*365 -> 75.540241 | H54: 75 | I54: ='Operating Assumptions'!Q14 -> 75 | J54: ='Operating Assumptions'!R14 -> 75 | K54: ='Operating Assumptions'!S14 -> 75 | L54: ='Operating Assumptions'!T14 -> 76 | M54: ='Operating Assumptions'!U14 -> 76 | N54: ='Operating Assumptions'!V14 -> 76 | O54: *As stores grow, inventory on hand scales accordingly with little relative change
B55: Prepaid Expenses | C55: =BS!D18 -> 39.969877 | D55: =BS!E18 -> 49.301702 | E55: =BS!F18 -> 40.007912 | F55: =BS!G18 -> 57.559149 | G55: =BS!H18 -> 59.783676 | H55: =H56*H46 -> 82.278836 | I55: =I56*I46 -> 103.66204 | J55: =J56*J46 -> 126.00044 | K55: =K56*K46 -> 149.1673 | L55: =L56*L46 -> 171.81755 | M55: =M56*M46 -> 192.44482 | N55: =N56*N46 -> 210.22255
B56: % Revenue | C56: =C55/C46 -> 0.068398926 | D56: =D55/D46 -> 0.039918575 | E56: =E55/E46 -> 0.020266471 | F56: =F55/F46 -> 0.016375758 | G56: =G55/G46 -> 0.012480189 | H56: 0.012 | I56: ='Operating Assumptions'!Q19 -> 0.012 | J56: ='Operating Assumptions'!R19 -> 0.012 | K56: ='Operating Assumptions'!S19 -> 0.012 | L56: ='Operating Assumptions'!T19 -> 0.012 | M56: ='Operating Assumptions'!U19 -> 0.012 | N56: ='Operating Assumptions'!V19 -> 0.012
...

Sheet Operating Assumptions
B2: Luckin Coffee Inc (OTCMKTS: LKNCY)
B3: Operating Model Assumptions
F5: FY 26 | G5: FY 27 | H5: FY 28 | I5: FY 29 | J5: FY 30 | K5: FY 31 | Q5: FY 26 | R5: FY 27 | S5: FY 28 | T5: FY 29 | U5: FY 30 | V5: FY 31
B7: Operating Statement Breakdown | M7: Working Capital Assumptions
B9: COGS % Revenue | F9: =CHOOSE(Cover!$F$9, F10,F11,F12) -> 0.38 | G9: =CHOOSE(Cover!$F$9, G10,G11,G12) -> 0.38 | H9: =CHOOSE(Cover!$F$9, H10,H11,H12) -> 0.39 | I9: =CHOOSE(Cover!$F$9, I10,I11,I12) -> 0.39 | J9: =CHOOSE(Cover!$F$9, J10,J11,J12) -> 0.4 | K9: =CHOOSE(Cover!$F$9, K10,K11,K12) -> 0.4 | M9: DSO | Q9: =CHOOSE(Cover!$F$9, Q10,Q11,Q12) -> 20 | R9: =CHOOSE(Cover!$F$9, R10,R11,R12) -> 20 | S9: =CHOOSE(Cover!$F$9, S10,S11,S12) -> 20 | T9: =CHOOSE(Cover!$F$9, T10,T11,T12) -> 19 | U9: =CHOOSE(Cover!$F$9, U10,U11,U12) -> 19 | V9: =CHOOSE(Cover!$F$9, V10,V11,V12) -> 19
B10: Upside | F10: 0.37 | G10: 0.37 | H10: 0.38 | I10: 0.38 | J10: 0.39 | K10: 0.39 | M10: Upside | Q10: 19 | R10: 19 | S10: 18 | T10: 18 | U10: 17 | V10: 17 | W10: *Strong payment power scale
B11: Base | F11: 0.38 | G11: 0.38 | H11: 0.39 | I11: 0.39 | J11: 0.4 | K11: 0.4 | M11: Base | Q11: 20 | R11: 20 | S11: 20 | T11: 19 | U11: 19 | V11: 19 | W11: *Relatively constant payment power
B12: Downside | F12: 0.39 | G12: 0.39 | H12: 0.4 | I12: 0.4 | J12: 0.41 | K12: 0.41 | M12: Downside | Q12: 21 | R12: 21 | S12: 22 | T12: 22 | U12: 23 | V12: 23 | W12: *Reflects declining payment power from high scale attempts
B14: SG&A % Revenue | F14: =CHOOSE(Cover!$F$9, F15,F16,F17) -> 0.45 | G14: =CHOOSE(Cover!$F$9, G15,G16,G17) -> 0.445 | H14: =CHOOSE(Cover!$F$9, H15,H16,H17) -> 0.44 | I14: =CHOOSE(Cover!$F$9, I15,I16,I17) -> 0.435 | J14: =CHOOSE(Cover!$F$9, J15,J16,J17) -> 0.43 | K14: =CHOOSE(Cover!$F$9, K15,K16,K17) -> 0.425 | M14: DIO | Q14: =CHOOSE(Cover!$F$9, Q15,Q16,Q17) -> 75 | R14: =CHOOSE(Cover!$F$9, R15,R16,R17) -> 75 | S14: =CHOOSE(Cover!$F$9, S15,S16,S17) -> 75 | T14: =CHOOSE(Cover!$F$9, T15,T16,T17) -> 76 | U14: =CHOOSE(Cover!$F$9, U15,U16,U17) -> 76 | V14: =CHOOSE(Cover!$F$9, V15,V16,V17) -> 76
B15: Upside | F15: =F16-1% -> 0.44 | G15: =G16-1% -> 0.435 | H15: =H16-1% -> 0.43 | I15: =I16-1% -> 0.425 | J15: =J16-1% -> 0.42 | K15: =K16-1% -> 0.415 | M15: Upside | Q15: 76 | R15: 76 | S15: 77 | T15: 77 | U15: 78 | V15: 78 | W15: *More flexibility with scale
B16: Base | F16: 0.45 | G16: 0.445 | H16: 0.44 | I16: 0.435 | J16: 0.43 | K16: 0.425 | M16: Base | Q16: 75 | R16: 75 | S16: 75 | T16: 76 | U16: 76 | V16: 76 | W16: *Little changing flexibility
B17: Downside | F17: =F16+1% -> 0.46 | G17: =G16+1% -> 0.455 | H17: =H16+1% -> 0.45 | I17: =I16+1% -> 0.445 | J17: =J16+1% -> 0.44 | K17: =K16+1% -> 0.435 | M17: Downside | Q17: 74 | R17: 74 | S17: 73 | T17: 73 | U17: 72 | V17: 72 | W17: *Declining flexibility due to high scale attempt
B19: Depreciation % Revenue | F19: =CHOOSE(Cover!$F$9, F20,F21,F22) -> 0.085 | G19: =CHOOSE(Cover!$F$9, G20,G21,G22) -> 0.085 | H19: =CHOOSE(Cover!$F$9, H20,H21,H22) -> 0.08 | I19: =CHOOSE(Cover!$F$9, I20,I21,I22) -> 0.08 | J19: =CHOOSE(Cover!$F$9, J20,J21,J22) -> 0.075 | K19: =CHOOSE(Cover!$F$9, K20,K21,K22) -> 0.075 | M19: Prepaid Expenses % Revenue | Q19: =CHOOSE(Cover!$F$9, Q20,Q21,Q22) -> 0.012 | R19: =CHOOSE(Cover!$F$9, R20,R21,R22) -> 0.012 | S19: =CHOOSE(Cover!$F$9, S20,S21,S22) -> 0.012 | T19: =CHOOSE(Cover!$F$9, T20,T21,T22) -> 0.012 | U19: =CHOOSE(Cover!$F$9, U20,U21,U22) -> 0.012 | V19: =CHOOSE(Cover!$F$9, V20,V21,V22) -> 0.012
B20: Upside | F20: 0.08 | G20: 0.08 | H20: 0.075 | I20: 0.075 | J20: 0.07 | K20: 0.07 | M20: Upside | Q20: 0.013 | R20: 0.013 | S20: 0.013 | T20: 0.013 | U20: 0.013 | V20: 0.013
B21: Base | F21: 0.085 | G21: 0.085 | H21: 0.08 | I21: 0.08 | J21: 0.075 | K21: 0.075 | M21: Base | Q21: 0.012 | R21: 0.012 | S21: 0.012 | T21: 0.012 | U21: 0.012 | V21: 0.012
B22: Downside | F22: 0.09 | G22: 0.09 | H22: 0.085 | I22: 0.085 | J22: 0.08 | K22: 0.08 | M22: Downside | Q22: 0.011 | R22: 0.011 | S22: 0.011 | T22: 0.011 | U22: 0.011 | V22: 0.011
B24: Other Operating Expenses % Revenue | F24: =CHOOSE(Cover!$F$9, F25,F26,F27) -> 0.01 | G24: =CHOOSE(Cover!$F$9, G25,G26,G27) -> 0.01 | H24: =CHOOSE(Cover!$F$9, H25,H26,H27) -> 0.008 | I24: =CHOOSE(Cover!$F$9, I25,I26,I27) -> 0.008 | J24: =CHOOSE(Cover!$F$9, J25,J26,J27) -> 0.007 | K24: =CHOOSE(Cover!$F$9, K25,K26,K27) -> 0.007 | M24: Other Current Assets % Revenue | Q24: =CHOOSE(Cover!$F$9, Q25,Q26,Q27) -> 0.003 | R24: =CHOOSE(Cover!$F$9, R25,R26,R27) -> 0.003 | S24: =CHOOSE(Cover!$F$9, S25,S26,S27) -> 0.003 | T24: =CHOOSE(Cover!$F$9, T25,T26,T27) -> 0.003 | U24: =CHOOSE(Cover!$F$9, U25,U26,U27) -> 0.003 | V24: =CHOOSE(Cover!$F$9, V25,V26,V27) -> 0.003
B25: Upside | F25: 0.008 | G25: 0.008 | H25: 0.006 | I25: 0.006 | J25: 0.005 | K25: 0.005 | M25: Upside | Q25: 0.004 | R25: 0.004 | S25: 0.004 | T25: 0.004 | U25: 0.004 | V25: 0.004
B26: Base | F26: 0.01 | G26: 0.01 | H26: 0.008 | I26: 0.008 | J26: 0.007 | K26: 0.007 | M26: Base | Q26: 0.003 | R26: 0.003 | S26: 0.003 | T26: 0.003 | U26: 0.003 | V26: 0.003
B27: Downside | F27: 0.012 | G27: 0.012 | H27: 0.01 | I27: 0.01 | J27: 0.009 | K27: 0.009 | M27: Downside | Q27: 0.002 | R27: 0.002 | S27: 0.002 | T27: 0.002 | U27: 0.002 | V27: 0.002
M29: DPO | Q29: =CHOOSE(Cover!$F$9, Q30,Q31,Q32) -> 22 | R29: =CHOOSE(Cover!$F$9, R30,R31,R32) -> 22 | S29: =CHOOSE(Cover!$F$9, S30,S31,S32) -> 23 | T29: =CHOOSE(Cover!$F$9, T30,T31,T32) -> 23 | U29: =CHOOSE(Cover!$F$9, U30,U31,U32) -> 24 | V29: =CHOOSE(Cover!$F$9, V30,V31,V32) -> 24
M30: Upside | Q30: 23 | R30: 23 | S30: 24 | T30: 24 | U30: 25 | V30: 25 | W30: *Much stronger flexibility with payables
M31: Base | Q31: 22 | R31: 22 | S31: 23 | T31: 23 | U31: 24 | V31: 24 | W31: *Slightly more flexibilty with payables
M32: Downside | Q32: 21 | R32: 21 | S32: 21 | T32: 22 | U32: 22 | V32: 22 | W32: *No growth with payable flexbility
M34: Other Current Liabilities % Revenue | Q34: =CHOOSE(Cover!$F$9, Q35,Q36,Q37) -> 0.093 | R34: =CHOOSE(Cover!$F$9, R35,R36,R37) -> 0.093 | S34: =CHOOSE(Cover!$F$9, S35,S36,S37) -> 0.09 | T34: =CHOOSE(Cover!$F$9, T35,T36,T37) -> 0.09 | U34: =CHOOSE(Cover!$F$9, U35,U36,U37) -> 0.09 | V34: =CHOOSE(Cover!$F$9, V35,V36,V37) -> 0.09
M35: Upside | Q35: 0.095 | R35: 0.095 | S35: 0.093 | T35: 0.093 | U35: 0.093 | V35: 0.093
M36: Base | Q36: 0.093 | R36: 0.093 | S36: 0.09 | T36: 0.09 | U36: 0.09 | V36: 0.09
M37: Downside | Q37: 0.09 | R37: 0.09 | S37: 0.087 | T37: 0.087 | U37: 0.087 | V37: 0.087
B38: Cash Flow from Investing
B40: CapEx % Revenue | F40: =CHOOSE(Cover!$F$9, F41,F42,F43) -> 0.12 | G40: =CHOOSE(Cover!$F$9, G41,G42,G43) -> 0.1 | H40: =CHOOSE(Cover!$F$9, H41,H42,H43) -> 0.08 | I40: =CHOOSE(Cover!$F$9, I41,I42,I43) -> 0.08 | J40: =CHOOSE(Cover!$F$9, J41,J42,J43) -> 0.08 | K40: =CHOOSE(Cover!$F$9, K41,K42,K43) -> 0.08
B41: Upside | F41: 0.13 | G41: 0.13 | H41: 0.09 | I41: 0.09 | J41: 0.09 | K41: 0.09 | L41: *Slightly stronger growth strategy
B42: Base | F42: 0.12 | G42: 0.1 | H42: 0.08 | I42: 0.08 | J42: 0.08 | K42: 0.08 | L42: *Strong Initial investment, followed by sustained growth investing
B43: Downside | F43: 0.11 | G43: 0.11 | H43: 0.07 | I43: 0.07 | J43: 0.07 | K43: 0.07 | L43: *Slightly lower than expected CapEx investment
B45: Net Assets From Acquisition % Revenue | F45: =CHOOSE(Cover!$F$9, F46,F47,F48) -> 0.001 | G45: =CHOOSE(Cover!$F$9, G46,G47,G48) -> 0.001 | H45: =CHOOSE(Cover!$F$9, H46,H47,H48) -> 0.001 | I45: =CHOOSE(Cover!$F$9, I46,I47,I48) -> 0.0015 | J45: =CHOOSE(Cover!$F$9, J46,J47,J48) -> 0.0015 | K45: =CHOOSE(Cover!$F$9, K46,K47,K48) -> 0.0015
B46: Upside | F46: 0.0005 | G46: 0.0005 | H46: 0.0005 | I46: 0.0005 | J46: 0.0005 | K46: 0.0005
B47: Base | F47: 0.001 | G47: 0.001 | H47: 0.001 | I47: 0.0015 | J47: 0.0015 | K47: 0.0015
B48: Downside | F48: 0.0015 | G48: 0.0015 | H48: 0.0015 | I48: 0.002 | J48: 0.002 | K48: 0.002

Sheet Comps
B2: Luckin Coffee Inc (OTCMKTS: LKNCY)
B3: Comparable Companies Analysis
B4: In Millions of $USD (except share price)
D7: Current | E7: % of | N7: LTM | O7: Total | Q7: Total
D8: Share | E8: 52-wk. | F8: Equity | G8: Enterprise | I8: LTM | K8: LTM | N8: EBIT | O8: Debt/ | Q8: Debt/ | R8: Unlevered
B9: Company | C9: Ticker | D9: Price | E9: High | F9: Value (M) | G9: Value (M) | I9: EV / Sales | K9: EV / EBITDA | N9: Margin | O9: EBIT | P9: Beta | Q9: Equity | R9: Beta
B11: Luckin Coffee | C11: OTCMKTS: LKNCY | D11: 33.72 | E11: 0.77268561 | F11: 9551 | G11: 8376 | I11: 0.94 | K11: 10.16 | N11: 0.115 | O11: 1.31 | P11: ='Factset Custom Comps'!P4 -> 0.349212 | Q11: ='Factset Custom Comps'!L4/100 -> 0.2682189 | R11: =P11/(1+((1-0.28)*Q11)) -> 0.29268867
B13: Tier I: Largest
B14: Starbucks | C14: NASDAQ: SBUX | D14: 92.7 | E14: =92.7 / 104.82 -> 0.88437321 | F14: 105610 | G14: 118644 | I14: 3.02 | K14: 24.97 | N14: 0.089 | O14: 7.64 | P14: ='Factset Custom Comps'!P5 -> 1.163099 | Q14: -
B15: Yum! Brands Inc. | C15: NYSE: YUM | D15: 159.16 | E15: =D15 / 169.39 -> 0.93960682 | F15: 44000 | G15: 55545 | I15: 6.02 | K15: 20.14 | N15: 0.309 | O15: 5.2 | P15: ='Factset Custom Comps'!P6 -> 0.439666 | Q15: -
B18: Tier II: Middle
B19: Dutch Bros | C19: NYSE: BROS | D19: 51.33 | E19: =51.33 / 77.88 -> 0.65909091 | F19: 8450 | G19: 9089 | I19: 4.22 | K19: 28.72 | N19: 0.098 | O19: 6.76 | P19: ='Factset Custom Comps'!P7 -> 1.84128 | Q19: ='Factset Custom Comps'!L7/100 -> 1.5403162 | R19: =P19/(1+((1-0.28)*Q19)) -> 0.87304687
B22: Tier III: Smallest
B23: Greggs | C23: OTCMKTS: GGGSF | D23: 20.31 | E23: 0.88611229 | F23: 2068 | G23: 2021 | I23: 0.65 | K23: 6.03 | N23: 0.091 | O23: 2.51 | P23: ='Factset Custom Comps'!P8 -> 0.585564 | Q23: ='Factset Custom Comps'!L8/100 -> 0.6943761 | R23: =P23/(1+((1-0.28)*Q23)) -> 0.39038881
B24: Chagee | C24: NASDAQ: CHA | D24: 10.12 | E24: 0.58320407 | F24: 1879 | G24: 623 | I24: 0.29 | K24: 1.95 | N24: 0.151 | O24: 0.5 | P24: ='Factset Custom Comps'!P9 -> 1.062469 | Q24: ='Factset Custom Comps'!L9/100 -> 0.08095835 | R24: =P24/(1+((1-0.28)*Q24)) -> 1.0039488
B27: Overall
B29: Mean | D29: =AVERAGE(D14:D24) -> 66.724 | E29: =AVERAGE(E14:E24) -> 0.79047746 | F29: =AVERAGE(F14:F24) -> 32401.4 | G29: =AVERAGE(G14:G24) -> 37184.4 | I29: =AVERAGE(I14:I24) -> 2.84 | K29: =AVERAGE(K14:K24) -> 16.362 | N29: =AVERAGE(N14:N24) -> 0.1476 | O29: =AVERAGE(O14:O24) -> 4.522 | P29: =AVERAGE(P14:P24) -> 1.0184156 | Q29: =AVERAGE(Q14:Q24) -> 0.77188355 | R29: =AVERAGE(R14:R24) -> 0.75579483
B30: Median | D30: =MEDIAN(D14:D24) -> 51.33 | E30: =MEDIAN(E14:E24) -> 0.88437321 | F30: =MEDIAN(F14:F24) -> 8450 | G30: =MEDIAN(G14:G24) -> 9089 | I30: =MEDIAN(I14:I24) -> 3.02 | K30: =MEDIAN(K14:K24) -> 20.14 | N30: =MEDIAN(N14:N24) -> 0.098 | O30: =MEDIAN(O14:O24) -> 5.2 | P30: =MEDIAN(P14:P24) -> 1.062469 | Q30: =MEDIAN(Q14:Q24) -> 0.6943761 | R30: =MEDIAN(R14:R24) -> 0.87304687
B32: High | D32: =MAXA(D14:D24) -> 159.16 | E32: =MAXA(E14:E24) -> 0.93960682 | F32: =MAXA(F14:F24) -> 105610 | G32: =MAXA(G14:G24) -> 118644 | I32: =MAXA(I14:I24) -> 6.02 | K32: =MAXA(K14:K24) -> 28.72 | N32: =MAXA(N14:N24) -> 0.309 | O32: =MAXA(O14:O24) -> 7.64 | P32: =MAXA(P14:P24) -> 1.84128 | Q32: =MAXA(Q14:Q24) -> 1.5403162 | R32: =MAXA(R14:R24) -> 1.0039488
B33: Q3 | D33: =_xlfn.QUARTILE.INC(D14:D24, 3) -> 92.7 | E33: =_xlfn.QUARTILE.INC(E14:E24, 3) -> 0.88611229 | F33: =_xlfn.QUARTILE.INC(F14:F24, 3) -> 44000 | G33: =_xlfn.QUARTILE.INC(G14:G24, 3) -> 55545 | I33: =_xlfn.QUARTILE.INC(I14:I24, 3) -> 4.22 | K33: =_xlfn.QUARTILE.INC(K14:K24, 3) -> 24.97 | N33: =_xlfn.QUARTILE.INC(N14:N24, 3) -> 0.151 | O33: =_xlfn.QUARTILE.INC(O14:O24, 3) -> 6.76 | P33: =_xlfn.QUARTILE.INC(P14:P24, 3) -> 1.163099 | Q33: =_xlfn.QUARTILE.INC(Q14:Q24, 3) -> 1.1173462 | R33: =_xlfn.QUARTILE.INC(R14:R24, 3) -> 0.93849784
B34: Q1 | D34: =_xlfn.QUARTILE.INC(D14:D24, 1) -> 20.31 | E34: =_xlfn.QUARTILE.INC(E14:E24, 1) -> 0.65909091 | F34: =_xlfn.QUARTILE.INC(F14:F24, 1) -> 2068 | G34: =_xlfn.QUARTILE.INC(G14:G24, 1) -> 2021 | I34: =_xlfn.QUARTILE.INC(I14:I24, 1) -> 0.65 | K34: =_xlfn.QUARTILE.INC(K14:K24, 1) -> 6.03 | N34: =_xlfn.QUARTILE.INC(N14:N24, 1) -> 0.091 | O34: =_xlfn.QUARTILE.INC(O14:O24, 1) -> 2.51 | P34: =_xlfn.QUARTILE.INC(P14:P24, 1) -> 0.585564 | Q34: =_xlfn.QUARTILE.INC(Q14:Q24, 1) -> 0.38766723 | R34: =_xlfn.QUARTILE.INC(R14:R24, 1) -> 0.63171784
B35: Low | D35: =MINA(D14:D24) -> 10.12 | E35: =MINA(E14:E24) -> 0.58320407 | F35: =MINA(F14:F24) -> 1879 | G35: =MINA(G14:G24) -> 623 | I35: =MINA(I14:I24) -> 0.29 | K35: =MINA(K14:K24) -> 1.95 | N35: =MINA(N14:N24) -> 0.089 | O35: =MINA(O14:O24) -> 0.5 | P35: =MINA(P14:P24) -> 0.439666 | Q35: =MINA(Q14:Q24) -> 0 | R35: =MINA(R14:R24) -> 0.39038881

Sheet Precedents
B2: Luckin Coffee Inc (OTCMKTS: LKNCY)
B3: Precedent Transactions Analysis
B4: In Millions of $USD (except share price)
B6: Company | C6: Acquirer | D6: Year | E6: Deal Type | F6: Transaction Value($M) | G6: EV/EBITDA
B7: KFC Japan | C7: Carlyle Group | D7: 2024 | E7: Strategic | F7: 1159 | G7: 12.9x
B8: Costa Coffee | C8: Coca-Cola | D8: 2018 | E8: Strategic | F8: 5100 | G8: 16.4
B9: Starbucks China | C9: Boyu Capital | D9: 2025 | E9: Controlling Stake | F9: 4000 | G9: 7.6x
B10: McDonald's China | C10: CITIC Capital | D10: 2017 | E10: Strategic | F10: 2100 | G10: 10.2 | H10: *Calculated multiple off of publicized data on transaction
E13: Mean | F13: =AVERAGE(F7:F11) -> 3089.75 | G13: =AVERAGE(G7:G11) -> 13.3
E14: Median | F14: =MEDIAN(F7:F11) -> 3050 | G14: =MEDIAN(G7:G11) -> 13.3

Sheet Support >>

Sheet IS
A1: Luckin Coffee, Inc. Sponsored ADR Class A
A2: LKNCY 54951L109 BK57TY2 US OTC Common stock
A3: Source: FactSet Fundamentals
B4: DEC '18 | C4: DEC '19 | D4: DEC '20 | E4: DEC '21 | F4: DEC '22 | G4: DEC '23 | H4: DEC '24 | I4: DEC '25
A5: GAAP/IFRS Income Statement
A6: Sales | B6: 127.05056 | C6: 437.771 | D6: 584.3641 | E6: 1235.0567 | F6: 1974.0937 | G6: 3514.8999 | H6: 4790.2859 | I6: 6856.5697
A7: Cost of Goods Sold (COGS) incl. D&A | B7: 96.555218 | C7: 294.53688 | D7: 359.13023 | E7: 568.10861 | F7: 827.31447 | G7: 1622.6884 | H7: 2126.6811 | I7: 2829.6561
A8: COGS excluding D&A | B8: 80.431625 | C8: 234.92882 | D8: 289.09189 | E8: 391.61136 | F8: 642.19583 | G8: 1339.8695 | H8: 1637.3043 | I8: 2613.0053
A9: Depreciation & Amortization Expense | B9: 16.123593 | C9: 59.608056 | D9: 70.038335 | E9: 176.49725 | F9: 185.11864 | G9: 282.8189 | H9: 489.37686 | I9: 216.6508
A10: Depreciation | B10: 16.123593 | C10: 59.608056 | D10: 70.038335 | E10: 176.49725 | F10: 185.11864 | G10: 282.8189 | H10: 489.37686 | I10: 216.6508
A11: Gross Income | B11: 30.495337 | C11: 143.23413 | D11: 225.23388 | E11: 666.94806 | F11: 1146.7792 | G11: 1892.2114 | H11: 2663.6048 | I11: 4026.9136
A12: SG&A Expense | B12: 257.21581 | C12: 567.44609 | D12: 519.42368 | E12: 692.03226 | F12: 925.62263 | G12: 1452.973 | H12: 2181.8698 | I12: 3307.1678
A13: Research & Development | E13: 39.025278 | F13: 44.757618 | G13: 47.82239 | H13: 68.619914
A14: Other SG&A | B14: 257.21581 | C14: 567.44609 | D14: 519.42368 | E14: 653.00698 | F14: 880.86501 | G14: 1405.1506 | H14: 2113.2499 | I14: 3307.1678
A15: EBIT (Operating Income) | B15: -226.72047 | C15: -424.21196 | D15: -294.18981 | E15: -25.0842 | F15: 221.15656 | G15: 439.23845 | H15: 481.73501 | I15: 719.74576
A16: Nonoperating Income - Net | B16: -12.625485 | C16: 3.085878 | D16: -0.556486 | E16: 29.39037 | F16: 17.858194 | G16: 9.06814 | H16: 12.583475 | I16: 21.879413
A17: Nonoperating Interest Income | B17: 1.347285 | C17: 11.491848 | D17: 19.662184 | E17: 15.85398 | F17: 12.611614 | G17: 15.33967 | H17: 12.393673 | I17: 26.240713
A18: Reserves Increase (Decrease) | B18: 0 | C18: 0 | D18: 0 | E18: 0 | F18: 0 | G18: 0 | H18: 12.575003
A19: Other Income (Expense) | B19: -13.97277 | C19: -8.40597 | D19: -20.21867 | E19: 13.53639 | F19: 5.24658 | G19: -6.27153 | H19: -12.3852 | I19: -4.3613
A20: Interest Expense | B20: 2.436296 | C20: 4.577376 | D20: 16.874391 | E20: 5.502873 | F20: 3.487526 | G20: 0 | H20: 0.545241 | I20: 0.017389
A21: Gross Interest Expense | B21: 2.436296 | C21: 4.577376 | D21: 16.874391 | E21: 5.502873 | F21: 3.487526 | G21: 0 | H21: 0.545241 | I21: 0.017389
A22: Unusual Expense - Net | B22: 2.913097 | C22: 31.487059 | D22: 592.54899 | E22: -97.720575 | F22: 68.197581 | G22: 9.725578 | H22: -19.544472 | I22: 7.071624
A23: Impairments | C23: 30.282692 | D23: 175.51809 | E23: 3.313198 | F23: 32.940217 | G23: 0.738035 | H23: 1.240131 | I23: 1.181757
A24: Property,Plant & Equipment | C24: 30.282692 | D24: 10.354183 | E24: 3.313198 | F24: 32.940217 | G24: 0.738035 | H24: 1.240131 | I24: 1.181757
A25: Financial Fixed Assets | D25: 165.16391 | E25: 0 | F25: 0
A26: Restructuring Expense | B26: 0 | C26: 0 | D26: 0 | E26: 0 | F26: 0 | G26: 0 | H26: 0 | I26: 0.975593
A27: Legal Claim Expense | D27: 417.0309 | E27: -101.03377 | F27: 52.745187 | G27: 8.987543 | H27: -20.784604 | I27: 4.914274
A28: Unrealized Valuation Gain/Loss | B28: -2.913097 | C28: -1.204367 | D28: 0 | E28: 0 | F28: -0.94762 | G28: 0 | H28: 0
