Workbook
Name __FDS_HYPERLINK_TOGGLE_STATE__: "ON"
Name __FDS_UNIQUE_RANGE_ID_GENERATOR_COUNTER: 5
Name __IntlFixup: TRUE
Name __q3: '[1]1601 Detail information'!$H$97:$H$129
Name _bdm.0052b2d879b443fb8b5b7f9b7e1d1cd2.edm: '[2]Precedent Transactions'!$1:$1048576
Name _bdm.006A679C67724FC79389DC4D22927E9A.edm: [3]Output!$A:$IV
Name _bdm.00a08cb028504395b46a809724d12a5d.edm: '[2]Football Field'!$1:$1048576
Name _bdm.00c6e94a41b24656b09a54c8f0719816.edm: '[4]Strat. Alt.'!$1:$1048576
Name _bdm.015D17FCDC584596B596D0D9D9E42423.edm: [3]Output!$A:$IV
Name _bdm.0260b451a590464bb4192c2c003e5ff7.edm: [4]DCF!$1:$1048576
Name _bdm.02cf64abf374488fa51fc1ec41a32c4e.edm: '[4]M&A Comps'!$1:$1048576
Name _bdm.02fca72f590d4af7b3e2c2954abe00c8.edm: [5]FF!$1:$1048576
Name _bdm.037EABD3E1C143E0A4C9EFAB96C2176C.edm: '[6]ghdx_gxdx output NEW'!$A:$IV
Name _bdm.03882b6fb0ef474bba0ef95ad063bcc3.edm: '[4]Football Field'!$1:$1048576
Name _bdm.03c17d6584414e4196fd5fce20d5c9ae.edm: '[2]Precedent Transactions'!$1:$1048576
Name _bdm.04b02edf28d94ee8b930259f38694521.edm: '[4]Strat. Alt.'!$1:$1048576
Name _bdm.04b7c7d82827448f95077a89ad31c896.edm: '[4]MP Charts 3.0'!$1:$1048576
Name _bdm.04d904f4c97e4d7296658df009e83741.edm: '[7]Fin Profile'!$1:$1048576
Name _bdm.0519f2ffd92b4534bd66ba989a17ab75.edm: '[7]LBO Summary'!$1:$1048576
Name _bdm.055852185cfd4528ade49f8915ecc655.edm: [5]FF!$1:$1048576
Name _bdm.05960a26cde14c82936a636b600ec85b.edm: '[7]LBO Summary'!$1:$1048576
Name _bdm.06000a289da64609969ecdd055070953.edm: '[4]Strat. Alt.'!$1:$1048576
Name _bdm.060F2793D9E2423998467AD3EC73BB2C.edm: [8]Output!$A:$IV
Name _bdm.06b66d61a14c4d479731f0e3143c6d48.edm: '[4]M&A Comps'!$1:$1048576
Name _bdm.0761830ae81b49f58448fda978756af4.edm: '[7]LBO Summary'!$1:$1048576
Name _bdm.07ba5318194a4b26b4697fe251d98fa8.edm: '[4]M&A Comps'!$1:$1048576
Name _bdm.0845d45cfd504654aa9ed88eac98d1e3.edm: '[4]Summary P.L'!$1:$1048576
Name _bdm.085e7abc2f75496fb1e071b3e4a5e59e.edm: '[4]Comps.2'!$1:$1048576
Name _bdm.08b6390c3de54834803333bfc8711f1e.edm: [4]AVP!$1:$1048576
Name _bdm.08C1D7BE819C4781A74CF6318805C5E2.edm: '[9]Spec. Pharma M&A Precedents'!$A:$IV
Name _bdm.0921c0170a6144df873c830ceeb4c7f4.edm: [4]Charts!$1:$1048576
Name _bdm.092f2dd0c7ce49d5a3bd0cf81be33132.edm: [5]DCF_2015!$1:$1048576
Name _bdm.098D708957BC4D3F8BBF2C8937342EBA.edm: [3]Output!$A:$IV
Name _bdm.09d586f35a89421eaf61944923137dc2.edm: '[4]M&A Comps'!$1:$1048576
Name _bdm.0A2E67B530F240BBBBDC3B4DC5001469.edm: [3]Output!$A:$IV
Name _bdm.0A9A50A4D9834205863153CF17E3B531.edm: [10]Charts!$A:$IV
Name _bdm.0AC2A1A0F3DD4A8BA18D8B4DA9E7CA5B.edm: [8]GXDX_IPO!$A:$IV
Name _bdm.0adb85cc32c04880bda5c8e99564a438.edm: '[7]Fin Profile'!$1:$1048576
Name _bdm.0b13a4d3931044539d21ac8f0fcd4444.edm: [4]DCF!$1:$1048576
Name _bdm.0b3c4a7be18446b2a153c2d1c8dd5c6e.edm: '[7]LBO Summary'!$1:$1048576
Name _bdm.0b7059d39d334c30959e118c5f0bf441.edm: '[7]LBO Summary'!$1:$1048576
Name _bdm.0bc7c6ddbe0f44efba274db558b3aec4.edm: '[7]LBO Summary'!$1:$1048576
Name _bdm.0bfb419883cb4b36826dab2bfdf29fd7.edm: [4]DCF!$1:$1048576
Name _bdm.0C60A6498314461E91091A5BC4B2CC02.edm: '[6]ghdx_gxdx output NEW'!$A:$IV
Name _bdm.0d13198c568342d1bfddc65de125a842.edm: '[4]M&A Comps'!$1:$1048576
Name _bdm.0d3c0384f46845d49626641f4044ba2d.edm: [7]IS!$1:$1048576
Name _bdm.0da3f46c7de146b598f9c074ef7cfc33.edm: [5]FF!$1:$1048576
Name _bdm.0eb9bfa0140945f1bbb693e439a697a9.edm: [4]DCF!$1:$1048576
Name _bdm.0ed65bae934742c59e0407895da36f8b.edm: [5]FF!$1:$1048576
Name _bdm.0f17cba32be64ef29b27fc1162234c18.edm: '[4]Strat. Alt.'!$1:$1048576
Name _bdm.0f4ea587d40948f59c1bc31c3573b963.edm: [2]AVP!$1:$1048576
Name _bdm.0FE355E66A5E41AC8F880A3AA51226B8.edm: '[9]SP Comps'!$A:$IV
Name _bdm.0fe9c490c9134e2ba6a6e35f5ed6aa57.edm: '[7]LBO Summary'!$1:$1048576
Name _bdm.1036a40be0a24a779dd008958eaac621.edm: '[4]MP Charts 3.0'!$1:$1048576
Name _bdm.1080a96a06e340e1a3cd6799139b7ac5.edm: '[7]LBO Summary'!$1:$1048576
Name _bdm.10A1BA92E6AF42689069FA0C225AE53E.edm: [10]Charts!$A:$IV
Name _bdm.115087044f204ca8ac825c0da8260cd6.edm: '[7]LBO Summary'!$1:$1048576
Name _bdm.12fbfc733a914c22a3982519f6484a19.edm: [5]FF!$1:$1048576
Name _bdm.132db457ce734dd0a95cac7dbcbb5842.edm: '[4]M&A Comps'!$1:$1048576
Name _bdm.13AC5C95A4324304BFB4E0F0B43DBAA6.edm: [10]Charts!$IV$1

Sheet Cover
C5: Buy: | D5: NYSE: TDG
C7: By: | D7: Tej Prattipati, Mary Tybon
C9: Operating Scenario: | F9: 2
C10: 1 = Bull | D10: 2 = Base | E10: 3 = Bear

Sheet LBO Model
B2: TransDigm Group (NYSE: TDG)
B3: Revenue Build
B4: In Millions of $USD (except share price)
B6: Sources: Factset Fundamentals, TDG 20-F Filings
B8: Control | L8: Uses Calculation
B10: Base Assumptions | L10: Equity Purchase Price
B12: Base Year | D12: 2026 | L12: FD Shares (M) | O12: =DCF!D12 -> 56.5
B13: Exit Multiple | D13: =DCF!D14 -> 22.253 | E13: *IPO Exit discounts multiple based on precedent transactions | L13: Current PPS | O13: =DCF!D11 -> 1167
B14: Tax Rate (%) | D14: 0.215 | E14: *Current effective tax rate | L14: Offer Premium | O14: 0.15
L15: Offer PPS | O15: =O13*(1+O14) -> 1342.05
B16: Debt Assumptions | L16: Equity Offer Price | O16: =O12*O15 -> 75825.825
B18: Debt | D18: Multiple | E18: Interest Rate | L18: Other Uses
B19: Revolver | D19: 0 | E19: 0.03 | F19: Reflect rates from the company's current stack
B20: First Lien Term Loan | D20: 4.75 | E20: 0.065 | L20: Cash | O20: =BS!B6 -> 2808
B21: Second Lien Term Loan | D21: 1 | E21: 0.075 | F21: *Analogous to first lien rate, simply a lot more risk from capital structure placement due to high Debt/EBITDA ratio, etc. | L21: Debt | O21: =-(BS!B49+BS!B40) -> -30081
B22: High Yield Bonds | D22: 1.5 | E22: 0.075 | L22: Refinance Net Debt | O22: =O20+O21 -> -27273
B23: Total Debt/EBITDA | D23: =SUM(D19:D22) -> 7.25 | F23: *Based off historic comps
B25: Sources & Uses | L25: Operating Model Output | O25: FY 26 | P25: FY 27 | Q25: FY 28 | R25: FY 29 | S25: FY 30 | T25: FY 31
B27: Sources | E27: Multiple | F27: % of Total | H27: Uses
B28: Revolver | D28: =E28*$O$30 -> 0 | E28: =D19 -> 0 | F28: =D28/$D$33 -> 0 | H28: Purchase Equity | J28: =O16 -> 75825.825 | L28: Revenue | O28: ='Operating Model'!I46 -> 10185.355 | P28: ='Operating Model'!J46 -> 11700.132 | Q28: ='Operating Model'!K46 -> 12941.881 | R28: ='Operating Model'!L46 -> 14680.709 | S28: ='Operating Model'!M46 -> 16567.708 | T28: ='Operating Model'!N46 -> 18729.366
B29: First Lien Term Loan | D29: =E29*$O$30 -> 27194.804 | E29: =D20 -> 4.75 | F29: =D29/$D$33 -> 0.25995044 | H29: Refinance Net Debt | J29: =-O22 -> 27273 | L29: EBIT | O29: ='Operating Model'!I28 -> 5118.8077 | P29: ='Operating Model'!J28 -> 5829.0058 | Q29: ='Operating Model'!K28 -> 6551.1801 | R29: ='Operating Model'!L28 -> 7551.7569 | S29: ='Operating Model'!M28 -> 8661.5976 | T29: ='Operating Model'!N28 -> 9935.9284
B30: Second Lien Term Loan | D30: =E30*$O$30 -> 5725.2219 | E30: =D21 -> 1 | F30: =D30/$D$33 -> 0.054726408 | H30: Transaction Fees | J30: =J28*0.02 -> 1516.5165 | L30: Adjusted EBITDA | O30: ='Operating Model'!I41 -> 5725.2219 | P30: ='Operating Model'!J41 -> 6499.9911 | Q30: ='Operating Model'!K41 -> 7269.424 | R30: ='Operating Model'!L41 -> 8335.4849 | S30: ='Operating Model'!M41 -> 9514.8584 | T30: ='Operating Model'!N41 -> 10867.356
B31: High Yield Bonds | D31: =E31*$O$30 -> 8587.8329 | E31: =D22 -> 1.5 | F31: =D31/$D$33 -> 0.082089613 | L31: UFCF | O31: =DCF!F29 -> 3574.387 | P31: =DCF!G29 -> 3783.0059 | Q31: =DCF!H29 -> 4499.4913 | R31: =DCF!I29 -> 5133.157 | S31: =DCF!J29 -> 6014.6797 | T31: =DCF!K29 -> 6909.3776
B32: Sponsor Equity | D32: =D33-SUM(D28:D31) -> 63107.483 | F32: =D32/$D$33 -> 0.60323354 | L32: Tax Accounted Interest Payment | O32: =(E45*$D$44 + E51*$D$50 + E57*$D$56)*(1-$D$14) -> 2230.296 | P32: =(F45*$D$44 + F51*$D$50 + F57*$D$56)*(1-$D$14) -> 2161.7137 | Q32: =(G45*$D$44 + G51*$D$50 + G57*$D$56)*(1-$D$14) -> 2078.9873 | R32: =(H45*$D$44 + H51*$D$50 + H57*$D$56)*(1-$D$14) -> 1955.4811 | S32: =(I45*$D$44 + I51*$D$50 + I57*$D$56)*(1-$D$14) -> 1793.3402 | T32: =(J45*$D$44 + J51*$D$50 + J57*$D$56)*(1-$D$14) -> 1577.9463
B33: Total | D33: =J33 -> 104615.34 | H33: Total | J33: =SUM(J28:J30) -> 104615.34 | L33: FCF | O33: =O31-O32 -> 1344.091 | P33: =P31-P32 -> 1621.2922 | Q33: =Q31-Q32 -> 2420.504 | R33: =R31-R32 -> 3177.676 | S33: =S31-S32 -> 4221.3395 | T33: =T31-T32 -> 5331.4313
B35: Debt Schedule | D35: Interest Rate | E35: FY 26 | F35: FY 27 | G35: FY 28 | H35: FY 29 | I35: FY 30 | J35: FY 31 | L35: Returns Analysis
B37: Revolver | D37: =E19 -> 0.03 | L37: Terminal EBITDA | O37: =T30 -> 10867.356 | Q37: Terminal EBITDA | T37: =T30 -> 10867.356
B38: Beginning Balance | E38: =D28 -> 0 | F38: =E40 -> 0 | G38: =F40 -> 0 | H38: =G40 -> 0 | I38: =H40 -> 0 | J38: =I40 -> 0 | L38: Exit Multiple | O38: =D13 -> 22.253 | Q38: Exit Multiple | T38: =D13 -> 22.253
B39: Paydown | F39: =-MIN(E40,O33) -> 0 | G39: =-MIN(F40,P33) -> 0 | H39: =-MIN(G40,Q33) -> 0 | I39: =-MIN(H40,R33) -> 0 | J39: =-MIN(I40,S33) -> 0 | L39: Enterprise Value | O39: =O37*O38 -> 241831.28 | Q39: Enterprise Value | T39: =T37*T38 -> 241831.28
B40: Ending Balance | E40: =SUM(E38:E39) -> 0 | F40: =SUM(F38:F39) -> 0 | G40: =SUM(G38:G39) -> 0 | H40: =SUM(H38:H39) -> 0 | I40: =SUM(I38:I39) -> 0 | J40: =SUM(J38:J39) -> 0 | L40: (-) Net Debt | O40: =J62 -> 23391.525 | Q40: (-) Net Debt | T40: =J62 -> 23391.525
B41: General Interest Expense | F41: =AVERAGE(E40:F40)*$D$37 -> 0 | G41: =AVERAGE(F40:G40)*$D$37 -> 0 | H41: =AVERAGE(G40:H40)*$D$37 -> 0 | I41: =AVERAGE(H40:I40)*$D$37 -> 0 | J41: =AVERAGE(I40:J40)*$D$37 -> 0 | L41: Equity Value at Exit | O41: =O39-O40 -> 218439.76 | Q41: Equity Value | T41: =T39-T40 -> 218439.76
B42: Reserve Interest Expense | D42: 0.0025 | F42: 0 | G42: 0 | H42: 0 | I42: 0 | J42: 0 | L42: Sponsor Ownership at Exit | O42: 1 | Q42: Sponsor Ownership at Exit | T42: 1
L43: Sponsor Equity at Exit | O43: =O41*O42 -> 218439.76 | Q43: Sponsor Equity at Closing | T43: =D32 -> 63107.483
B44: First Lien Term Loan | D44: =E20 -> 0.065 | L44: Sponsor Equity at Closing | O44: =D32 -> 63107.483 | Q44: Net Debt at Closing | T44: =SUM(D29:D31) -> 41507.859
B45: Beginning Balance | E45: =D29 -> 27194.804 | F45: =E47 -> 25850.713 | G45: =F47 -> 24229.421 | H45: =G47 -> 21808.917 | I45: =H47 -> 18631.241 | J45: =I47 -> 14409.901 | L45: MOIC | O45: =O43/O44 -> 3.4613923 | Q45: Implied TEV at Closing | T45: =T43 + T44 - T47 -> 103098.82
B46: Paydown | E46: =MIN(E45, O33) -> 1344.091 | F46: =MIN(F45,P33+F39) -> 1621.2922 | G46: =MIN(G45,Q33+G39) -> 2420.504 | H46: =MIN(H45,R33+H39) -> 3177.676 | I46: =MIN(I45,S33+I39) -> 4221.3395 | J46: =MIN(J45,T33+J39) -> 5331.4313 | L46: IRR | O46: =O45^(1/6)-1 -> 0.22991511 | Q46: (-) Old Net Debt | T46: =O22 -> -27273
B47: Ending Balance | E47: =E45- E46 -> 25850.713 | F47: =F45- F46 -> 24229.421 | G47: =G45- G46 -> 21808.917 | H47: =H45- H46 -> 18631.241 | I47: =I45- I46 -> 14409.901 | J47: =J45- J46 -> 9078.4702 | Q47: (-) Transaction Fees | T47: =J30 -> 1516.5165
B48: Interest Expense | E48: =E47 * D44 -> 1680.2963 | F48: =AVERAGE(E47:F47)*$D$44 -> 1627.6044 | G48: =AVERAGE(F47:G47)*$D$44 -> 1496.246 | H48: =AVERAGE(G47:H47)*$D$44 -> 1314.3051 | I48: =AVERAGE(H47:I47)*$D$44 -> 1073.8371 | J48: =AVERAGE(I47:J47)*$D$44 -> 763.37208
Q49: Equity Purchase Price | T49: =T45 + T46 -> 75825.825
B50: Second Lien Term Loan | D50: =E21 -> 0.075 | Q50: FD Shares | T50: =O12 -> 56.5
...

Sheet DCF
B2: TransDigm Group (NYSE: TDG)
B3: DCF Valuation
B4: In Millions of $USD (except share price)
B6: Sources: Factset Fundamentals, TransDigm 20-F, 10-K, 10-Q Filings
B8: Control
B10: Inputs / Assumptions
B11: Share Price | D11: =Comps!D11 -> 1167
B12: Shares out. (M) | D12: 56.5
B13: Net Debt (M) | D13: 27518
B14: Exit Multiple | D14: =AVERAGE(Precedents!F14, Comps!K29) -> 22.253 | E14: Average of Smaller Precedents transaction EV/EBITDA and Closer Comps current trading EV/EBITDA
B15: WACC (%) | D15: =WACC!D27 -> 0.0848344
B16: Tax Rate (%) | D16: 0.215
B17: PGR Growth Rate (%) | D17: 0.0225
B19: all figures in M unless otherwise stated | F19: FY 26 | G19: FY 27 | H19: FY 28 | I19: FY 29 | J19: FY 30 | K19: FY 31
B21: UFCF Calculation
B23: EBIT | F23: ='Operating Model'!I28 -> 5118.8077 | G23: ='Operating Model'!J28 -> 5829.0058 | H23: ='Operating Model'!K28 -> 6551.1801 | I23: ='Operating Model'!L28 -> 7551.7569 | J23: ='Operating Model'!M28 -> 8661.5976 | K23: ='Operating Model'!N28 -> 9935.9284
B24: (-) Taxes | F24: =F23*$D$16 -> 1100.5437 | G24: =G23*$D$16 -> 1253.2362 | H24: =H23*$D$16 -> 1408.5037 | I24: =I23*$D$16 -> 1623.6277 | J24: =J23*$D$16 -> 1862.2435 | K24: =K23*$D$16 -> 2136.2246
B25: NOPAT | F25: =F23-F24 -> 4018.264 | G25: =G23-G24 -> 4575.7695 | H25: =H23-H24 -> 5142.6764 | I25: =I23-I24 -> 5928.1291 | J25: =J23-J24 -> 6799.3541 | K25: =K23-K24 -> 7799.7038
B26: (+) D&A | F26: ='Operating Model'!I23 -> 407.4142 | G26: ='Operating Model'!J23 -> 468.00528 | H26: ='Operating Model'!K23 -> 511.2043 | I26: ='Operating Model'!L23 -> 572.54766 | J26: ='Operating Model'!M23 -> 637.85675 | K26: ='Operating Model'!N23 -> 711.71589
B27: (-) Δ NWC | F27: ='Operating Model'!I65 -> 107.76032 | G27: ='Operating Model'!J65 -> 418.35942 | H27: ='Operating Model'!K65 -> 287.2834 | I27: ='Operating Model'!L65 -> 398.59293 | J27: ='Operating Model'!M65 -> 411.90104 | K27: ='Operating Model'!N65 -> 478.28018
B28: (-) Cash from Investing | F28: ='Operating Model'!I76*-1 -> 743.53091 | G28: ='Operating Model'!J76*-1 -> 842.40951 | H28: ='Operating Model'!K76*-1 -> 867.10602 | I28: ='Operating Model'!L76*-1 -> 968.92681 | J28: ='Operating Model'!M76*-1 -> 1010.6302 | K28: ='Operating Model'!N76*-1 -> 1123.7619
B29: UFCF | F29: =F25+F26-F27-F28 -> 3574.387 | G29: =G25+G26-G27-G28 -> 3783.0059 | H29: =H25+H26-H27-H28 -> 4499.4913 | I29: =I25+I26-I27-I28 -> 5133.157 | J29: =J25+J26-J27-J28 -> 6014.6797 | K29: =K25+K26-K27-K28 -> 6909.3776
B31: Period | F31: 0.5 | G31: =1+F31 -> 1.5 | H31: =1+G31 -> 2.5 | I31: =1+H31 -> 3.5 | J31: =1+I31 -> 4.5 | K31: =1+J31 -> 5.5
B32: Discount Rate | F32: =$D$15 -> 0.0848344 | G32: =F32 -> 0.0848344 | H32: =$D$15 -> 0.0848344 | I32: =$D$15 -> 0.0848344 | J32: =$D$15 -> 0.0848344 | K32: =$D$15 -> 0.0848344
B33: Discounted FCFs | F33: =F29/(1+F32)^F31 -> 3431.7832 | G33: =G29/(1+G32)^G31 -> 3348.0493 | H33: =H29/(1+H32)^H31 -> 3670.7499 | I33: =I29/(1+I32)^I31 -> 3860.2238 | J33: =J29/(1+J32)^J31 -> 4169.4329 | K33: =K29/(1+K32)^K31 -> 4415.0941
B35: DCF
B37: Exit Multiples Method | G37: Perpetuity Growth Method
B38: PV of FCFFs | E38: =SUM(F33:L33) -> 22895.333 | G38: PV of FCFFs | J38: =SUM(F33:K33) -> 22895.333
B39: Final Year EBITDA | E39: ='Operating Model'!N31 -> 10647.644 | G39: Terminal Value | J39: =K29*(1+D17)/(D15-D17) -> 113337.72
B40: EV/EBITDA Multiple | E40: =D14 -> 22.253 | G40: PV of TV | J40: =J39/(1+$D$15)^$K$31 -> 72422.831
B41: TV in Final Year | E41: =E39*E40 -> 236942.03 | G41: Total Enterprise Value (TEV) | J41: =J38+J40 -> 95318.164
B42: PV of TV | E42: =E41/(1+$D$15)^$K$31 -> 151406.02 | G42: (-) Net Debt | J42: =D13 -> 27518
B43: Total Enterprise Value (TEV) | E43: =E38+E42 -> 174301.35 | G43: Equity Value | J43: =J41-J42 -> 67800.164
B44: (-) Net Debt | E44: =D13 -> 27518 | G44: Shares Oustanding | J44: =D12 -> 56.5
B45: Equity Value | E45: =E43-E44 -> 146783.35 | G45: Implied Share Price | J45: =J43/J44 -> 1200.0029
B46: Shares Oustanding | E46: =D12 -> 56.5 | G46: Current Market Share Price | J46: =$D$11 -> 1167
B47: Implied Share Price | E47: =E45/E46 -> 2597.9354 | G47: Implied Upside | J47: =J45/J46-1 -> 0.02828012
B48: Current Market Share Price | E48: =$D$11 -> 1167 | G48: Implied % Growth | J48: =((1+J47)^(1/5)-1) -> 0.0055931073
B49: Implied Upside | E49: =E47/E48-1 -> 1.2261657
B50: Implied % Growth | E50: =((1+E49)^(1/5)-1) -> 0.17357676
...

Sheet WACC
B2: TransDigm Group (NYSE: TDG)
B3: WACC Calculation
B4: In Millions of $USD (except share price)
B6: Sources: Factset Fundamentals, TransDigm 20-F, 10-K, 10-Q Filings
B8: WACC Calculation | K8: SID Relevered Beta
B9: Target Capital Structure | O9: Target | P9: Target
B10: Debt-to-Total Capitalization | D10: 0.4 | N10: Unlevered | O10: Debt/ | P10: Marginal | Q10: Relevered
B11: Equity-to-Total Capitalization | D11: =1-D10 -> 0.6 | N11: Beta | O11: Equity | P11: Tax Rate | Q11: Beta
K12: Relevered Beta | N12: 0.83 | O12: 0.5 | P12: 0.28 | Q12: =N12*(1+(1-P12)*(O12)) -> 1.1288 | R12: Use Market Cap for Equity Valuye
B13: Cost of Debt
B14: Pre-Tax Cost of Debt | D14: 0.0596 | E14: Implied historical cost of debt (using 2020-2025 financials) | K14: WACC Sensitivity Analysis
B15: Tax Rate | D15: 0.215 | M15: Pre-tax Cost of Debt
B16: After-tax Cost of Debt | D16: =+D14*(1-D15) -> 0.046786 | L16: -- | M16: =D14-0.01 -> 0.0496 | N16: =D14-0.005 -> 0.0546 | O16: =$D$14 -> 0.0596 | P16: =$D$14+0.005 -> 0.0646 | Q16: =$D$14+0.01 -> 0.0696
K17: Debt-to-Total Capitalization | L17: =L18-0.01 -> 0.38 | M17: =($D$24*$D$11)+($L$17*((1-$D$15)*(M16))) -> 0.08091568 | N17: =($D$24*$D$11)+($L$17*((1-$D$15)*(N16))) -> 0.08240718 | O17: =($D$24*$D$11)+($L$17*((1-$D$15)*(O16))) -> 0.08389868 | P17: =($D$24*$D$11)+($L$17*((1-$D$15)*(P16))) -> 0.08539018 | Q17: =($D$24*$D$11)+($L$17*((1-$D$15)*(Q16))) -> 0.08688168
B18: Cost of Equity | L18: =L19-0.01 -> 0.39 | M18: =($D$24*$D$11)+($L$18*((1-$D$15)*(M16))) -> 0.08130504 | N18: =($D$24*$D$11)+($L$18*((1-$D$15)*(N16))) -> 0.08283579 | O18: =($D$24*$D$11)+($L$18*((1-$D$15)*(O16))) -> 0.08436654 | P18: =($D$24*$D$11)+($L$18*((1-$D$15)*(P16))) -> 0.08589729 | Q18: =($D$24*$D$11)+($L$18*((1-$D$15)*(Q16))) -> 0.08742804
B19: Risk-free Rate | D19: 0.0431 | L19: =D10 -> 0.4 | M19: =($D$24*$D$11)+($L$19*((1-$D$15)*(M16))) -> 0.0816944 | N19: =($D$24*$D$11)+($L$19*((1-$D$15)*(N16))) -> 0.0832644 | O19: =($D$24*$D$11)+($L$19*((1-$D$15)*(O16))) -> 0.0848344 | P19: =($D$24*$D$11)+($L$19*((1-$D$15)*(P16))) -> 0.0864044 | Q19: =($D$24*$D$11)+($L$19*((1-$D$15)*(Q16))) -> 0.0879744
B20: Equity Risk Premium | D20: 0.055 | L20: =L19+0.01 -> 0.41 | M20: =($D$24*$D$11)+($L$20*((1-$D$15)*(M16))) -> 0.08208376 | N20: =($D$24*$D$11)+($L$20*((1-$D$15)*(N16))) -> 0.08369301 | O20: =($D$24*$D$11)+($L$20*((1-$D$15)*(O16))) -> 0.08530226 | P20: =($D$24*$D$11)+($L$20*((1-$D$15)*(P16))) -> 0.08691151 | Q20: =($D$24*$D$11)+($L$20*((1-$D$15)*(Q16))) -> 0.08852076
B21: Country Risk Premium | D21: 0 | L21: =L20+0.01 -> 0.42 | M21: =($D$24*$D$11)+($L$21*((1-$D$15)*(M16))) -> 0.08247312 | N21: =($D$24*$D$11)+($L$21*((1-$D$15)*(N16))) -> 0.08412162 | O21: =($D$24*$D$11)+($L$21*((1-$D$15)*(O16))) -> 0.08577012 | P21: =($D$24*$D$11)+($L$21*((1-$D$15)*(P16))) -> 0.08741862 | Q21: =($D$24*$D$11)+($L$21*((1-$D$15)*(Q16))) -> 0.08906712
B22: Levered Beta | D22: 1.22
M23: Levered Beta
B24: Cost of Equity | D24: =D19+(D22*(D21+D20)) -> 0.1102 | L24: =D28 -> 0 | M24: =N24-0.25 -> 0.6288 | N24: =O24-0.25 -> 0.8788 | O24: =Q12 -> 1.1288 | P24: =O24+0.25 -> 1.3788 | Q24: =P24+0.25 -> 1.6288
K25: MRP | L25: =L26-0.0025 -> 0.05 | M25: =($D$10*$D$16)+($D$11*($D$19+($L$25*M24))) -> 0.0634384 | N25: =($D$10*$D$16)+($D$11*($D$19+($L$25*N24))) -> 0.0709384 | O25: =($D$10*$D$16)+($D$11*($D$19+($L$25*O24))) -> 0.0784384 | P25: =($D$10*$D$16)+($D$11*($D$19+($L$25*P24))) -> 0.0859384 | Q25: =($D$10*$D$16)+($D$11*($D$19+($L$25*Q24))) -> 0.0934384
L26: =L27-0.0025 -> 0.0525 | M26: =($D$10*$D$16)+($D$11*($D$19+($L$26*M24))) -> 0.0643816 | N26: =($D$10*$D$16)+($D$11*($D$19+($L$26*N24))) -> 0.0722566 | O26: =($D$10*$D$16)+($D$11*($D$19+($L$26*O24))) -> 0.0801316 | P26: =($D$10*$D$16)+($D$11*($D$19+($L$26*P24))) -> 0.0880066 | Q26: =($D$10*$D$16)+($D$11*($D$19+($L$26*Q24))) -> 0.0958816
B27: WACC | D27: =(D10*D16)+(D11*D24) -> 0.0848344 | L27: =D20 -> 0.055 | M27: =($D$10*$D$16)+($D$11*($D$19+($L$27*M24))) -> 0.0653248 | N27: =($D$10*$D$16)+($D$11*($D$19+($L$27*N24))) -> 0.0735748 | O27: =($D$10*$D$16)+($D$11*($D$19+($L$27*O24))) -> 0.0818248 | P27: =($D$10*$D$16)+($D$11*($D$19+($L$27*P24))) -> 0.0900748 | Q27: =($D$10*$D$16)+($D$11*($D$19+($L$27*Q24))) -> 0.0983248
L28: =L27+0.0025 -> 0.0575 | M28: =($D$10*$D$16)+($D$11*($D$19+($L$28*M24))) -> 0.066268 | N28: =($D$10*$D$16)+($D$11*($D$19+($L$28*N24))) -> 0.074893 | O28: =($D$10*$D$16)+($D$11*($D$19+($L$28*O24))) -> 0.083518 | P28: =($D$10*$D$16)+($D$11*($D$19+($L$28*P24))) -> 0.092143 | Q28: =($D$10*$D$16)+($D$11*($D$19+($L$28*Q24))) -> 0.100768
L29: =L28+0.0025 -> 0.06 | M29: =($D$10*$D$16)+($D$11*($D$19+($L$29*M24))) -> 0.0672112 | N29: =($D$10*$D$16)+($D$11*($D$19+($L$29*N24))) -> 0.0762112 | O29: =($D$10*$D$16)+($D$11*($D$19+($L$29*O24))) -> 0.0852112 | P29: =($D$10*$D$16)+($D$11*($D$19+($L$29*P24))) -> 0.0942112 | Q29: =($D$10*$D$16)+($D$11*($D$19+($L$29*Q24))) -> 0.1032112

Sheet Revenue Build
B2: TransDigm (NYSE: TDG)
B3: Revenue Build
B4: In Millions of $USD (except share price)
B6: Sources: Factset Fundamentals, TDG 20-F Filings, TDG Earnings Calls, TDG Earnings Presentations, TDG 10Qs and 10Ks
B8: all figures in M unless otherwise stated | C8: FY 20 | D8: FY 21 | E8: FY22 | F8: FY23 | G8: FY24 | H8: FY25 | I8: FY 26 | J8: FY 27 | K8: FY 28 | L8: FY 29 | M8: FY 30 | N8: FY 31
B10: Total Revenue Projected
B12: Total Revenue | C12: =SUM(C15,C19,C23,C27,) -> 5103 | D12: =SUM(D15,D19,D23,D27,) -> 4799 | E12: =SUM(E15,E19,E23,E27,) -> 5437 | F12: =SUM(F15,F19,F23,F27,) -> 6585 | G12: =SUM(G15,G19,G23,G27,) -> 7904 | H12: =SUM(H15,H19,H23,H27,) -> 8831 | I12: =SUM(I15,I19,I23,I27,) -> 10185.355 | J12: =SUM(J15,J19,J23,J27,) -> 11700.132 | ... N12: =SUM(N15,N19,N23,N27,) -> 18729.366
B13: % Growth | D13: =(D12-C12)/C12 -> -0.0595728 | E13: =(E12-D12)/D12 -> 0.13294436 | F13: =(F12-E12)/E12 -> 0.21114585 | G13: =(G12-F12)/F12 -> 0.20030372 | H13: =(H12-G12)/G12 -> 0.11728239 | I13: =(I12-H12)/H12 -> 0.15336372 | J13: =(J12-I12)/I12 -> 0.14872108 | K13: =(K12-J12)/J12 -> 0.10613119 | ... N13: =(N12-M12)/M12 -> 0.13047416
B15: Commercial OEM | C15: 1406 | D15: 1151.76 | E15: 1304.88 | F15: 1685 | G15: 2107 | H15: 2106 | I15: =H15*(1+I16) -> 2316.6 | J15: =I15*(1+J16) -> 2501.928 | K15: =J15*(1+K16) -> 2677.063 | L15: =K15*(1+L16) -> 2837.6867 | M15: =L15*(1+M16) -> 2979.5711 | N15: =M15*(1+N16) -> 3128.5496
B16: % Growth | D16: =(D15-C15)/C15 -> -0.18082504 | E16: =(E15-D15)/D15 -> 0.13294436 | F16: =(F15-E15)/E15 -> 0.29130648 | G16: =(G15-F15)/F15 -> 0.2504451 | H16: =(H15-G15)/G15 -> -0.00047460845 | I16: ='Revenue Assumptions'!G9 -> 0.1 | J16: ='Revenue Assumptions'!H9 -> 0.08 | K16: ='Revenue Assumptions'!I9 -> 0.07 | L16: ='Revenue Assumptions'!J9 -> 0.06 | M16: ='Revenue Assumptions'!K9 -> 0.05 | N16: ='Revenue Assumptions'!K9 -> 0.05
B17: % of total revenue | C17: =C15/C$12 -> 0.2755242 | D17: =D15/D$12 -> 0.24 | E17: =E15/E$12 -> 0.24 | F17: =F15/F$12 -> 0.25588459 | G17: =G15/G$12 -> 0.26657389 | H17: =H15/H$12 -> 0.23847809 | I17: =I15/I$12 -> 0.22744421 | J17: =J15/J$12 -> 0.21383759 | ... N17: =N15/N$12 -> 0.16703981
B19: Commercial Aftermarket | C19: 1362 | D19: 1343.72 | E19: 1848.58 | F19: 2186 | G19: 2461 | H19: 2804 | I19: =H19*(1+I20) -> 3364.8 | J19: =I19*(1+J20) -> 4020.936 | K19: =J19*(1+K20) -> 4784.9138 | L19: =K19*(1+L20) -> 5670.1229 | M19: =L19*(1+M20) -> 6662.3944 | N19: =M19*(1+N20) -> 7828.3134
B20: % Growth | D20: =(D19-C19)/C19 -> -0.013421439 | E20: =(E19-D19)/D19 -> 0.37571816 | F20: =(F19-E19)/E19 -> 0.18252929 | G20: =(G19-F19)/F19 -> 0.12580055 | H20: =(H19-G19)/G19 -> 0.13937424 | I20: ='Revenue Assumptions'!G14 -> 0.2 | J20: ='Revenue Assumptions'!H14 -> 0.195 | K20: ='Revenue Assumptions'!I14 -> 0.19 | L20: ='Revenue Assumptions'!J14 -> 0.185 | M20: ='Revenue Assumptions'!K14 -> 0.175 | N20: ='Revenue Assumptions'!K14 -> 0.175
B21: % of total revenue | C21: =C19/C$12 -> 0.26690182 | D21: =D19/D$12 -> 0.28 | E21: =E19/E$12 -> 0.34 | F21: =F19/F$12 -> 0.33196659 | G21: =G19/G$12 -> 0.31136134 | H21: =H19/H$12 -> 0.31751783 | I21: =I19/I$12 -> 0.33035667 | J21: =J19/J$12 -> 0.34366587 | ... N21: =N19/N$12 -> 0.41797003
B23: Defense | C23: 2180 | D23: 2111.56 | E23: 2120.43 | F23: 2562 | G23: 3176 | H23: 3761 | I23: =H23*(1+I24) -> 4343.955 | J23: =I23*(1+J24) -> 5017.268 | K23: =J23*(1+K24) -> 5318.3041 | L23: =K23*(1+L24) -> 6009.6836 | M23: =L23*(1+M24) -> 6760.8941 | N23: =M23*(1+N24) -> 7606.0059
B24: % Growth | D24: =(D23-C23)/C23 -> -0.031394495 | E24: =(E23-D23)/D23 -> 0.0042006857 | F24: =(F23-E23)/E23 -> 0.2082455 | G24: =(G23-F23)/F23 -> 0.23965652 | H24: =(H23-G23)/G23 -> 0.18419395 | I24: ='Revenue Assumptions'!G19 -> 0.155 | J24: ='Revenue Assumptions'!H19 -> 0.155 | K24: ='Revenue Assumptions'!I19 -> 0.06 | L24: ='Revenue Assumptions'!J19 -> 0.13 | M24: ='Revenue Assumptions'!K19 -> 0.125 | N24: ='Revenue Assumptions'!K19 -> 0.125
B25: % of total revenue | C25: =C23/C$12 -> 0.42719969 | D25: =D23/D$12 -> 0.44 | E25: =E23/E$12 -> 0.39 | F25: =F23/F$12 -> 0.38906606 | G25: =G23/G$12 -> 0.40182186 | H25: =H23/H$12 -> 0.42588608 | I25: =I23/I$12 -> 0.42649029 | J25: =J23/J$12 -> 0.42882149 | ... N25: =N23/N$12 -> 0.40610056
B27: Non-Aviation (Other) | C27: 155 | D27: 191.96 | E27: 163.11 | F27: 152 | G27: 160 | H27: 160 | I27: =H27*(1+I28) -> 160 | J27: =I27*(1+J28) -> 160 | K27: =J27*(1+K28) -> 161.6 | L27: =K27*(1+L28) -> 163.216 | M27: =L27*(1+M28) -> 164.84816 | N27: =M27*(1+N28) -> 166.49664
B28: % Growth | D28: =(D27-C27)/C27 -> 0.23845161 | E28: =(E27-D27)/D27 -> -0.15029173 | F28: =(F27-E27)/E27 -> -0.068113543 | G28: =(G27-F27)/F27 -> 0.052631579 | H28: =(H27-G27)/G27 -> 0 | I28: ='Revenue Assumptions'!G24 -> 0 | J28: ='Revenue Assumptions'!H24 -> 0 | K28: ='Revenue Assumptions'!I24 -> 0.01 | L28: ='Revenue Assumptions'!J24 -> 0.01 | M28: ='Revenue Assumptions'!K24 -> 0.01 | N28: ='Revenue Assumptions'!K24 -> 0.01
B29: % of total revenue | C29: =C27/C$12 -> 0.03037429 | D29: =D27/D$12 -> 0.04 | E29: =E27/E$12 -> 0.03 | F29: =F27/F$12 -> 0.023082764 | G29: =G27/G$12 -> 0.020242915 | H29: =H27/H$12 -> 0.018117993 | I29: =I27/I$12 -> 0.015708829 | J29: =J27/J$12 -> 0.013675059 | ... N29: =N27/N$12 -> 0.0088896039

Sheet Revenue Assumptions
B2: TransDigm (NYSE: TDG)
B3: Revenue Build Assumptions
C5: FY 23 (Base, Actual) | D5: FY 24 (Base, Actual) | E5: FY 24 (Base, Actual) | F5: FY 26 | G5: FY 27 | H5: FY 28 | I5: FY 29 | J5: FY 30 | K5: FY 31
B7: Revenue Growth Breakdown
B9: Commercial OEM | F9: =CHOOSE(Cover!$F$9, F10,F11,F12) -> 0.12 | G9: =CHOOSE(Cover!$F$9, G10,G11,G12) -> 0.1 | H9: =CHOOSE(Cover!$F$9, H10,H11,H12) -> 0.08 | I9: =CHOOSE(Cover!$F$9, I10,I11,I12) -> 0.07 | J9: =CHOOSE(Cover!$F$9, J10,J11,J12) -> 0.06 | K9: =CHOOSE(Cover!$F$9, K10,K11,K12) -> 0.05
B10: Upside | F10: 0.15 | G10: 0.13 | H10: 0.11 | I10: 0.09 | J10: 0.08 | K10: 0.07
B11: Base | C11: ='Revenue Build'!F13 -> 0.21114585 | D11: ='Revenue Build'!G13 -> 0.20030372 | E11: ='Revenue Build'!H13 -> 0.11728239 | F11: 0.12 | G11: 0.1 | H11: 0.08 | I11: 0.07 | J11: 0.06 | K11: 0.05
B12: Downside | F12: 0.08 | G12: 0.07 | H12: 0.06 | I12: 0.05 | J12: 0.04 | K12: 0.03
B14: Commercial Aftermarket | F14: =CHOOSE(Cover!$F$9, F15,F16,F17) -> 0.2 | G14: =CHOOSE(Cover!$F$9, G15,G16,G17) -> 0.2 | H14: =CHOOSE(Cover!$F$9, H15,H16,H17) -> 0.195 | I14: =CHOOSE(Cover!$F$9, I15,I16,I17) -> 0.19 | J14: =CHOOSE(Cover!$F$9, J15,J16,J17) -> 0.185 | K14: =CHOOSE(Cover!$F$9, K15,K16,K17) -> 0.175
B15: Upside | F15: 0.24 | G15: 0.235 | H15: 0.23 | I15: 0.225 | J15: 0.22 | K15: 0.21 | L15: Relatively aggressive growth numbers based on 30-40% YoY price hikes
B16: Base | C16: ='Revenue Build'!F20 -> 0.18252929 | D16: ='Revenue Build'!G20 -> 0.12580055 | E16: ='Revenue Build'!H20 -> 0.13937424 | F16: 0.2 | G16: 0.2 | H16: 0.195 | I16: 0.19 | J16: 0.185 | K16: 0.175 | L16: (consistent with previous years and management strategy)
B17: Downside | F17: 0.12 | G17: 0.12 | H17: 0.12 | I17: 0.115 | J17: 0.105 | K17: 0.095 | L17: However the revenue growth doesn't necessarily match 40% becuase that's only for niche segments
B19: Defense | F19: =CHOOSE(Cover!$F$9, F20,F21,F22) -> 0.17 | G19: =CHOOSE(Cover!$F$9, G20,G21,G22) -> 0.155 | H19: =CHOOSE(Cover!$F$9, H20,H21,H22) -> 0.155 | I19: 0.06 | J19: =CHOOSE(Cover!$F$9, J20,J21,J22) -> 0.13 | K19: =CHOOSE(Cover!$F$9, K20,K21,K22) -> 0.125
B20: Upside | F20: 0.21 | G20: 0.19 | H20: 0.18 | I20: 0.165 | J20: 0.15 | K20: 0.14 | L20: BULL AND BASE ASSUME NO DOD REGULATION CHANGES
B21: Base | C21: ='Revenue Build'!F24 -> 0.2082455 | D21: ='Revenue Build'!G24 -> 0.23965652 | E21: ='Revenue Build'!H24 -> 0.18419395 | F21: 0.17 | G21: 0.155 | H21: 0.155 | I21: 0.14 | J21: 0.13 | K21: 0.125
B22: Downside | F22: -0.25 | G22: 0.07 | H22: 0.065 | I22: 0.055 | J22: 0.045 | K22: 0.04 | L22: BEAR CASE ASSUMES DOD CHANGES REGULATIONS RESULTING IN DRASTIC MARGIN REDUCITONS
L23: check the specific percentaqe
B24: Non-Aviation (Other) | F24: =CHOOSE(Cover!$F$9, F25,F26,F27) -> 0 | G24: =CHOOSE(Cover!$F$9, G25,G26,G27) -> 0 | H24: =CHOOSE(Cover!$F$9, H25,H26,H27) -> 0 | I24: =CHOOSE(Cover!$F$9, I25,I26,I27) -> 0.01 | J24: =CHOOSE(Cover!$F$9, J25,J26,J27) -> 0.01 | K24: =CHOOSE(Cover!$F$9, K25,K26,K27) -> 0.01
B25: Upside | F25: 0.05 | G25: 0.04 | H25: 0.03 | I25: 0.03 | J25: 0.03 | K25: 0.02
B26: Base | C26: ='Revenue Build'!F28 -> -0.068113543 | D26: ='Revenue Build'!G28 -> 0.052631579 | E26: ='Revenue Build'!H28 -> 0 | F26: 0 | G26: 0 | H26: 0 | I26: 0.01 | J26: 0.01 | K26: 0.01
B27: Downside | F27: -0.03 | G27: -0.02 | H27: -0.01 | I27: 0 | J27: 0 | K27: 0

Sheet Operating Model
B2: TransDigm (NYSE: TDG)
B3: Operating Model
B4: In Millions of $USD (except share price)
B6: Sources: Factset Fundamentals, TDG 20-F Filings, TDG Earnings Calls, TDG Earnings Presentations, TDG 10Qs and 10Ks
B8: all figures in M unless otherwise stated | C8: FY 20 | D8: FY 21 | E8: FY 22 | F8: FY 23 | G8: FY 24 | H8: FY 25 | I8: FY 26 | J8: FY 27 | K8: FY 28 | L8: FY 29 | M8: FY 30 | N8: FY 31
B10: Operating Statement
B12: Revenue | C12: =IS!H6 -> 5107 | D12: =IS!G6 -> 4799 | E12: =IS!F6 -> 5437 | F12: =IS!E6 -> 6585 | G12: =IS!D6 -> 7936 | H12: =IS!C6 -> 8832 | I12: ='Revenue Build'!I12 -> 10185.355 | J12: ='Revenue Build'!J12 -> 11700.132 | K12: ='Revenue Build'!K12 -> 12941.881 | L12: ='Revenue Build'!L12 -> 14680.709 | M12: ='Revenue Build'!M12 -> 16567.708 | N12: ='Revenue Build'!N12 -> 18729.366 | O12: *Refer to Revenue Build and Assumptions
B13: % growth | D13: =D12/C12-1 -> -0.060309379 | E13: =E12/D12-1 -> 0.13294436 | F13: =F12/E12-1 -> 0.21114585 | G13: =G12/F12-1 -> 0.20516325 | H13: =H12/G12-1 -> 0.11290323 | I13: =I12/H12-1 -> 0.15323313 | J13: =J12/I12-1 -> 0.14872108 | K13: =K12/J12-1 -> 0.10613119 | ... N13: =N12/M12-1 -> 0.13047416
B15: COGS (Excluding D&A) | C15: =IS!H8 -> 2273 | D15: =IS!G8 -> 2129 | E15: =IS!F8 -> 2250 | F15: =IS!E8 -> 2566 | G15: =IS!D8 -> 3064 | H15: =IS!C8 -> 3347 | I15: =I12*I16 -> 3723.7658 | J15: =J12*J16 -> 4215.5576 | K15: =K12*K16 -> 4585.3084 | L15: =L12*L16 -> 5110.3549 | M15: =M12*M16 -> 5661.1857 | N15: =N12*N16 -> 6283.7021
B16: % revenue | C16: =C15/C12 -> 0.44507539 | D16: =D15/D12 -> 0.44363409 | E16: =E15/E12 -> 0.41383116 | F16: =F15/F12 -> 0.3896735 | G16: =G15/G12 -> 0.38608871 | H16: =H15/H12 -> 0.37896286 | I16: ='Operating Assumptions'!F9 -> 0.3656 | J16: ='Operating Assumptions'!G9 -> 0.3603 | K16: ='Operating Assumptions'!H9 -> 0.3543 | L16: ='Operating Assumptions'!I9 -> 0.3481 | M16: ='Operating Assumptions'!J9 -> 0.3417 | N16: ='Operating Assumptions'!K9 -> 0.3355 | O16: Weighted Average Math using %of Revenue by Rev Category
B17: Gross Profit | C17: =C12-C15 -> 2834 | D17: =D12-D15 -> 2670 | E17: =E12-E15 -> 3187 | F17: =F12-F15 -> 4019 | G17: =G12-G15 -> 4872 | H17: =H12-H15 -> 5485 | I17: =I12-I15 -> 6461.5892 | J17: =J12-J15 -> 7484.5745 | ... N17: =N12-N15 -> 12445.663
B18: GP margin (%) | C18: =C17/C12 -> 0.55492461 | D18: =D17/D12 -> 0.55636591 | E18: =E17/E12 -> 0.58616884 | F18: =F17/F12 -> 0.6103265 | G18: =G17/G12 -> 0.61391129 | H18: =H17/H12 -> 0.62103714 | I18: =I17/I12 -> 0.6344 | J18: =J17/J12 -> 0.6397 | ... N18: =N17/N12 -> 0.6645
B20: OpEx
B21: SG&A | C21: =IS!H15 -> 565.4 | D21: =IS!G15 -> 544.4 | E21: =IS!F15 -> 642.1 | F21: =IS!E15 -> 661 | G21: =IS!D15 -> 827 | H21: =IS!C15 -> 803 | I21: =I22*I12 -> 926.8673 | J21: =J22*J12 -> 1053.0119 | K21: =K22*K12 -> 1151.8274 | L21: =L22*L12 -> 1291.9024 | M21: =M22*M12 -> 1441.3906 | N21: =N22*N12 -> 1610.7254
B22: % revenue | C22: =C21/C12 -> 0.11071079 | D22: =D21/D12 -> 0.1134403 | E22: =E21/E12 -> 0.11809822 | F22: =F21/F12 -> 0.10037965 | G22: =G21/G12 -> 0.10420867 | H22: =H21/H12 -> 0.090919384 | I22: ='Operating Assumptions'!F14 -> 0.091 | J22: ='Operating Assumptions'!G14 -> 0.09 | K22: ='Operating Assumptions'!H14 -> 0.089 | L22: ='Operating Assumptions'!I14 -> 0.088 | M22: ='Operating Assumptions'!J14 -> 0.087 | N22: ='Operating Assumptions'!K14 -> 0.086 | O22: *Assumed slight contraction
B23: Depreciation | C23: =IS!H52 -> 283 | D23: =IS!G52 -> 252 | E23: =IS!F52 -> 252 | F23: =IS!E52 -> 268 | G23: =IS!D52 -> 310 | H23: =IS!C52 -> 364 | I23: =I24*I12 -> 407.4142 | J23: =J24*J12 -> 468.00528 | K23: =K24*K12 -> 511.2043 | L23: =L24*L12 -> 572.54766 | M23: =M24*M12 -> 637.85675 | N23: =N24*N12 -> 711.71589
B24: % revenue | C24: =C23/C12 -> 0.055414137 | D24: =D23/D12 -> 0.05251094 | E24: =E23/E12 -> 0.04634909 | F24: =F23/F12 -> 0.040698557 | G24: =G23/G12 -> 0.0390625 | H24: =H23/H12 -> 0.041213768 | I24: ='Operating Assumptions'!F19 -> 0.04 | J24: ='Operating Assumptions'!G19 -> 0.04 | K24: ='Operating Assumptions'!H19 -> 0.0395 | L24: ='Operating Assumptions'!I19 -> 0.039 | M24: ='Operating Assumptions'!J19 -> 0.0385 | N24: ='Operating Assumptions'!K19 -> 0.038
B25: Other Operating Expenses | C25: =IS!H14 -> 130.9 | D25: =IS!G14 -> 105.6 | E25: =IS!F14 -> 94.9 | F25: =IS!E14 -> 105 | G25: =IS!D14 -> 107 | H25: =IS!C14 -> 118 | I25: 8.5 | J25: =J26*J12 -> 134.55152 | K25: =K26*K12 -> 142.36069 | L25: =L26*L12 -> 154.14745 | M25: =M26*M12 -> 165.67708 | N25: =N26*N12 -> 187.29366
B26: % revenue | C26: =C25/C12 -> 0.025631486 | D26: =D25/D12 -> 0.022004584 | E26: =E25/E12 -> 0.017454479 | F26: =F25/F12 -> 0.01594533 | G26: =G25/G12 -> 0.013482863 | H26: =H25/H12 -> 0.013360507 | I26: ='Operating Assumptions'!F24 -> 0.012 | J26: ='Operating Assumptions'!G24 -> 0.0115 | K26: ='Operating Assumptions'!H24 -> 0.011 | L26: ='Operating Assumptions'!I24 -> 0.0105 | M26: ='Operating Assumptions'!J24 -> 0.01 | N26: ='Operating Assumptions'!K24 -> 0.01
B27: Total OpEx | C27: =C21+C23+C25 -> 979.3 | D27: =D21+D23+D25 -> 902 | E27: =E21+E23+E25 -> 989 | F27: =F21+F23+F25 -> 1034 | G27: =G21+G23+G25 -> 1244 | H27: =H21+H23+H25 -> 1285 | I27: =I21+I23+I25 -> 1342.7815 | J27: =J21+J23+J25 -> 1655.5687 | ... N27: =N21+N23+N25 -> 2509.735
B28: Operating Income (EBIT) | C28: =C17-C21-C23-C25 -> 1854.7 | D28: =D17-D21-D23-D25 -> 1768 | E28: =E17-E21-E23-E25 -> 2198 | F28: =F17-F21-F23-F25 -> 2985 | G28: =G17-G21-G23-G25 -> 3628 | H28: =H17-H21-H23-H25 -> 4200 | I28: =I17-I21-I23-I25 -> 5118.8077 | J28: =J17-J21-J23-J25 -> 5829.0058 | ... N28: =N17-N21-N23-N25 -> 9935.9284
B29: EBIT margin (%) | C29: =C28/C12 -> 0.3631682 | D29: =D28/D12 -> 0.36841009 | E29: =E28/E12 -> 0.40426706 | F29: =F28/F12 -> 0.45330296 | G29: =G28/G12 -> 0.45715726 | H29: =H28/H12 -> 0.47554348 | I29: =I28/I12 -> 0.50256547 | J29: =J28/J12 -> 0.4982 | ... N29: =N28/N12 -> 0.5305 | O29: Maintained industry-leading EBIT and EBITDA margins
B31: EBITDA | C31: =C28+C23 -> 2137.7 | D31: =D28+D23 -> 2020 | E31: =E28+E23 -> 2450 | F31: =F28+F23 -> 3253 | G31: =G28+G23 -> 3938 | H31: =H28+H23 -> 4564 | I31: =I28+I23 -> 5526.2219 | J31: =J28+J23 -> 6297.0111 | ... N31: =N28+N23 -> 10647.644
B32: EBITDA margin (%) | C32: =C31/C12 -> 0.41858234 | D32: =D31/D12 -> 0.42092103 | E32: =E31/E12 -> 0.45061615 | F32: =F31/F12 -> 0.49400152 | G32: =G31/G12 -> 0.49621976 | H32: =H31/H12 -> 0.51675725 | I32: =I31/I12 -> 0.54256547 | J32: =J31/J12 -> 0.5382 | ... N32: =N31/N12 -> 0.5685
B34: Interest Payment | C34: =IS!H19 -> 1061 | D34: =IS!G19 -> 1098 | E34: =IS!F19 -> 1078 | F34: =IS!E19 -> 1220 | G34: =IS!D19 -> 1344 | H34: =IS!C19 -> 1640 | I34: =I35 *I12 -> 1981.18 | J34: =J35 *J12 -> 2314.7554 | K34: =K35 *K12 -> 2693.1382 | L34: =L35 *L12 -> 3173.3984 | M34: =M35 *M12 -> 3710.4138 | N34: =N35 *N12 -> 4370.6055 | O34: *As M&A spending further increases throughout LBO hold term, interest expenses will grow in turn, especially with PIK interest toggles
B35: % of Revenue | C35: =C34 / C12 -> 0.20775406 | D35: =D34 / D12 -> 0.22879767 | E35: =E34 / E12 -> 0.19827111 | F35: =F34 / F12 -> 0.18526955 | G35: =G34 / G12 -> 0.16935484 | H35: =H34 / H12 -> 0.18568841 | I35: =AVERAGE(F35:H35) * 1.08 -> 0.19451261 | J35: =AVERAGE(G35:I35) * 1.08 -> 0.19784011 | K35: =AVERAGE(H35:J35) * 1.08 -> 0.2080948 | L35: =AVERAGE(I35:K35) * 1.08 -> 0.21616111 | M35: =AVERAGE(J35:L35) * 1.08 -> 0.22395457 | N35: =AVERAGE(K35:M35) * 1.08 -> 0.23335577
B36: EBITDA Adjustment
B38: EBITDA | C38: =C31 -> 2137.7 | D38: =D31 -> 2020 | E38: =E31 -> 2450 | F38: =F31 -> 3253 | G38: =G31 -> 3938 | H38: =H31 -> 4564 | I38: =I31 -> 5526.2219 | J38: =J31 -> 6297.0111 | ... N38: =N31 -> 10647.644
B39: Unusual Expenses | C39: =IS!H21 -> 77.7 | D39: =IS!G21 -> 65 | E39: =IS!F21 -> 15 | F39: =IS!E21 -> 48 | G39: =IS!D21 -> 81 | H39: =IS!C21 -> 24 | I39: =AVERAGE(E39:H39) -> 42 | J39: =I39*(1+0.02) -> 42.84 | K39: =J39*(1+0.02) -> 43.6968 | L39: =K39*(1+0.02) -> 44.570736 | M39: =L39*(1+0.02) -> 45.462151 | N39: =M39*(1+0.02) -> 46.371394 | O39: *Used historical average of non-irregular figures, then base projection rate used
B40: Stock-Based Compensation | C40: 105 | D40: 148 | E40: 153 | F40: 135 | G40: 188 | H40: 152 | I40: =AVERAGE(E40:H40) -> 157 | J40: =I40*1.02 -> 160.14 | K40: =J40*1.02 -> 163.3428 | L40: =K40*1.02 -> 166.60966 | M40: =L40*1.02 -> 169.94185 | N40: =M40*1.02 -> 173.34069 | O40: *Used historical average of non-irregular figures, then base projection rate used
B41: Adjusted EBITDA | C41: =C38+C39+C40 -> 2320.4 | D41: =D38+D39+D40 -> 2233 | E41: =E38+E39+E40 -> 2618 | F41: =F38+F39+F40 -> 3436 | G41: =G38+G39+G40 -> 4207 | H41: =H38+H39+H40 -> 4740 | I41: =I38+I39+I40 -> 5725.2219 | J41: =J38+J39+J40 -> 6499.9911 | ... N41: =N38+N39+N40 -> 10867.356
B44: Working Capital
B46: Revenue | C46: =C12 -> 5107 | D46: =D12 -> 4799 | E46: =E12 -> 5437 | F46: =F12 -> 6585 | G46: =G12 -> 7936 | H46: =H12 -> 8832 | I46: =I12 -> 10185.355 | J46: =J12 -> 11700.132 | ... N46: =N12 -> 18729.366
B47: COGS | C47: =C15 -> 2273 | D47: =D15 -> 2129 | E47: =E15 -> 2250 | F47: =F15 -> 2566 | G47: =G15 -> 3064 | H47: =H15 -> 3347 | I47: =I15 -> 3723.7658 | J47: =J15 -> 4215.5576 | ... N47: =N15 -> 6283.7021
B50: Non-Cash Current Assets
B51: Short-Term Receivables | C51: =756 -> 756 | D51: 861 | E51: 1086 | F51: 1421 | G51: 1651 | H51: 1897 | I51: =(I52/365)*I46 -> 2009.1659 | J51: =(J52/365)*J46 -> 2307.9712 | K51: =(K52/365)*K46 -> 2517.4618 | L51: =(L52/365)*L46 -> 2815.4785 | M51: =(M52/365)*M46 -> 3131.9776 | N51: =(N52/365)*N46 -> 3489.3065
B52: DSO | C52: 66.8 | D52: 61.5 | E52: 65.4 | F52: 69.5 | G52: 70.6 | H52: 73.3 | I52: ='Operating Assumptions'!Q9 -> 72 | J52: ='Operating Assumptions'!R9 -> 72 | K52: ='Operating Assumptions'!S9 -> 71 | L52: ='Operating Assumptions'!T9 -> 70 | M52: ='Operating Assumptions'!U9 -> 69 | N52: ='Operating Assumptions'!V9 -> 68
B53: Inventory | C53: 1283 | D53: 1185 | E53: 1332 | F53: 1616 | G53: 1876 | H53: 2095 | I53: =(I54/365)*I47 -> 2193.4511 | J53: =(J54/365)*J47 -> 2471.5872 | K53: =(K54/365)*K47 -> 2675.8101 | L53: =(L54/365)*L47 -> 2968.2061 | M53: =(M54/365)*M47 -> 3272.6307 | N53: =(N54/365)*N47 -> 3615.2807
B54: DIO | C54: 202 | D54: 211.6 | E54: 204.2 | F54: 209.7 | G54: 208 | H54: 216.5 | I54: ='Operating Assumptions'!Q14 -> 215 | J54: ='Operating Assumptions'!R14 -> 214 | K54: ='Operating Assumptions'!S14 -> 213 | L54: ='Operating Assumptions'!T14 -> 212 | M54: ='Operating Assumptions'!U14 -> 211 | N54: ='Operating Assumptions'!V14 -> 210
B55: Other Current Assets | C55: 204 | D55: 197 | E55: 230 | F55: 229 | G55: 241 | H55: 212 | I55: =I56*I46 -> 234.26316 | J55: =J56*J46 -> 257.4029 | K55: =K56*K46 -> 271.7795 | L55: =L56*L46 -> 293.61419 | M55: =M56*M46 -> 314.78645 | N55: =N56*N46 -> 337.12858
...

Sheet Operating Assumptions
B2: TransDigm (NYSE: TDG)
B3: Operating Model Assumptions
F5: FY 26 | G5: FY 27 | H5: FY 28 | I5: FY 29 | J5: FY 30 | K5: FY 31 | Q5: FY 26 | R5: FY 27 | S5: FY 28 | T5: FY 29 | U5: FY 30 | V5: FY 31
B7: Operating Statement Breakdown | M7: Working Capital Assumptions
B9: COGS % Revenue (Weighted Average) | F9: =CHOOSE(Cover!$F$9, F10,F11,F12) -> 0.3656 | G9: =CHOOSE(Cover!$F$9, G10,G11,G12) -> 0.3603 | H9: =CHOOSE(Cover!$F$9, H10,H11,H12) -> 0.3543 | I9: =CHOOSE(Cover!$F$9, I10,I11,I12) -> 0.3481 | J9: =CHOOSE(Cover!$F$9, J10,J11,J12) -> 0.3417 | K9: =CHOOSE(Cover!$F$9, K10,K11,K12) -> 0.3355 | M9: DSO | Q9: =CHOOSE(Cover!$F$9, Q10,Q11,Q12) -> 72 | R9: =CHOOSE(Cover!$F$9, R10,R11,R12) -> 72 | S9: =CHOOSE(Cover!$F$9, S10,S11,S12) -> 71 | T9: =CHOOSE(Cover!$F$9, T10,T11,T12) -> 70 | U9: =CHOOSE(Cover!$F$9, U10,U11,U12) -> 69 | V9: =CHOOSE(Cover!$F$9, V10,V11,V12) -> 68
B10: Upside | F10: =F11 + 0.75% -> 0.3731 | G10: =G11 + 0.75% -> 0.3678 | H10: =H11 + 0.75% -> 0.3618 | I10: =I11 + 0.75% -> 0.3556 | J10: =J11 + 0.75% -> 0.3492 | K10: =K11 + 0.75% -> 0.343 | M10: Upside | Q10: 70 | R10: 69 | S10: 68 | T10: 67 | U10: 66 | V10: 65
B11: Base | F11: 0.3656 | G11: 0.3603 | H11: 0.3543 | I11: 0.3481 | J11: 0.3417 | K11: 0.3355 | M11: Base | Q11: 72 | R11: 72 | S11: 71 | T11: 70 | U11: 69 | V11: 68 | W11: Based on projections from past years
B12: Downside | F12: =F11 - 0.77% -> 0.3579 | G12: =G11 - 0.77% -> 0.3526 | H12: =H11 - 0.77% -> 0.3466 | I12: =I11 - 0.77% -> 0.3404 | J12: =J11 - 0.77% -> 0.334 | K12: =K11 - 0.77% -> 0.3278 | M12: Downside | Q12: 74 | R12: 75 | S12: 75 | T12: 76 | U12: 76 | V12: 77
B14: SG&A % Revenue | F14: =CHOOSE(Cover!$F$9, F15,F16,F17) -> 0.091 | G14: =CHOOSE(Cover!$F$9, G15,G16,G17) -> 0.09 | H14: =CHOOSE(Cover!$F$9, H15,H16,H17) -> 0.089 | I14: =CHOOSE(Cover!$F$9, I15,I16,I17) -> 0.088 | J14: =CHOOSE(Cover!$F$9, J15,J16,J17) -> 0.087 | K14: =CHOOSE(Cover!$F$9, K15,K16,K17) -> 0.086 | M14: DIO | Q14: =CHOOSE(Cover!$F$9, Q15,Q16,Q17) -> 215 | R14: =CHOOSE(Cover!$F$9, R15,R16,R17) -> 214 | S14: =CHOOSE(Cover!$F$9, S15,S16,S17) -> 213 | T14: =CHOOSE(Cover!$F$9, T15,T16,T17) -> 212 | U14: =CHOOSE(Cover!$F$9, U15,U16,U17) -> 211 | V14: =CHOOSE(Cover!$F$9, V15,V16,V17) -> 210
B15: Upside | F15: 0.091 | G15: 0.089 | H15: 0.087 | I15: 0.085 | J15: 0.083 | K15: 0.081 | M15: Upside | Q15: 212 | R15: 210 | S15: 208 | T15: 206 | U15: 204 | V15: 202
B16: Base | F16: 0.091 | G16: 0.09 | H16: 0.089 | I16: 0.088 | J16: 0.087 | K16: 0.086 | M16: Base | Q16: 215 | R16: 214 | S16: 213 | T16: 212 | U16: 211 | V16: 210 | W16: Based on projections from past years
B17: Downside | F17: 0.091 | G17: 0.092 | H17: 0.092 | I17: 0.091 | J17: 0.091 | K17: 0.09 | M17: Downside | Q17: 220 | R17: 222 | S17: 223 | T17: 224 | U17: 225 | V17: 225
B19: Depreciation % Revenue | F19: =CHOOSE(Cover!$F$9, F20,F21,F22) -> 0.04 | G19: =CHOOSE(Cover!$F$9, G20,G21,G22) -> 0.04 | H19: =CHOOSE(Cover!$F$9, H20,H21,H22) -> 0.0395 | I19: =CHOOSE(Cover!$F$9, I20,I21,I22) -> 0.039 | J19: =CHOOSE(Cover!$F$9, J20,J21,J22) -> 0.0385 | K19: =CHOOSE(Cover!$F$9, K20,K21,K22) -> 0.038 | M19: DPO | Q19: =CHOOSE(Cover!$F$9, Q20,Q21,Q22) -> 39 | R19: =CHOOSE(Cover!$F$9, R20,R21,R22) -> 39 | S19: =CHOOSE(Cover!$F$9, S20,S21,S22) -> 39 | T19: =CHOOSE(Cover!$F$9, T20,T21,T22) -> 40 | U19: =CHOOSE(Cover!$F$9, U20,U21,U22) -> 40 | V19: =CHOOSE(Cover!$F$9, V20,V21,V22) -> 40
B20: Upside | F20: 0.039 | G20: 0.038 | H20: 0.037 | I20: 0.036 | J20: 0.0355 | K20: 0.035 | M20: Upside | Q20: 40 | R20: 40 | S20: 41 | T20: 41 | U20: 42 | V20: 42
B21: Base | F21: 0.04 | G21: 0.04 | H21: 0.0395 | I21: 0.039 | J21: 0.0385 | K21: 0.038 | M21: Base | Q21: 39 | R21: 39 | S21: 39 | T21: 40 | U21: 40 | V21: 40
B22: Downside | F22: 0.042 | G22: 0.0415 | H22: 0.041 | I22: 0.0405 | J22: 0.04 | K22: 0.0395 | M22: Downside | Q22: 37 | R22: 37 | S22: 37 | T22: 38 | U22: 38 | V22: 38
B24: Other Operating Expenses % Revenue | F24: =CHOOSE(Cover!$F$9, F25,F26,F27) -> 0.012 | G24: =CHOOSE(Cover!$F$9, G25,G26,G27) -> 0.0115 | H24: =CHOOSE(Cover!$F$9, H25,H26,H27) -> 0.011 | I24: =CHOOSE(Cover!$F$9, I25,I26,I27) -> 0.0105 | J24: =CHOOSE(Cover!$F$9, J25,J26,J27) -> 0.01 | K24: =CHOOSE(Cover!$F$9, K25,K26,K27) -> 0.01 | M24: Other Current Assets | Q24: =CHOOSE(Cover!$F$9, Q25,Q26,Q27) -> 0.023 | R24: =CHOOSE(Cover!$F$9, R25,R26,R27) -> 0.022 | S24: =CHOOSE(Cover!$F$9, S25,S26,S27) -> 0.021 | T24: =CHOOSE(Cover!$F$9, T25,T26,T27) -> 0.02 | U24: =CHOOSE(Cover!$F$9, U25,U26,U27) -> 0.019 | V24: =CHOOSE(Cover!$F$9, V25,V26,V27) -> 0.018
B25: Upside | F25: 0.011 | G25: 0.0105 | H25: 0.01 | I25: 0.0095 | J25: 0.009 | K25: 0.009 | M25: Upside | Q25: 0.021 | R25: 0.02 | S25: 0.019 | T25: 0.018 | U25: 0.018 | V25: 0.017
B26: Base | F26: 0.012 | G26: 0.0115 | H26: 0.011 | I26: 0.0105 | J26: 0.01 | K26: 0.01 | M26: Base | Q26: 0.023 | R26: 0.022 | S26: 0.021 | T26: 0.02 | U26: 0.019 | V26: 0.018
B27: Downside | F27: 0.0135 | G27: 0.0135 | H27: 0.013 | I27: 0.013 | J27: 0.0125 | K27: 0.0125 | M27: Downside | Q27: 0.026 | R27: 0.025 | S27: 0.024 | T27: 0.023 | U27: 0.022 | V27: 0.021
M29: Other Current Liabilities | Q29: =CHOOSE(Cover!$F$9, Q30,Q31,Q32) -> 0.093 | R29: =CHOOSE(Cover!$F$9, R30,R31,R32) -> 0.092 | S29: =CHOOSE(Cover!$F$9, S30,S31,S32) -> 0.091 | T29: =CHOOSE(Cover!$F$9, T30,T31,T32) -> 0.09 | U29: =CHOOSE(Cover!$F$9, U30,U31,U32) -> 0.09 | V29: =CHOOSE(Cover!$F$9, V30,V31,V32) -> 0.089
M30: Upside | Q30: 0.096 | R30: 0.095 | S30: 0.094 | T30: 0.093 | U30: 0.092 | V30: 0.092
M31: Base | Q31: 0.093 | R31: 0.092 | S31: 0.091 | T31: 0.09 | U31: 0.09 | V31: 0.089
M32: Downside | Q32: 0.09 | R32: 0.089 | S32: 0.088 | T32: 0.087 | U32: 0.086 | V32: 0.085
B38: Cash Flow from Investing
B40: CapEx % Revenue | F40: =CHOOSE(Cover!$F$9, F41,F42,F43) -> 0.023 | G40: =CHOOSE(Cover!$F$9, G41,G42,G43) -> 0.022 | H40: =CHOOSE(Cover!$F$9, H41,H42,H43) -> 0.022 | I40: =CHOOSE(Cover!$F$9, I41,I42,I43) -> 0.021 | J40: =CHOOSE(Cover!$F$9, J41,J42,J43) -> 0.021 | K40: =CHOOSE(Cover!$F$9, K41,K42,K43) -> 0.02
B41: Upside | F41: 0.02 | G41: 0.02 | H41: 0.019 | I41: 0.019 | J41: 0.018 | K41: 0.018
B42: Base | F42: 0.023 | G42: 0.022 | H42: 0.022 | I42: 0.021 | J42: 0.021 | K42: 0.02
B43: Downside | F43: 0.026 | G43: 0.025 | H43: 0.025 | I43: 0.024 | J43: 0.024 | K43: 0.023
B45: Net Assets From Acquisition % Revenue | F45: =CHOOSE(Cover!$F$9, F46,F47,F48) -> -0.05 | G45: =CHOOSE(Cover!$F$9, G46,G47,G48) -> -0.05 | H45: =CHOOSE(Cover!$F$9, H46,H47,H48) -> -0.045 | I45: =CHOOSE(Cover!$F$9, I46,I47,I48) -> -0.045 | J45: =CHOOSE(Cover!$F$9, J46,J47,J48) -> -0.04 | K45: =CHOOSE(Cover!$F$9, K46,K47,K48) -> -0.04
B46: Upside | F46: -0.03 | G46: -0.03 | H46: -0.025 | I46: -0.025 | J46: -0.02 | K46: -0.02
B47: Base | F47: -0.05 | G47: -0.05 | H47: -0.045 | I47: -0.045 | J47: -0.04 | K47: -0.04
B48: Downside | F48: -0.07 | G48: -0.07 | H48: -0.065 | I48: -0.065 | J48: -0.06 | K48: -0.06
B50: For sake of making this work, we'll consider Bull to be stable, non-aggressive expansion
B51: Bear case is high value transactions yearly where cash spend is higher on average

Sheet Comps
B2: TransDigm Group (NYSE: TDG)
B3: Comparable Companies Analysis
B4: In Millions of $USD (except share price)
D7: Current | E7: % of | N7: LTM | O7: Total | Q7: Total
D8: Share | E8: 52-wk. | F8: Equity | G8: Enterprise | I8: LTM | K8: LTM | N8: EBIT | O8: Debt/ | Q8: Debt/
B9: Company | C9: Ticker | D9: Price | E9: High | F9: Value (M) | G9: Value (M) | I9: EV / Sales | K9: EV / EBITDA | N9: Margin | O9: EBIT | P9: Beta | Q9: Equity
B11: TransDigm Group | C11: NYSE: TDG | D11: 1167 | E11: =D11 / 1623.82 -> 0.71867572 | F11: 69139 | G11: 95664 | I11: 9.54 | K11: 20.96 | N11: 0.47 | O11: 7.01 | P11: 0.82 | Q11: - | R11: stockholder's deficit
R12: book equity is negative
B13: Tier I: Largest
B14: Boeing | C14: NYSE: BA | D14: 208.22 | E14: =D14 / 254.35 -> 0.81863574 | F14: 171920 | G14: 199670 | I14: 2.05 | K14: - | N14: -0.06 | O14: - | P14: 1.75 | Q14: 10.33
B15: RTX | C15: NYSE: RTX | D15: 196.21 | E15: =D15 / 214.5 -> 0.91473193 | F15: 267660 | G15: 300020 | I15: 3.21 | K15: 23.28 | N15: 0.1 | O15: 4.5 | P15: 0.9 | Q15: 0.612
B18: Tier II: Middle
B19: Howmet Aerospace | C19: NYSE: HWM | D19: 232.68 | E19: =D19 / 267.31 -> 0.87045004 | F19: 93800 | G19: 96648 | I19: 10.41 | K19: 40.05 | N19: 0.258 | O19: 1.51 | P19: 1.3 | Q19: 0.6
B20: HEICO | C20: NYSE: HEI | D20: 271.77 | E20: =D20 / 361.69 -> 0.75138931 | F20: 33312 | G20: 36102 | I20: 7.14 | K20: 30.02 | N20: 0.224 | O20: 2.41 | P20: 0.98 | Q20: 0.557
B22: Tier III: Smallest
B23: Textron | C23: NYSE: TXT | D23: 88.05 | E23: =D23 / 101.57 -> 0.86688983 | F23: 15520 | G23: 17373 | I23: 1.12 | K23: 12.43 | N23: 0.068 | O23: 4.28 | P23: 1.21 | Q23: 0.544
B24: FTAI Aviation | C24: NASDAQ: FTAI | D24: 242.69 | E24: =D24 / 323.51 -> 0.75017774 | F24: 24893 | G24: 27727 | I24: 8.45 | K24: 27.75 | N24: 0.305 | O24: 4.5 | P24: 1.44 | Q24: 10.321
B27: Overall
B29: Mean | D29: =AVERAGE(D14:D24) -> 206.60333 | E29: =AVERAGE(E14:E24) -> 0.82871243 | F29: =AVERAGE(F14:F24) -> 101184.17 | G29: =AVERAGE(G14:G24) -> 112923.33 | I29: =AVERAGE(I14:I24) -> 5.3966667 | K29: =AVERAGE(K14:K24) -> 26.706 | N29: =AVERAGE(N14:N24) -> 0.14916667 | O29: =AVERAGE(O14:O24) -> 3.44 | P29: =AVERAGE(P14:P24) -> 1.2633333 | Q29: =AVERAGE(Q14:Q24) -> 3.8273333
B30: Median | D30: =MEDIAN(D14:D24) -> 220.45 | E30: =MEDIAN(E14:E24) -> 0.84276278 | F30: =MEDIAN(F14:F24) -> 63556 | G30: =MEDIAN(G14:G24) -> 66375 | I30: =MEDIAN(I14:I24) -> 5.175 | K30: =MEDIAN(K14:K24) -> 27.75 | N30: =MEDIAN(N14:N24) -> 0.162 | O30: =MEDIAN(O14:O24) -> 4.28 | P30: =MEDIAN(P14:P24) -> 1.255 | Q30: =MEDIAN(Q14:Q24) -> 0.606
B32: High | D32: =MAXA(D14:D24) -> 271.77 | E32: =MAXA(E14:E24) -> 0.91473193 | F32: =MAXA(F14:F24) -> 267660 | G32: =MAXA(G14:G24) -> 300020 | I32: =MAXA(I14:I24) -> 10.41 | K32: =MAXA(K14:K24) -> 40.05 | N32: =MAXA(N14:N24) -> 0.305 | O32: =MAXA(O14:O24) -> 4.5 | P32: =MAXA(P14:P24) -> 1.75 | Q32: =MAXA(Q14:Q24) -> 10.33
B33: Q3 | D33: =_xlfn.QUARTILE.INC(D14:D24, 3) -> 240.1875 | E33: =_xlfn.QUARTILE.INC(E14:E24, 3) -> 0.86955999 | F33: =_xlfn.QUARTILE.INC(F14:F24, 3) -> 152390 | G33: =_xlfn.QUARTILE.INC(G14:G24, 3) -> 173914.5 | I33: =_xlfn.QUARTILE.INC(I14:I24, 3) -> 8.1225 | K33: =_xlfn.QUARTILE.INC(K14:K24, 3) -> 30.02 | N33: =_xlfn.QUARTILE.INC(N14:N24, 3) -> 0.2495 | O33: =_xlfn.QUARTILE.INC(O14:O24, 3) -> 4.5 | P33: =_xlfn.QUARTILE.INC(P14:P24, 3) -> 1.405 | Q33: =_xlfn.QUARTILE.INC(Q14:Q24, 3) -> 7.89375
B34: Q1 | D34: =_xlfn.QUARTILE.INC(D14:D24, 1) -> 199.2125 | E34: =_xlfn.QUARTILE.INC(E14:E24, 1) -> 0.76820092 | F34: =_xlfn.QUARTILE.INC(F14:F24, 1) -> 26997.75 | G34: =_xlfn.QUARTILE.INC(G14:G24, 1) -> 29820.75 | I34: =_xlfn.QUARTILE.INC(I14:I24, 1) -> 2.34 | K34: =_xlfn.QUARTILE.INC(K14:K24, 1) -> 23.28 | N34: =_xlfn.QUARTILE.INC(N14:N24, 1) -> 0.076 | O34: =_xlfn.QUARTILE.INC(O14:O24, 1) -> 2.41 | P34: =_xlfn.QUARTILE.INC(P14:P24, 1) -> 1.0375 | Q34: =_xlfn.QUARTILE.INC(Q14:Q24, 1) -> 0.56775
B35: Low | D35: =MINA(D14:D24) -> 88.05 | E35: =MINA(E14:E24) -> 0.75017774 | F35: =MINA(F14:F24) -> 15520 | G35: =MINA(G14:G24) -> 17373 | I35: =MINA(I14:I24) -> 1.12 | K35: =MINA(K14:K24) -> 0 | N35: =MINA(N14:N24) -> -0.06 | O35: =MINA(O14:O24) -> 0 | P35: =MINA(P14:P24) -> 0.9 | Q35: =MINA(Q14:Q24) -> 0.544

Sheet Precedents
B2: TransDigm Group (NYSE: TDG)
B3: Precedent Transactions Analysis
B4: In Millions of $USD (except share price)
B6: Company | C6: Acquirer | D6: Year | E6: Transaction Value($M) | F6: EV/EBITDA Multiple
B7: TriMas Aerospace | C7: Blackstone and Tinicum L.P. | D7: 2025 | E7: 1450 | F7: 18
B8: Novaria Group | C8: Arcline Investment Management | D8: 2025 | E8: 2200 | F8: 17.6
B9: Cobham Mission Systems | C9: Eaton Corporation | D9: 2021 | E9: 2830 | F9: 14
B10: Meggit PLC | C10: Parker-Hannifin | D10: 2022 | E10: 7257 | F10: 19.2 | G10: *Calculated multiple off of publicized data on transaction
D13: Mean | E13: =AVERAGE(E7:E11) -> 3434.25 | F13: =AVERAGE(F7:F11) -> 17.2
D14: Median | E14: =MEDIAN(E7:E11) -> 2515 | F14: =MEDIAN(F7:F11) -> 17.8

Sheet Support >>

Sheet IS
A1: TransDigm Group Incorporated
A2: TDG 893641100 B11FJK3 NYSE Common stock
A3: Source: FactSet Fundamentals
B4: DEC '25 | C4: SEP '25 | D4: SEP '24 | E4: SEP '23 | F4: SEP '22 | G4: SEP '21 | H4: SEP '20 | I4: SEP '19 | J4: SEP '18 | K4: SEP '17 | L4: SEP '16
B5: LTM
A6: Sales | B6: 9110 | C6: 8832 | D6: 7936 | E6: 6585 | F6: 5437 | G6: 4799 | H6: 5107 | I6: 5223.223 | J6: 3811.126 | K6: 3504.286 | L6: 3171.411
A7: Cost of Goods Sold (COGS) incl. D&A | B7: 3860 | C7: 3711 | D7: 3374 | E7: 2834 | F7: 2502 | G7: 2381 | H7: 2556 | I7: 2540.584 | J7: 1692.67 | K7: 1604.885 | L7: 1512.493
A8: COGS excluding D&A | B8: 3484 | C8: 3347 | D8: 3064 | E8: 2566 | F8: 2250 | G8: 2129 | H8: 2273 | I8: 2315.943 | J8: 1563.819 | K8: 1464.722 | L8: 1390.823
A9: Depreciation & Amortization Expense | B9: 376 | C9: 364 | D9: 310 | E9: 268 | F9: 252 | G9: 252 | H9: 283 | I9: 224.641 | J9: 128.851 | K9: 140.163 | L9: 121.67
A10: Depreciation | B10: 169 | C10: 163 | D10: 149 | E10: 129 | F10: 116 | G10: 115 | H10: 114 | I10: 89.689 | J10: 56.397 | K10: 50.937 | L10: 43.455
A11: Amortization of Intangibles | B11: 207 | C11: 201 | D11: 161 | E11: 139 | F11: 136 | G11: 137 | H11: 169 | I11: 134.952 | J11: 72.454 | K11: 89.226 | L11: 78.215
A12: Gross Income | B12: 5250 | C12: 5121 | D12: 4562 | E12: 3751 | F12: 2935 | G12: 2418 | H12: 2551 | I12: 2682.639 | J12: 2118.456 | K12: 1899.401 | L12: 1658.918
A13: SG&A Expense | B13: 965 | C13: 921 | D13: 934 | E13: 766 | F13: 737 | G13: 650 | H13: 696.3 | I13: 668.973 | J13: 442.495 | K13: 409.075 | L13: 356.858
A14: Research & Development | C14: 118 | D14: 107 | E14: 105 | F14: 94.9 | G14: 105.6 | H14: 130.9 | I14: 116.8 | J14: 73.8 | K14: 73.8 | L14: 58.6
A15: Other SG&A | B15: 965 | C15: 803 | D15: 827 | E15: 661 | F15: 642.1 | G15: 544.4 | H15: 565.4 | I15: 552.173 | J15: 368.695 | K15: 335.275 | L15: 298.258
A16: EBIT (Operating Income) | B16: 4285 | C16: 4200 | D16: 3628 | E16: 2985 | F16: 2198 | G16: 1768 | H16: 1854.7 | I16: 2013.666 | J16: 1675.961 | K16: 1490.326 | L16: 1302.06
A17: Nonoperating Income - Net | B17: 34 | C17: 93 | D17: 12 | E17: -1 | F17: 22 | G17: 110 | H17: 24 | I17: 9.325 | J17: 0.4 | K17: 0 | L17: 0
A18: Other Income (Expense) | B18: 34 | C18: 93 | D18: 12 | E18: -1 | F18: 22 | G18: 110 | H18: 24 | I18: 9.325 | J18: 0.4 | K18: 0 | L18: 0
A19: Interest Expense | B19: 1703 | C19: 1640 | D19: 1344 | E19: 1220 | F19: 1078 | G19: 1098 | H19: 1061 | I19: 865.826 | J19: 669.404 | K19: 639.296 | L19: 498.244
A20: Gross Interest Expense | B20: 1703 | C20: 1640 | D20: 1344 | E20: 1220 | F20: 1078 | G20: 1098 | H20: 1061 | I20: 865.826 | J20: 669.404 | K20: 639.296 | L20: 498.244
A21: Unusual Expense - Net | B21: 35 | C21: 24 | D21: 81 | E21: 48 | F21: 15 | G21: 65 | H21: 77.7 | I21: 94.3 | J21: 21.4 | K21: 13.6 | L21: 35.7
A22: Restructuring Expense | B22: 35 | C22: 24 | D22: 81 | E22: 48 | F22: 15 | G22: 65 | H22: 77 | I22: 91.9 | J22: 21.4 | K22: 10.5 | L22: 34.3
A23: Unrealized Valuation Gain/Loss | H23: -0.7
A24: Hedges/Derivatives | H24: -0.7
A25: Excpl Chrgs - Others | I25: 2.4 | K25: 3.1 | L25: 1.4
A26: Restructuring of Debt | K26: 3.1 | L26: 1.4
A27: Calamitous Events | I27: 2.4
A28: Pretax Income | B28: 2581 | C28: 2629 | D28: 2215 | E28: 1716 | F28: 1127 | G28: 715 | H28: 740 | I28: 1062.865 | J28: 985.557 | K28: 837.43 | L28: 768.116
A29: Income Taxes | B29: 555 | C29: 555 | D29: 500 | E29: 417 | F29: 261 | G29: 34 | H29: 87 | I29: 221.986 | J29: 24.021 | K29: 208.889 | L29: 181.702
A30: Income Taxes - Current Domestic | C30: 465 | D30: 392 | E30: 317 | F30: 221 | G30: -7 | H30: 29 | I30: 168.615 | J30: 148.422 | K30: 188.48 | L30: 163.191
A31: Income Taxes - Current Foreign | C31: 100 | D31: 98 | E31: 97 | F31: 62 | G31: 7 | H31: 34 | I31: 53.72 | J31: 27.239 | K31: 21.327 | L31: 12.703
A32: Income Taxes - Deferred Domestic | C32: -31 | D32: 1 | E32: 39 | F32: -25 | G32: 5 | H32: 24 | I32: -0.349 | J32: -151.64 | K32: -0.918 | L32: 5.808
A33: Income Taxes - Deferred Foreign | C33: 21 | D33: 9 | E33: -36 | F33: 3 | G33: 29 | H33: 0 | I33: 0 | J33: 0 | K33: 0 | L33: 0
A34: Other After Tax Adjustments | B34: -218 | C34: -208 | D34: -233 | E34: -38 | F34: -86 | G34: -73 | H34: -185 | I34: -111.021 | J34: -56.148 | K34: -159.257 | L34: -3
A35: Consolidated Net Income | B35: 1808 | C35: 1866 | D35: 1482 | E35: 1261 | F35: 780 | G35: 608 | H35: 468 | I35: 729.858 | J35: 905.388 | K35: 469.284 | L35: 583.414
A36: Minority Interest | B36: 0 | C36: 0 | D36: 1 | E36: 1 | F36: 1 | G36: 1 | H36: 1 | I36: 1.541 | J36: 0 | K36: 0 | L36: 0
A37: Net Income | B37: 1808 | C37: 1866 | D37: 1481 | E37: 1260 | F37: 779 | G37: 607 | H37: 467 | I37: 728.317 | J37: 905.388 | K37: 469.284 | L37: 583.414
A38: Discontinued Operations | B38: 0 | C38: 0 | D38: 0 | E38: 0 | F38: 1 | G38: 0 | H38: 7 | I38: 50.432 | J38: 2.37 | K38: -31.654 | L38: 0
A39: Net Income available to Common | B39: 1808 | C39: 1866 | D39: 1481 | E39: 1260 | F39: 780 | G39: 607 | H39: 474 | I39: 778.749 | J39: 907.758 | K39: 437.63 | L39: 583.414
A40: Per Share
...

Sheet CFS
A1: TransDigm Group Incorporated
A2: TDG 893641100 B11FJK3 NYSE Common stock
A3: Source: FactSet Fundamentals
B4: DEC '25 | C4: SEP '25 | D4: SEP '24 | E4: SEP '23 | F4: SEP '22 | G4: SEP '21 | H4: SEP '20 | I4: SEP '19 | J4: SEP '18 | K4: SEP '17 | L4: SEP '16
B5: LTM
A6: Operating Activities
A7: Net Income / Starting Line | B7: 2026 | C7: 2074 | D7: 1715 | E7: 1299 | F7: 866 | G7: 681 | H7: 700 | I7: 891.311 | J7: 957.062 | K7: 596.887 | L7: 586.414
A8: Depreciation, Depletion & Amortization | B8: 377 | C8: 367 | D8: 312 | E8: 268 | F8: 253 | G8: 253 | H8: 283 | I8: 225.7 | J8: 129.844 | K8: 141.025 | L8: 121.67
A9: Depreciation and Depletion | B9: 167 | C9: 163 | D9: 149 | E9: 129 | F9: 116 | G9: 115 | H9: 114 | I9: 89.689 | J9: 56.397 | K9: 50.937 | L9: 43.455
A10: Amortization of Intangible Assets | B10: 210 | C10: 204 | D10: 163 | E10: 139 | F10: 137 | G10: 138 | H10: 169 | I10: 136.011 | J10: 73.447 | K10: 90.088 | L10: 78.215
A11: Deferred Taxes & Investment Tax Credit | B11: -9 | C11: -10 | D11: 10 | E11: 3 | F11: -22 | G11: 34 | H11: 24 | I11: -0.349 | J11: -151.64 | K11: -0.918 | L11: 5.808
A12: Deferred Taxes | B12: -9 | C12: -10 | D12: 10 | E12: 3 | F12: -22 | G12: 34 | H12: 24 | I12: -0.349 | J12: -151.64 | K12: -0.918 | L12: 5.808
A13: Other Funds | B13: 220 | C13: 165 | D13: 310 | E13: 236 | F13: 111 | G13: 69 | H13: 71 | I13: 112.557 | J13: 91.479 | K13: 138.091 | L13: 65.943
A14: Funds from Operations | B14: 2614 | C14: 2596 | D14: 2347 | E14: 1806 | F14: 1208 | G14: 1037 | H14: 1078 | I14: 1229.219 | J14: 1026.745 | K14: 875.085 | L14: 779.835
A15: Changes in Working Capital | B15: -496 | C15: -558 | D15: -302 | E15: -431 | F15: -260 | G15: -124 | H15: 135 | I15: -213.747 | J15: -4.572 | K15: -86.352 | L15: -110.905
A16: Receivables | B16: -198 | C16: -212 | D16: -84 | E16: -212 | F16: -190 | G16: -78 | H16: 352 | I16: -82.268 | J16: -43.811 | K16: -54.669 | L16: -80.114
A17: Inventories | B17: -173 | C17: -156 | D17: -104 | E17: -261 | F17: -134 | G17: 79 | H17: -62 | I17: -35.712 | J17: -10.808 | K17: 5.127 | L17: -2.073
A18: Accounts Payable | B18: 16 | C18: 38 | D18: -11 | E18: 12 | F18: 58 | G18: 3 | H18: -62 | I18: -1.632 | J18: 18.075 | K18: -10.354 | L18: -6.657
A19: Income Taxes Payable | J19: 36.161 | K19: 18.219 | L19: -12.299
A20: Other Accruals | B20: 43 | C20: -79 | D20: 19 | E20: -94 | F20: 4 | G20: -32 | H20: 67 | I20: -64.701 | J20: 0.624 | K20: -34.111 | L20: -4.843
A21: Other Assets/Liabilities | B21: -163 | C21: -149 | D21: -122 | E21: 124 | F21: 2 | G21: -96 | H21: -160 | I21: -29.434 | J21: -4.813 | K21: -10.564 | L21: -4.919
